Workbook

Sheet EVE项目明细
A1: 项目序号 | B1: 项目名称 | C1: 是否末级节点 | D1: 当前余额（人民币元） | E1: 类别 | F1: 类型 | G1: 久期（年） | H1: 基期PV | I1: 情景1 PV (+200bp) | J1: 情景1 ΔPV | K1: 情景2 PV (-100bp) | L1: 情景2 ΔPV | M1: 情景3 PV (短+250/+100) | N1: 情景3 ΔPV | O1: 情景4 PV (短-100/-50) | P1: 情景4 ΔPV | Q1: 情景5 PV (短-100/+100) | R1: 情景5 ΔPV | S1: 情景6 PV (短+100/-100) | T1: 情景6 ΔPV | U1: EVE规则说明
A2: S010000000000 | B2: 总资产 | C2: 否 | E2: 汇总 | H2: =D2/(1+0.03)^G2 | I2: =D2/(1+0.05)^G2 | J2: =H2-I2 | K2: =D2/(1+0.02)^G2 | L2: =H2-K2 | M2: =IF(G2<1,D2/(1+0.05)^G2,D2/(1+0.04)^G2) | N2: =H2-M2 | O2: =IF(G2<1,D2/(1+0.02)^G2,D2/(1+0.025)^G2) | P2: =H2-O2 | Q2: =IF(G2<1,D2/(1+0.02)^G2,D2/(1+0.04)^G2) | R2: =H2-Q2 | S2: =IF(G2<1,D2/(1+0.04)^G2,D2/(1+0.02)^G2) | T2: =H2-S2 | U2: 汇总节点不参与 EVE 计算
A3: S010100000000 | B3: （一）人民币小计 | C3: 否 | E3: 汇总 | H3: =D3/(1+0.03)^G3 | I3: =D3/(1+0.05)^G3 | J3: =H3-I3 | K3: =D3/(1+0.02)^G3 | L3: =H3-K3 | M3: =IF(G3<1,D3/(1+0.05)^G3,D3/(1+0.04)^G3) | N3: =H3-M3 | O3: =IF(G3<1,D3/(1+0.02)^G3,D3/(1+0.025)^G3) | P3: =H3-O3 | Q3: =IF(G3<1,D3/(1+0.02)^G3,D3/(1+0.04)^G3) | R3: =H3-Q3 | S3: =IF(G3<1,D3/(1+0.04)^G3,D3/(1+0.02)^G3) | T3: =H3-S3 | U3: 汇总节点不参与 EVE 计算
A4: S010101000000 | B4: 1.境内人民币各项贷款 | C4: 否 | D4: 8.3808476e+12 | E4: 汇总 | H4: =D4/(1+0.03)^G4 | I4: =D4/(1+0.05)^G4 | J4: =H4-I4 | K4: =D4/(1+0.02)^G4 | L4: =H4-K4 | M4: =IF(G4<1,D4/(1+0.05)^G4,D4/(1+0.04)^G4) | N4: =H4-M4 | O4: =IF(G4<1,D4/(1+0.02)^G4,D4/(1+0.025)^G4) | P4: =H4-O4 | Q4: =IF(G4<1,D4/(1+0.02)^G4,D4/(1+0.04)^G4) | R4: =H4-Q4 | S4: =IF(G4<1,D4/(1+0.04)^G4,D4/(1+0.02)^G4) | T4: =H4-S4 | U4: 汇总节点不参与 EVE 计算
A5: S010101010000 | B5: 1.1.对公一般贷款 | C5: 是 | D5: 2.945272e+12 | E5: asset | F5: 贷款 | G5: 2 | H5: =D5/(1+0.03)^G5 | I5: =D5/(1+0.05)^G5 | J5: =H5-I5 | K5: =D5/(1+0.02)^G5 | L5: =H5-K5 | M5: =IF(G5<1,D5/(1+0.05)^G5,D5/(1+0.04)^G5) | N5: =H5-M5 | O5: =IF(G5<1,D5/(1+0.02)^G5,D5/(1+0.025)^G5) | P5: =H5-O5 | Q5: =IF(G5<1,D5/(1+0.02)^G5,D5/(1+0.04)^G5) | R5: =H5-Q5 | S5: =IF(G5<1,D5/(1+0.04)^G5,D5/(1+0.02)^G5) | T5: =H5-S5
A6: S010101020000 | B6: 1.2.个人贷款 | C6: 是 | D6: 1.8281866e+12 | E6: asset | F6: 贷款 | G6: 1.05 | H6: =D6/(1+0.03)^G6 | I6: =D6/(1+0.05)^G6 | J6: =H6-I6 | K6: =D6/(1+0.02)^G6 | L6: =H6-K6 | M6: =IF(G6<1,D6/(1+0.05)^G6,D6/(1+0.04)^G6) | N6: =H6-M6 | O6: =IF(G6<1,D6/(1+0.02)^G6,D6/(1+0.025)^G6) | P6: =H6-O6 | Q6: =IF(G6<1,D6/(1+0.02)^G6,D6/(1+0.04)^G6) | R6: =H6-Q6 | S6: =IF(G6<1,D6/(1+0.04)^G6,D6/(1+0.02)^G6) | T6: =H6-S6
A7: S010101030000 | B7: 1.3.信用卡贷款 | C7: 是 | D7: 4.445255e+11 | E7: asset | F7: 贷款 | G7: 1.5 | H7: =D7/(1+0.03)^G7 | I7: =D7/(1+0.05)^G7 | J7: =H7-I7 | K7: =D7/(1+0.02)^G7 | L7: =H7-K7 | M7: =IF(G7<1,D7/(1+0.05)^G7,D7/(1+0.04)^G7) | N7: =H7-M7 | O7: =IF(G7<1,D7/(1+0.02)^G7,D7/(1+0.025)^G7) | P7: =H7-O7 | Q7: =IF(G7<1,D7/(1+0.02)^G7,D7/(1+0.04)^G7) | R7: =H7-Q7 | S7: =IF(G7<1,D7/(1+0.04)^G7,D7/(1+0.02)^G7) | T7: =H7-S7
A8: S010101040000 | B8: 1.4.票据贴现 | C8: 是 | D8: 2.0134008e+11 | E8: asset | F8: 贷款 | G8: 0.5 | H8: =D8/(1+0.03)^G8 | I8: =D8/(1+0.05)^G8 | J8: =H8-I8 | K8: =D8/(1+0.02)^G8 | L8: =H8-K8 | M8: =IF(G8<1,D8/(1+0.05)^G8,D8/(1+0.04)^G8) | N8: =H8-M8 | O8: =IF(G8<1,D8/(1+0.02)^G8,D8/(1+0.025)^G8) | P8: =H8-O8 | Q8: =IF(G8<1,D8/(1+0.02)^G8,D8/(1+0.04)^G8) | R8: =H8-Q8 | S8: =IF(G8<1,D8/(1+0.04)^G8,D8/(1+0.02)^G8) | T8: =H8-S8
A9: S010101050000 | B9: 1.5.非银贷款 | C9: 是 | D9: 348478250000 | E9: asset | F9: 贷款 | G9: 1.5 | H9: =D9/(1+0.03)^G9 | I9: =D9/(1+0.05)^G9 | J9: =H9-I9 | K9: =D9/(1+0.02)^G9 | L9: =H9-K9 | M9: =IF(G9<1,D9/(1+0.05)^G9,D9/(1+0.04)^G9) | N9: =H9-M9 | O9: =IF(G9<1,D9/(1+0.02)^G9,D9/(1+0.025)^G9) | P9: =H9-O9 | Q9: =IF(G9<1,D9/(1+0.02)^G9,D9/(1+0.04)^G9) | R9: =H9-Q9 | S9: =IF(G9<1,D9/(1+0.04)^G9,D9/(1+0.02)^G9) | T9: =H9-S9
A10: S010102000000 | B10: 2.人民币非信贷类业务 | C10: 否 | D10: 2.6130452e+12 | E10: 汇总 | H10: =D10/(1+0.03)^G10 | I10: =D10/(1+0.05)^G10 | J10: =H10-I10 | K10: =D10/(1+0.02)^G10 | L10: =H10-K10 | M10: =IF(G10<1,D10/(1+0.05)^G10,D10/(1+0.04)^G10) | N10: =H10-M10 | O10: =IF(G10<1,D10/(1+0.02)^G10,D10/(1+0.025)^G10) | P10: =H10-O10 | Q10: =IF(G10<1,D10/(1+0.02)^G10,D10/(1+0.04)^G10) | R10: =H10-Q10 | S10: =IF(G10<1,D10/(1+0.04)^G10,D10/(1+0.02)^G10) | T10: =H10-S10 | U10: 汇总节点不参与 EVE 计算
A11: S010102010000 | B11: 2.1.债券投资 | C11: 否 | D11: 1.7944005e+12 | E11: 汇总 | H11: =D11/(1+0.03)^G11 | I11: =D11/(1+0.05)^G11 | J11: =H11-I11 | K11: =D11/(1+0.02)^G11 | L11: =H11-K11 | M11: =IF(G11<1,D11/(1+0.05)^G11,D11/(1+0.04)^G11) | N11: =H11-M11 | O11: =IF(G11<1,D11/(1+0.02)^G11,D11/(1+0.025)^G11) | P11: =H11-O11 | Q11: =IF(G11<1,D11/(1+0.02)^G11,D11/(1+0.04)^G11) | R11: =H11-Q11 | S11: =IF(G11<1,D11/(1+0.04)^G11,D11/(1+0.02)^G11) | T11: =H11-S11 | U11: 汇总节点不参与 EVE 计算
A12: S010102010100 | B12: 2.1.1金市自营债券 | C12: 否 | D12: 1.1843826e+12 | E12: 汇总 | H12: =D12/(1+0.03)^G12 | I12: =D12/(1+0.05)^G12 | J12: =H12-I12 | K12: =D12/(1+0.02)^G12 | L12: =H12-K12 | M12: =IF(G12<1,D12/(1+0.05)^G12,D12/(1+0.04)^G12) | N12: =H12-M12 | O12: =IF(G12<1,D12/(1+0.02)^G12,D12/(1+0.025)^G12) | P12: =H12-O12 | Q12: =IF(G12<1,D12/(1+0.02)^G12,D12/(1+0.04)^G12) | R12: =H12-Q12 | S12: =IF(G12<1,D12/(1+0.04)^G12,D12/(1+0.02)^G12) | T12: =H12-S12 | U12: 汇总节点不参与 EVE 计算
A13: S010102010101 | B13: 2.1.1.1AC | C13: 是 | D13: 5.4398007e+11 | E13: asset | F13: 债券 | G13: 3.5 | H13: =D13/(1+0.03)^G13 | I13: =D13/(1+0.05)^G13 | J13: =H13-I13 | K13: =D13/(1+0.02)^G13 | L13: =H13-K13 | M13: =IF(G13<1,D13/(1+0.05)^G13,D13/(1+0.04)^G13) | N13: =H13-M13 | O13: =IF(G13<1,D13/(1+0.02)^G13,D13/(1+0.025)^G13) | P13: =H13-O13 | Q13: =IF(G13<1,D13/(1+0.02)^G13,D13/(1+0.04)^G13) | R13: =H13-Q13 | S13: =IF(G13<1,D13/(1+0.04)^G13,D13/(1+0.02)^G13) | T13: =H13-S13
A14: S010102010102 | B14: 2.1.1.2FVOCI | C14: 是 | D14: 640402496404 | E14: asset | F14: 债券 | G14: 4 | H14: =D14/(1+0.03)^G14 | I14: =D14/(1+0.05)^G14 | J14: =H14-I14 | K14: =D14/(1+0.02)^G14 | L14: =H14-K14 | M14: =IF(G14<1,D14/(1+0.05)^G14,D14/(1+0.04)^G14) | N14: =H14-M14 | O14: =IF(G14<1,D14/(1+0.02)^G14,D14/(1+0.025)^G14) | P14: =H14-O14 | Q14: =IF(G14<1,D14/(1+0.02)^G14,D14/(1+0.04)^G14) | R14: =H14-Q14 | S14: =IF(G14<1,D14/(1+0.04)^G14,D14/(1+0.02)^G14) | T14: =H14-S14
A15: S010102010103 | B15: 2.1.1.3FVTPL | C15: 是 | D15: 50000000000 | E15: asset | F15: 债券 | G15: 3 | H15: =D15/(1+0.03)^G15 | I15: =D15/(1+0.05)^G15 | J15: =H15-I15 | K15: =D15/(1+0.02)^G15 | L15: =H15-K15 | M15: =IF(G15<1,D15/(1+0.05)^G15,D15/(1+0.04)^G15) | N15: =H15-M15 | O15: =IF(G15<1,D15/(1+0.02)^G15,D15/(1+0.025)^G15) | P15: =H15-O15 | Q15: =IF(G15<1,D15/(1+0.02)^G15,D15/(1+0.04)^G15) | R15: =H15-Q15 | S15: =IF(G15<1,D15/(1+0.04)^G15,D15/(1+0.02)^G15) | T15: =H15-S15
A16: S010102010200 | B16: 2.1.2司库债券 | C16: 否 | D16: 6.1001796e+11 | E16: 汇总 | H16: =D16/(1+0.03)^G16 | I16: =D16/(1+0.05)^G16 | J16: =H16-I16 | K16: =D16/(1+0.02)^G16 | L16: =H16-K16 | M16: =IF(G16<1,D16/(1+0.05)^G16,D16/(1+0.04)^G16) | N16: =H16-M16 | O16: =IF(G16<1,D16/(1+0.02)^G16,D16/(1+0.025)^G16) | P16: =H16-O16 | Q16: =IF(G16<1,D16/(1+0.02)^G16,D16/(1+0.04)^G16) | R16: =H16-Q16 | S16: =IF(G16<1,D16/(1+0.04)^G16,D16/(1+0.02)^G16) | T16: =H16-S16 | U16: 汇总节点不参与 EVE 计算
A17: S010102010201 | B17: 2.1.2.1AC | C17: 是 | D17: 5.6635137e+11 | E17: asset | F17: 债券 | G17: 3.5 | H17: =D17/(1+0.03)^G17 | I17: =D17/(1+0.05)^G17 | J17: =H17-I17 | K17: =D17/(1+0.02)^G17 | L17: =H17-K17 | M17: =IF(G17<1,D17/(1+0.05)^G17,D17/(1+0.04)^G17) | N17: =H17-M17 | O17: =IF(G17<1,D17/(1+0.02)^G17,D17/(1+0.025)^G17) | P17: =H17-O17 | Q17: =IF(G17<1,D17/(1+0.02)^G17,D17/(1+0.04)^G17) | R17: =H17-Q17 | S17: =IF(G17<1,D17/(1+0.04)^G17,D17/(1+0.02)^G17) | T17: =H17-S17
A18: S010102010202 | B18: 2.1.2.2FVOCI | C18: 是 | D18: 4.366659e+10 | E18: asset | F18: 债券 | G18: 4 | H18: =D18/(1+0.03)^G18 | I18: =D18/(1+0.05)^G18 | J18: =H18-I18 | K18: =D18/(1+0.02)^G18 | L18: =H18-K18 | M18: =IF(G18<1,D18/(1+0.05)^G18,D18/(1+0.04)^G18) | N18: =H18-M18 | O18: =IF(G18<1,D18/(1+0.02)^G18,D18/(1+0.025)^G18) | P18: =H18-O18 | Q18: =IF(G18<1,D18/(1+0.02)^G18,D18/(1+0.04)^G18) | R18: =H18-Q18 | S18: =IF(G18<1,D18/(1+0.04)^G18,D18/(1+0.02)^G18) | T18: =H18-S18
A19: S010102010203 | B19: 2.1.2.3FVTPL | C19: 是 | D19: 30000000000 | E19: asset | F19: 债券 | G19: 3 | H19: =D19/(1+0.03)^G19 | I19: =D19/(1+0.05)^G19 | J19: =H19-I19 | K19: =D19/(1+0.02)^G19 | L19: =H19-K19 | M19: =IF(G19<1,D19/(1+0.05)^G19,D19/(1+0.04)^G19) | N19: =H19-M19 | O19: =IF(G19<1,D19/(1+0.02)^G19,D19/(1+0.025)^G19) | P19: =H19-O19 | Q19: =IF(G19<1,D19/(1+0.02)^G19,D19/(1+0.04)^G19) | R19: =H19-Q19 | S19: =IF(G19<1,D19/(1+0.04)^G19,D19/(1+0.02)^G19) | T19: =H19-S19
A20: S010102020000 | B20: 2.2.结构化融资 | C20: 是 | D20: 2.0517233e+11 | E20: asset | F20: 结构化 | G20: 3 | H20: =D20/(1+0.03)^G20 | I20: =D20/(1+0.05)^G20 | J20: =H20-I20 | K20: =D20/(1+0.02)^G20 | L20: =H20-K20 | M20: =IF(G20<1,D20/(1+0.05)^G20,D20/(1+0.04)^G20) | N20: =H20-M20 | O20: =IF(G20<1,D20/(1+0.02)^G20,D20/(1+0.025)^G20) | P20: =H20-O20 | Q20: =IF(G20<1,D20/(1+0.02)^G20,D20/(1+0.04)^G20) | R20: =H20-Q20 | S20: =IF(G20<1,D20/(1+0.04)^G20,D20/(1+0.02)^G20) | T20: =H20-S20
A21: S010102030000 | B21: 2.3.同业资产（不含拆放非银） | C21: 是 | D21: 2.4811766e+11 | E21: asset | F21: 同业 | G21: 1 | H21: =D21/(1+0.03)^G21 | I21: =D21/(1+0.05)^G21 | J21: =H21-I21 | K21: =D21/(1+0.02)^G21 | L21: =H21-K21 | M21: =IF(G21<1,D21/(1+0.05)^G21,D21/(1+0.04)^G21) | N21: =H21-M21 | O21: =IF(G21<1,D21/(1+0.02)^G21,D21/(1+0.025)^G21) | P21: =H21-O21 | Q21: =IF(G21<1,D21/(1+0.02)^G21,D21/(1+0.04)^G21) | R21: =H21-Q21 | S21: =IF(G21<1,D21/(1+0.04)^G21,D21/(1+0.02)^G21) | T21: =H21-S21
A22: S010102040000 | B22: 2.4.存款准备金 | C22: 是 | D22: 3.6535469e+11 | E22: asset | F22: 利率 | G22: 0 | H22: =D22/(1+0.03)^G22 | I22: =D22/(1+0.05)^G22 | J22: =H22-I22 | K22: =D22/(1+0.02)^G22 | L22: =H22-K22 | M22: =IF(G22<1,D22/(1+0.05)^G22,D22/(1+0.04)^G22) | N22: =H22-M22 | O22: =IF(G22<1,D22/(1+0.02)^G22,D22/(1+0.025)^G22) | P22: =H22-O22 | Q22: =IF(G22<1,D22/(1+0.02)^G22,D22/(1+0.04)^G22) | R22: =H22-Q22 | S22: =IF(G22<1,D22/(1+0.04)^G22,D22/(1+0.02)^G22) | T22: =H22-S22
A23: S010103000000 | B23: 3.人民币非生息资产 | C23: 否 | D23: 8.67779e+11 | E23: 汇总 | H23: =D23/(1+0.03)^G23 | I23: =D23/(1+0.05)^G23 | J23: =H23-I23 | K23: =D23/(1+0.02)^G23 | L23: =H23-K23 | M23: =IF(G23<1,D23/(1+0.05)^G23,D23/(1+0.04)^G23) | N23: =H23-M23 | O23: =IF(G23<1,D23/(1+0.02)^G23,D23/(1+0.025)^G23) | P23: =H23-O23 | Q23: =IF(G23<1,D23/(1+0.02)^G23,D23/(1+0.04)^G23) | R23: =H23-Q23 | S23: =IF(G23<1,D23/(1+0.04)^G23,D23/(1+0.02)^G23) | T23: =H23-S23 | U23: 汇总节点不参与 EVE 计算
A24: S010103010000 | B24: 3.1.FVTPL类资产 | C24: 是 | D24: 6.4026245e+11 | E24: asset | F24: FVTPL | G24: 2 | H24: =D24/(1+0.03)^G24 | I24: =D24/(1+0.05)^G24 | J24: =H24-I24 | K24: =D24/(1+0.02)^G24 | L24: =H24-K24 | M24: =IF(G24<1,D24/(1+0.05)^G24,D24/(1+0.04)^G24) | N24: =H24-M24 | O24: =IF(G24<1,D24/(1+0.02)^G24,D24/(1+0.025)^G24) | P24: =H24-O24 | Q24: =IF(G24<1,D24/(1+0.02)^G24,D24/(1+0.04)^G24) | R24: =H24-Q24 | S24: =IF(G24<1,D24/(1+0.04)^G24,D24/(1+0.02)^G24) | T24: =H24-S24
A25: S010103020000 | B25: 3.2.其他非生息资产 | C25: 否 | D25: 2.2751655e+11 | E25: 汇总 | H25: =D25/(1+0.03)^G25 | I25: =D25/(1+0.05)^G25 | J25: =H25-I25 | K25: =D25/(1+0.02)^G25 | L25: =H25-K25 | M25: =IF(G25<1,D25/(1+0.05)^G25,D25/(1+0.04)^G25) | N25: =H25-M25 | O25: =IF(G25<1,D25/(1+0.02)^G25,D25/(1+0.025)^G25) | P25: =H25-O25 | Q25: =IF(G25<1,D25/(1+0.02)^G25,D25/(1+0.04)^G25) | R25: =H25-Q25 | S25: =IF(G25<1,D25/(1+0.04)^G25,D25/(1+0.02)^G25) | T25: =H25-S25 | U25: 汇总节点不参与 EVE 计算
A26: S010103020100 | B26: 3.2.1. 其中：现金 | C26: 是 | D26: 127516545106 | E26: asset | F26: 现金 | G26: 0 | H26: =D26/(1+0.03)^G26 | I26: =D26/(1+0.05)^G26 | J26: =H26-I26 | K26: =D26/(1+0.02)^G26 | L26: =H26-K26 | M26: =IF(G26<1,D26/(1+0.05)^G26,D26/(1+0.04)^G26) | N26: =H26-M26 | O26: =IF(G26<1,D26/(1+0.02)^G26,D26/(1+0.025)^G26) | P26: =H26-O26 | Q26: =IF(G26<1,D26/(1+0.02)^G26,D26/(1+0.04)^G26) | R26: =H26-Q26 | S26: =IF(G26<1,D26/(1+0.04)^G26,D26/(1+0.02)^G26) | T26: =H26-S26
A27: S010103020200 | B27: 3.2.2. 其中：其它 | C27: 是 | D27: 100000000000 | E27: asset | F27: 无息 | G27: 0 | H27: =D27/(1+0.03)^G27 | I27: =D27/(1+0.05)^G27 | J27: =H27-I27 | K27: =D27/(1+0.02)^G27 | L27: =H27-K27 | M27: =IF(G27<1,D27/(1+0.05)^G27,D27/(1+0.04)^G27) | N27: =H27-M27 | O27: =IF(G27<1,D27/(1+0.02)^G27,D27/(1+0.025)^G27) | P27: =H27-O27 | Q27: =IF(G27<1,D27/(1+0.02)^G27,D27/(1+0.04)^G27) | R27: =H27-Q27 | S27: =IF(G27<1,D27/(1+0.04)^G27,D27/(1+0.02)^G27) | T27: =H27-S27
A28: S010200000000 | B28: （二）外币小计（美元） | C28: 否 | E28: 汇总 | H28: =D28/(1+0.03)^G28 | I28: =D28/(1+0.05)^G28 | J28: =H28-I28 | K28: =D28/(1+0.02)^G28 | L28: =H28-K28 | M28: =IF(G28<1,D28/(1+0.05)^G28,D28/(1+0.04)^G28) | N28: =H28-M28 | O28: =IF(G28<1,D28/(1+0.02)^G28,D28/(1+0.025)^G28) | P28: =H28-O28 | Q28: =IF(G28<1,D28/(1+0.02)^G28,D28/(1+0.04)^G28) | R28: =H28-Q28 | S28: =IF(G28<1,D28/(1+0.04)^G28,D28/(1+0.02)^G28) | T28: =H28-S28 | U28: 汇总节点不参与 EVE 计算
A29: S010201000000 | B29: 1.外币贷款 | C29: 是 | D29: 80000000000 | E29: asset | F29: 贷款 | G29: 2 | H29: =D29/(1+0.03)^G29 | I29: =D29/(1+0.05)^G29 | J29: =H29-I29 | K29: =D29/(1+0.02)^G29 | L29: =H29-K29 | M29: =IF(G29<1,D29/(1+0.05)^G29,D29/(1+0.04)^G29) | N29: =H29-M29 | O29: =IF(G29<1,D29/(1+0.02)^G29,D29/(1+0.025)^G29) | P29: =H29-O29 | Q29: =IF(G29<1,D29/(1+0.02)^G29,D29/(1+0.04)^G29) | R29: =H29-Q29 | S29: =IF(G29<1,D29/(1+0.04)^G29,D29/(1+0.02)^G29) | T29: =H29-S29
A30: S010202000000 | B30: 2.外币非信贷资产 | C30: 否 | E30: 汇总 | H30: =D30/(1+0.03)^G30 | I30: =D30/(1+0.05)^G30 | J30: =H30-I30 | K30: =D30/(1+0.02)^G30 | L30: =H30-K30 | M30: =IF(G30<1,D30/(1+0.05)^G30,D30/(1+0.04)^G30) | N30: =H30-M30 | O30: =IF(G30<1,D30/(1+0.02)^G30,D30/(1+0.025)^G30) | P30: =H30-O30 | Q30: =IF(G30<1,D30/(1+0.02)^G30,D30/(1+0.04)^G30) | R30: =H30-Q30 | S30: =IF(G30<1,D30/(1+0.04)^G30,D30/(1+0.02)^G30) | T30: =H30-S30 | U30: 汇总节点不参与 EVE 计算
A31: S010202010000 | B31: 2.1.外币债券 | C31: 是 | D31: 35000000000 | E31: asset | F31: 债券 | G31: 3.5 | H31: =D31/(1+0.03)^G31 | I31: =D31/(1+0.05)^G31 | J31: =H31-I31 | K31: =D31/(1+0.02)^G31 | L31: =H31-K31 | M31: =IF(G31<1,D31/(1+0.05)^G31,D31/(1+0.04)^G31) | N31: =H31-M31 | O31: =IF(G31<1,D31/(1+0.02)^G31,D31/(1+0.025)^G31) | P31: =H31-O31 | Q31: =IF(G31<1,D31/(1+0.02)^G31,D31/(1+0.04)^G31) | R31: =H31-Q31 | S31: =IF(G31<1,D31/(1+0.04)^G31,D31/(1+0.02)^G31) | T31: =H31-S31
A32: S010202020000 | B32: 2.2.同业资产 | C32: 是 | D32: 25000000000 | E32: asset | F32: 同业 | G32: 1 | H32: =D32/(1+0.03)^G32 | I32: =D32/(1+0.05)^G32 | J32: =H32-I32 | K32: =D32/(1+0.02)^G32 | L32: =H32-K32 | M32: =IF(G32<1,D32/(1+0.05)^G32,D32/(1+0.04)^G32) | N32: =H32-M32 | O32: =IF(G32<1,D32/(1+0.02)^G32,D32/(1+0.025)^G32) | P32: =H32-O32 | Q32: =IF(G32<1,D32/(1+0.02)^G32,D32/(1+0.04)^G32) | R32: =H32-Q32 | S32: =IF(G32<1,D32/(1+0.04)^G32,D32/(1+0.02)^G32) | T32: =H32-S32
A33: S010203000000 | B33: 3.外币非生息资产 | C33: 是 | D33: 10000000000 | E33: asset | F33: 无息 | G33: 0.25 | H33: =D33/(1+0.03)^G33 | I33: =D33/(1+0.05)^G33 | J33: =H33-I33 | K33: =D33/(1+0.02)^G33 | L33: =H33-K33 | M33: =IF(G33<1,D33/(1+0.05)^G33,D33/(1+0.04)^G33) | N33: =H33-M33 | O33: =IF(G33<1,D33/(1+0.02)^G33,D33/(1+0.025)^G33) | P33: =H33-O33 | Q33: =IF(G33<1,D33/(1+0.02)^G33,D33/(1+0.04)^G33) | R33: =H33-Q33 | S33: =IF(G33<1,D33/(1+0.04)^G33,D33/(1+0.02)^G33) | T33: =H33-S33
A34: S020000000000 | B34: 总负债 | C34: 否 | E34: 汇总 | H34: =D34/(1+0.03)^G34 | I34: =D34/(1+0.05)^G34 | J34: =H34-I34 | K34: =D34/(1+0.02)^G34 | L34: =H34-K34 | M34: =IF(G34<1,D34/(1+0.05)^G34,D34/(1+0.04)^G34) | N34: =H34-M34 | O34: =IF(G34<1,D34/(1+0.02)^G34,D34/(1+0.025)^G34) | P34: =H34-O34 | Q34: =IF(G34<1,D34/(1+0.02)^G34,D34/(1+0.04)^G34) | R34: =H34-Q34 | S34: =IF(G34<1,D34/(1+0.04)^G34,D34/(1+0.02)^G34) | T34: =H34-S34 | U34: 汇总节点不参与 EVE 计算
A35: S020100000000 | B35: （一）人民币小计 | C35: 否 | E35: 汇总 | H35: =D35/(1+0.03)^G35 | I35: =D35/(1+0.05)^G35 | J35: =H35-I35 | K35: =D35/(1+0.02)^G35 | L35: =H35-K35 | M35: =IF(G35<1,D35/(1+0.05)^G35,D35/(1+0.04)^G35) | N35: =H35-M35 | O35: =IF(G35<1,D35/(1+0.02)^G35,D35/(1+0.025)^G35) | P35: =H35-O35 | Q35: =IF(G35<1,D35/(1+0.02)^G35,D35/(1+0.04)^G35) | R35: =H35-Q35 | S35: =IF(G35<1,D35/(1+0.04)^G35,D35/(1+0.02)^G35) | T35: =H35-S35 | U35: 汇总节点不参与 EVE 计算
A36: S020101000000 | B36: 1.境内人民币自营存款 | C36: 否 | E36: 汇总 | H36: =D36/(1+0.03)^G36 | I36: =D36/(1+0.05)^G36 | J36: =H36-I36 | K36: =D36/(1+0.02)^G36 | L36: =H36-K36 | M36: =IF(G36<1,D36/(1+0.05)^G36,D36/(1+0.04)^G36) | N36: =H36-M36 | O36: =IF(G36<1,D36/(1+0.02)^G36,D36/(1+0.025)^G36) | P36: =H36-O36 | Q36: =IF(G36<1,D36/(1+0.02)^G36,D36/(1+0.04)^G36) | R36: =H36-Q36 | S36: =IF(G36<1,D36/(1+0.04)^G36,D36/(1+0.02)^G36) | T36: =H36-S36 | U36: 汇总节点不参与 EVE 计算
A37: S020101010000 | B37: 1.1.对公存款 | C37: 否 | D37: 4.2226821e+12 | E37: 汇总 | H37: =D37/(1+0.03)^G37 | I37: =D37/(1+0.05)^G37 | J37: =H37-I37 | K37: =D37/(1+0.02)^G37 | L37: =H37-K37 | M37: =IF(G37<1,D37/(1+0.05)^G37,D37/(1+0.04)^G37) | N37: =H37-M37 | O37: =IF(G37<1,D37/(1+0.02)^G37,D37/(1+0.025)^G37) | P37: =H37-O37 | Q37: =IF(G37<1,D37/(1+0.02)^G37,D37/(1+0.04)^G37) | R37: =H37-Q37 | S37: =IF(G37<1,D37/(1+0.04)^G37,D37/(1+0.02)^G37) | T37: =H37-S37 | U37: 汇总节点不参与 EVE 计算
A38: S020101010100 | B38: 1.1.1对公活期存款 | C38: 是 | D38: 2.4862124e+12 | E38: liab | F38: 活期 | G38: 1 | H38: =D38/(1+0.03)^G38 | I38: =D38/(1+0.05)^G38 | J38: =H38-I38 | K38: =D38/(1+0.02)^G38 | L38: =H38-K38 | M38: =IF(G38<1,D38/(1+0.05)^G38,D38/(1+0.04)^G38) | N38: =H38-M38 | O38: =IF(G38<1,D38/(1+0.02)^G38,D38/(1+0.025)^G38) | P38: =H38-O38 | Q38: =IF(G38<1,D38/(1+0.02)^G38,D38/(1+0.04)^G38) | R38: =H38-Q38 | S38: =IF(G38<1,D38/(1+0.04)^G38,D38/(1+0.02)^G38) | T38: =H38-S38
A39: S020101010200 | B39: 1.1.2对公定期存款 | C39: 是 | D39: 1.7364697e+12 | E39: liab | F39: 定期 | G39: 2 | H39: =D39/(1+0.03)^G39 | I39: =D39/(1+0.05)^G39 | J39: =H39-I39 | K39: =D39/(1+0.02)^G39 | L39: =H39-K39 | M39: =IF(G39<1,D39/(1+0.05)^G39,D39/(1+0.04)^G39) | N39: =H39-M39 | O39: =IF(G39<1,D39/(1+0.02)^G39,D39/(1+0.025)^G39) | P39: =H39-O39 | Q39: =IF(G39<1,D39/(1+0.02)^G39,D39/(1+0.04)^G39) | R39: =H39-Q39 | S39: =IF(G39<1,D39/(1+0.04)^G39,D39/(1+0.02)^G39) | T39: =H39-S39
A40: S020101020000 | B40: 1.2.零售存款 | C40: 否 | D40: 2.1694315e+12 | E40: 汇总 | H40: =D40/(1+0.03)^G40 | I40: =D40/(1+0.05)^G40 | J40: =H40-I40 | K40: =D40/(1+0.02)^G40 | L40: =H40-K40 | M40: =IF(G40<1,D40/(1+0.05)^G40,D40/(1+0.04)^G40) | N40: =H40-M40 | O40: =IF(G40<1,D40/(1+0.02)^G40,D40/(1+0.025)^G40) | P40: =H40-O40 | Q40: =IF(G40<1,D40/(1+0.02)^G40,D40/(1+0.04)^G40) | R40: =H40-Q40 | S40: =IF(G40<1,D40/(1+0.04)^G40,D40/(1+0.02)^G40) | T40: =H40-S40 | U40: 汇总节点不参与 EVE 计算
...

Sheet EVE计算
A1: △EVE 经济价值变动（IRRBB 银行账户利率风险）
A2: 依据：巴塞尔 IRRBB（2016）+ 银保监会《商业银行银行账户利率风险管理办法》（2018）
A3: 基期利率 r₀ = 3.0%
A4: 注：3.2 拆分为 3.2.1 现金（久期 0.05）和 3.2.2 其它（久期 0.25）
A6: Tier 1 一级资本（所有者权益） | B6: 786217000000
A7: 资产合计（仅末级映射） | B7: =SUMIFS(EVE项目明细!D:D,EVE项目明细!E:E,"asset",EVE项目明细!C:C,"是")
A8: 负债合计（仅末级映射） | B8: =SUMIFS(EVE项目明细!D:D,EVE项目明细!E:E,"liab",EVE项目明细!C:C,"是")
A9: 资产加权久期 D_A（按余额加权） | B9: =SUMPRODUCT((EVE项目明细!E2:E58="asset")*(EVE项目明细!C2:C58="是")*(EVE项目明细!G2:G58)*(EVE项目明细!D2:D58))/B7
A10: 负债加权久期 D_L（按余额加权） | B10: =SUMPRODUCT((EVE项目明细!E2:E58="liab")*(EVE项目明细!C2:C58="是")*(EVE项目明细!G2:G58)*(EVE项目明细!D2:D58))/B8
A13: 情景 1：平行向上 +200bp（基期 3% → 5%）
A14: 资产 PV 减少（损失） | B14: =SUMIFS(EVE项目明细!J:J,EVE项目明细!E:E,"asset")
A15: 负债 PV 减少（利好） | B15: =SUMIFS(EVE项目明细!J:J,EVE项目明细!E:E,"liab")
A16: △EVE（损失） | B16: =B14-B15
A17: △EVE / Tier 1 资本 | B17: =B16/B6*100
A19: 情景 2：平行向下 -100bp（基期 3% → 2%）
A20: 资产 PV 减少（损失） | B20: =SUMIFS(EVE项目明细!L:L,EVE项目明细!E:E,"asset")
A21: 负债 PV 减少（利好） | B21: =SUMIFS(EVE项目明细!L:L,EVE项目明细!E:E,"liab")
A22: △EVE（损失） | B22: =B20-B21
A23: △EVE / Tier 1 资本 | B23: =B22/B6*100
A25: 情景 3：短端向上 +250bp（t<1）/ +100bp（t≥1）
A26: 资产 PV 减少（损失） | B26: =SUMIFS(EVE项目明细!N:N,EVE项目明细!E:E,"asset")
A27: 负债 PV 减少（利好） | B27: =SUMIFS(EVE项目明细!N:N,EVE项目明细!E:E,"liab")
A28: △EVE（损失） | B28: =B26-B27
A29: △EVE / Tier 1 资本 | B29: =B28/B6*100
A31: 情景 4：短端向下 -100bp（t<1）/ -50bp（t≥1）
A32: 资产 PV 减少（损失） | B32: =SUMIFS(EVE项目明细!P:P,EVE项目明细!E:E,"asset")
A33: 负债 PV 减少（利好） | B33: =SUMIFS(EVE项目明细!P:P,EVE项目明细!E:E,"liab")
A34: △EVE（损失） | B34: =B32-B33
A35: △EVE / Tier 1 资本 | B35: =B34/B6*100
A37: 情景 5：长端向上 -100bp（t<1）/ +100bp（t≥1）
A38: 资产 PV 减少（损失） | B38: =SUMIFS(EVE项目明细!R:R,EVE项目明细!E:E,"asset")
A39: 负债 PV 减少（利好） | B39: =SUMIFS(EVE项目明细!R:R,EVE项目明细!E:E,"liab")
A40: △EVE（损失） | B40: =B38-B39
A41: △EVE / Tier 1 资本 | B41: =B40/B6*100
A43: 情景 6：长端向下 +100bp（t<1）/ -100bp（t≥1）
A44: 资产 PV 减少（损失） | B44: =SUMIFS(EVE项目明细!T:T,EVE项目明细!E:E,"asset")
A45: 负债 PV 减少（利好） | B45: =SUMIFS(EVE项目明细!T:T,EVE项目明细!E:E,"liab")
A46: △EVE（损失） | B46: =B44-B45
A47: △EVE / Tier 1 资本 | B47: =B46/B6*100
A50: 【最不利情景 △EVE】
...
