Workbook

Sheet NII数据源
A1: NII 净利息收入数据源 (Net Interest Income Data Source) — 中信银行 2025-12-31
A2: 🟢 绿区(蓝字) = 可编辑输入：期初/期末余额、年化利率、重定价β | 🟣 浅紫区(紫字) = 自动计算：平均余额、有效计息、利息收入/支出 | 修改本表 → 利息收入明细 / 利息支出明细 / NII计量表 / 结构拆解 / 情景敏感性 全部自动联动
A3: 账户编码 | B3: 账户名称 | C3: 方向 | D3: 业务条线 | E3: 子类 | F3: 账户类型 | G3: 币种 | H3: 期初余额 (亿元) | I3: 期末余额 (亿元) | J3: 平均余额 (亿元) | K3: 年化利率 | L3: 有效计息 | M3: 重定价β | N3: 利息收入 (亿元) | O3: 利息支出 (亿元) | P3: 备注
A4: S010101010000 | B4: 1.1.对公一般贷款 | C4: 资产 | D4: 贷款类 | E4: 对公 | F4: 信贷 | G4: 人民币 | H4: 27685.56 | I4: 29452.72 | J4: =(H4+I4)/2 | K4: 0.0465 | L4: =IF(K4>0,"是","否") | M4: 0.6 | N4: =IF(AND($C4="资产",$L4="是"),$J4*$K4,0) | O4: =IF(AND($C4="负债",$L4="是"),$J4*$K4,0) | P4: 对公一般贷款 年化 4.65%
A5: S010101020000 | B5: 1.2.个人贷款 | C5: 资产 | D5: 贷款类 | E5: 零售 | F5: 信贷 | G5: 人民币 | H5: 17184.95 | I5: 18281.87 | J5: =(H5+I5)/2 | K5: 0.0485 | L5: =IF(K5>0,"是","否") | M5: 0.6 | N5: =IF(AND($C5="资产",$L5="是"),$J5*$K5,0) | O5: =IF(AND($C5="负债",$L5="是"),$J5*$K5,0) | P5: 个人贷款 年化 4.85%
A6: S010101030000 | B6: 1.3.信用卡贷款 | C6: 资产 | D6: 贷款类 | E6: 信用卡 | F6: 信贷 | G6: 人民币 | H6: 4089.63 | I6: 4445.26 | J6: =(H6+I6)/2 | K6: 0.1205 | L6: =IF(K6>0,"是","否") | M6: 0.75 | N6: =IF(AND($C6="资产",$L6="是"),$J6*$K6,0) | O6: =IF(AND($C6="负债",$L6="是"),$J6*$K6,0) | P6: 信用卡贷款 年化 12.05%
A7: S010101040000 | B7: 1.4.票据贴现 | C7: 资产 | D7: 贷款类 | E7: 票据 | F7: 信贷 | G7: 人民币 | H7: 1912.73 | I7: 2013.4 | J7: =(H7+I7)/2 | K7: 0.0255 | L7: =IF(K7>0,"是","否") | M7: 0.9 | N7: =IF(AND($C7="资产",$L7="是"),$J7*$K7,0) | O7: =IF(AND($C7="负债",$L7="是"),$J7*$K7,0) | P7: 票据贴现 年化 2.55%
A8: S010101050000 | B8: 1.5.非银贷款 | C8: 资产 | D8: 贷款类 | E8: 非银 | F8: 信贷 | G8: 人民币 | H8: 3345.39 | I8: 3484.78 | J8: =(H8+I8)/2 | K8: 0.0405 | L8: =IF(K8>0,"是","否") | M8: 0.8 | N8: =IF(AND($C8="资产",$L8="是"),$J8*$K8,0) | O8: =IF(AND($C8="负债",$L8="是"),$J8*$K8,0) | P8: 非银贷款 年化 4.05%
A9: S010102010101 | B9: 2.1.1.1金市自营 AC | C9: 资产 | D9: 债券投资类 | E9: AC | F9: 投资 | G9: 人民币 | H9: 5602.99 | I9: 5439.8 | J9: =(H9+I9)/2 | K9: 0.0325 | L9: =IF(K9>0,"是","否") | M9: 0.5 | N9: =IF(AND($C9="资产",$L9="是"),$J9*$K9,0) | O9: =IF(AND($C9="负债",$L9="是"),$J9*$K9,0) | P9: 金市自营 AC 年化 3.25%
A10: S010102010102 | B10: 2.1.1.2金市自营 FVOCI | C10: 资产 | D10: 债券投资类 | E10: FVOCI | F10: 投资 | G10: 人民币 | H10: 6596.15 | I10: 6404.02 | J10: =(H10+I10)/2 | K10: 0.0305 | L10: =IF(K10>0,"是","否") | M10: 0.5 | N10: =IF(AND($C10="资产",$L10="是"),$J10*$K10,0) | O10: =IF(AND($C10="负债",$L10="是"),$J10*$K10,0) | P10: 金市自营 FVOCI 年化 3.05%
A11: S010102010103 | B11: 2.1.1.3金市自营 FVTPL | C11: 资产 | D11: 债券投资类 | E11: FVTPL | F11: 投资 | G11: 人民币 | H11: 515 | I11: 500 | J11: =(H11+I11)/2 | K11: 0 | L11: =IF(K11>0,"是","否") | M11: 0.5 | N11: =IF(AND($C11="资产",$L11="是"),$J11*$K11,0) | O11: =IF(AND($C11="负债",$L11="是"),$J11*$K11,0) | P11: 金市自营 FVTPL 票息 0%
A12: S010102010201 | B12: 2.1.2.1司库 AC | C12: 资产 | D12: 债券投资类 | E12: AC | F12: 投资 | G12: 人民币 | H12: 5833.42 | I12: 5663.51 | J12: =(H12+I12)/2 | K12: 0.0325 | L12: =IF(K12>0,"是","否") | M12: 0.5 | N12: =IF(AND($C12="资产",$L12="是"),$J12*$K12,0) | O12: =IF(AND($C12="负债",$L12="是"),$J12*$K12,0) | P12: 司库 AC 年化 3.25%
A13: S010102010202 | B13: 2.1.2.2司库 FVOCI | C13: 资产 | D13: 债券投资类 | E13: FVOCI | F13: 投资 | G13: 人民币 | H13: 449.77 | I13: 436.67 | J13: =(H13+I13)/2 | K13: 0.0305 | L13: =IF(K13>0,"是","否") | M13: 0.5 | N13: =IF(AND($C13="资产",$L13="是"),$J13*$K13,0) | O13: =IF(AND($C13="负债",$L13="是"),$J13*$K13,0) | P13: 司库 FVOCI 年化 3.05%
A14: S010102010203 | B14: 2.1.2.3司库 FVTPL | C14: 资产 | D14: 债券投资类 | E14: FVTPL | F14: 投资 | G14: 人民币 | H14: 309 | I14: 300 | J14: =(H14+I14)/2 | K14: 0 | L14: =IF(K14>0,"是","否") | M14: 0.5 | N14: =IF(AND($C14="资产",$L14="是"),$J14*$K14,0) | O14: =IF(AND($C14="负债",$L14="是"),$J14*$K14,0) | P14: 司库 FVTPL 票息 0%
A15: S010102020000 | B15: 2.2.结构化融资 | C15: 资产 | D15: 金融市场类 | E15: 结构化 | F15: 金融 | G15: 人民币 | H15: 1908.1 | I15: 2051.72 | J15: =(H15+I15)/2 | K15: 0.0455 | L15: =IF(K15>0,"是","否") | M15: 0.85 | N15: =IF(AND($C15="资产",$L15="是"),$J15*$K15,0) | O15: =IF(AND($C15="负债",$L15="是"),$J15*$K15,0) | P15: 结构化融资 年化 4.55%
... A39: S020202000000 | B39: 2.外币市场化负债 | C39: 负债 | D39: 外币负债 | E39: 外币市场化 | F39: 外币 | G39: 外币 | H39: 752 | I39: 800 | J39: =(H39+I39)/2 | K39: 0.029 | L39: =IF(K39>0,"是","否") | M39: 0.95 | N39: =IF(AND($C39="资产",$L39="是"),$J39*$K39,0) | O39: =IF(AND($C39="负债",$L39="是"),$J39*$K39,0) | P39: 外币市场化负债 年化 2.90%
B40: 合计 / 加权平均 | H40: =SUM(H4:H39) | I40: =SUM(I4:I39) | J40: =SUM(J4:J39) | K40: =IF(J40=0,0,(SUMPRODUCT($J$4:$J$39,$K$4:$K$39))/J40) | N40: =SUM(N4:N39) | O40: =SUM(O4:O39) | P40: 净利息收入 NII = N40 - O40

Sheet 利息收入明细
A1: 利息收入明细表 (Interest Income Detail) — 逐资产账户拆解
A2: 利息收入 = 平均余额 × 年化利率（仅计入有效计息资产，利率 > 0） | 全部引用「NII数据源」sheet，不含硬编码 | 单位：亿元
A4: 账户编码 | B4: 账户名称 | C4: 业务条线 | D4: 子类 | E4: 账户类型 | F4: 币种 | G4: 期初余额 (亿元) | H4: 期末余额 (亿元) | I4: 平均余额 (亿元) | J4: 年化利率 | K4: 利息收入 (亿元) | L4: 利息收入 占比 | M4: 说明
A5: ='NII数据源'!A4 | B5: ='NII数据源'!B4 | C5: ='NII数据源'!D4 | D5: ='NII数据源'!E4 | E5: ='NII数据源'!F4 | F5: ='NII数据源'!G4 | G5: ='NII数据源'!H4 | H5: ='NII数据源'!I4 | I5: ='NII数据源'!J4 | J5: ='NII数据源'!K4 | K5: ='NII数据源'!N4 | L5: =IF($K$26=0,0,K5/$K$26) | M5: ='NII数据源'!P4
A6: ='NII数据源'!A5 | B6: ='NII数据源'!B5 | C6: ='NII数据源'!D5 | D6: ='NII数据源'!E5 | E6: ='NII数据源'!F5 | F6: ='NII数据源'!G5 | G6: ='NII数据源'!H5 | H6: ='NII数据源'!I5 | I6: ='NII数据源'!J5 | J6: ='NII数据源'!K5 | K6: ='NII数据源'!N5 | L6: =IF($K$26=0,0,K6/$K$26) | M6: ='NII数据源'!P5
A7: ='NII数据源'!A6 | B7: ='NII数据源'!B6 | C7: ='NII数据源'!D6 | D7: ='NII数据源'!E6 | E7: ='NII数据源'!F6 | F7: ='NII数据源'!G6 | G7: ='NII数据源'!H6 | H7: ='NII数据源'!I6 | I7: ='NII数据源'!J6 | J7: ='NII数据源'!K6 | K7: ='NII数据源'!N6 | L7: =IF($K$26=0,0,K7/$K$26) | M7: ='NII数据源'!P6
A8: ='NII数据源'!A7 | B8: ='NII数据源'!B7 | C8: ='NII数据源'!D7 | D8: ='NII数据源'!E7 | E8: ='NII数据源'!F7 | F8: ='NII数据源'!G7 | G8: ='NII数据源'!H7 | H8: ='NII数据源'!I7 | I8: ='NII数据源'!J7 | J8: ='NII数据源'!K7 | K8: ='NII数据源'!N7 | L8: =IF($K$26=0,0,K8/$K$26) | M8: ='NII数据源'!P7
A9: ='NII数据源'!A8 | B9: ='NII数据源'!B8 | C9: ='NII数据源'!D8 | D9: ='NII数据源'!E8 | E9: ='NII数据源'!F8 | F9: ='NII数据源'!G8 | G9: ='NII数据源'!H8 | H9: ='NII数据源'!I8 | I9: ='NII数据源'!J8 | J9: ='NII数据源'!K8 | K9: ='NII数据源'!N8 | L9: =IF($K$26=0,0,K9/$K$26) | M9: ='NII数据源'!P8
A10: ='NII数据源'!A9 | B10: ='NII数据源'!B9 | C10: ='NII数据源'!D9 | D10: ='NII数据源'!E9 | E10: ='NII数据源'!F9 | F10: ='NII数据源'!G9 | G10: ='NII数据源'!H9 | H10: ='NII数据源'!I9 | I10: ='NII数据源'!J9 | J10: ='NII数据源'!K9 | K10: ='NII数据源'!N9 | L10: =IF($K$26=0,0,K10/$K$26) | M10: ='NII数据源'!P9
A11: ='NII数据源'!A10 | B11: ='NII数据源'!B10 | C11: ='NII数据源'!D10 | D11: ='NII数据源'!E10 | E11: ='NII数据源'!F10 | F11: ='NII数据源'!G10 | G11: ='NII数据源'!H10 | H11: ='NII数据源'!I10 | I11: ='NII数据源'!J10 | J11: ='NII数据源'!K10 | K11: ='NII数据源'!N10 | L11: =IF($K$26=0,0,K11/$K$26) | M11: ='NII数据源'!P10
A12: ='NII数据源'!A11 | B12: ='NII数据源'!B11 | C12: ='NII数据源'!D11 | D12: ='NII数据源'!E11 | E12: ='NII数据源'!F11 | F12: ='NII数据源'!G11 | G12: ='NII数据源'!H11 | H12: ='NII数据源'!I11 | I12: ='NII数据源'!J11 | J12: ='NII数据源'!K11 | K12: ='NII数据源'!N11 | L12: =IF($K$26=0,0,K12/$K$26) | M12: ='NII数据源'!P11
A13: ='NII数据源'!A12 | B13: ='NII数据源'!B12 | C13: ='NII数据源'!D12 | D13: ='NII数据源'!E12 | E13: ='NII数据源'!F12 | F13: ='NII数据源'!G12 | G13: ='NII数据源'!H12 | H13: ='NII数据源'!I12 | I13: ='NII数据源'!J12 | J13: ='NII数据源'!K12 | K13: ='NII数据源'!N12 | L13: =IF($K$26=0,0,K13/$K$26) | M13: ='NII数据源'!P12
A14: ='NII数据源'!A13 | B14: ='NII数据源'!B13 | C14: ='NII数据源'!D13 | D14: ='NII数据源'!E13 | E14: ='NII数据源'!F13 | F14: ='NII数据源'!G13 | G14: ='NII数据源'!H13 | H14: ='NII数据源'!I13 | I14: ='NII数据源'!J13 | J14: ='NII数据源'!K13 | K14: ='NII数据源'!N13 | L14: =IF($K$26=0,0,K14/$K$26) | M14: ='NII数据源'!P13
A15: ='NII数据源'!A14 | B15: ='NII数据源'!B14 | C15: ='NII数据源'!D14 | D15: ='NII数据源'!E14 | E15: ='NII数据源'!F14 | F15: ='NII数据源'!G14 | G15: ='NII数据源'!H14 | H15: ='NII数据源'!I14 | I15: ='NII数据源'!J14 | J15: ='NII数据源'!K14 | K15: ='NII数据源'!N14 | L15: =IF($K$26=0,0,K15/$K$26) | M15: ='NII数据源'!P14
A16: ='NII数据源'!A15 | B16: ='NII数据源'!B15 | C16: ='NII数据源'!D15 | D16: ='NII数据源'!E15 | E16: ='NII数据源'!F15 | F16: ='NII数据源'!G15 | G16: ='NII数据源'!H15 | H16: ='NII数据源'!I15 | I16: ='NII数据源'!J15 | J16: ='NII数据源'!K15 | K16: ='NII数据源'!N15 | L16: =IF($K$26=0,0,K16/$K$26) | M16: ='NII数据源'!P15
... A25: ='NII数据源'!A24 | B25: ='NII数据源'!B24 | C25: ='NII数据源'!D24 | D25: ='NII数据源'!E24 | E25: ='NII数据源'!F24 | F25: ='NII数据源'!G24 | G25: ='NII数据源'!H24 | H25: ='NII数据源'!I24 | I25: ='NII数据源'!J24 | J25: ='NII数据源'!K24 | K25: ='NII数据源'!N24 | L25: =IF($K$26=0,0,K25/$K$26) | M25: ='NII数据源'!P24
A26: 【附】平均余额口径还原校验 —— 期末余额口径 vs 平均余额口径 | B26: 利息收入合计 | G26: =SUM(G5:G25) | H26: =SUM(H5:H25) | I26: =SUM(I5:I25) | J26: =IF(I26=0,0,K26/I26) | K26: =SUM(K5:K25) | L26: =IF(K26=0,0,SUM(L5:L25)) | M26: 合计行 I = 加权平均年化收益率，L = 占比合计应为 100%
B27: 期末余额口径利息收入（Σ 资产端 期末余额 × 利率） | K27: =SUMPRODUCT(('NII数据源'!$C$4:$C$39="资产")*('NII数据源'!$K$4:$K$39>0)*'NII数据源'!$I$4:$I$39,'NII数据源'!$K$4:$K$39) | M27: 与 K 列合计差额 = 平均余额法与期末余额法的利息差异
B28: 差额（平均口径 − 期末口径） | K28: =K26-K27 | M28: 规模扩张期平均余额 < 期末余额，资产端差额为负属正常

Sheet 利息支出明细
A1: 利息支出明细表 (Interest Expense Detail) — 逐负债账户拆解
A2: 利息支出 = 平均余额 × 年化利率（仅计入有效计息负债，利率 > 0） | 全部引用「NII数据源」sheet | 单位：亿元
A4: 账户编码 | B4: 账户名称 | C4: 业务条线 | D4: 子类 | E4: 账户类型 | F4: 币种 | G4: 期初余额 (亿元) | H4: 期末余额 (亿元) | I4: 平均余额 (亿元) | J4: 年化利率 | K4: 利息支出 (亿元) | L4: 利息支出 占比 | M4: 说明
A5: ='NII数据源'!A25 | B5: ='NII数据源'!B25 | C5: ='NII数据源'!D25 | D5: ='NII数据源'!E25 | E5: ='NII数据源'!F25 | F5: ='NII数据源'!G25 | G5: ='NII数据源'!H25 | H5: ='NII数据源'!I25 | I5: ='NII数据源'!J25 | J5: ='NII数据源'!K25 | K5: ='NII数据源'!O25 | L5: =IF($K$20=0,0,K5/$K$20) | M5: ='NII数据源'!P25
A6: ='NII数据源'!A26 | B6: ='NII数据源'!B26 | C6: ='NII数据源'!D26 | D6: ='NII数据源'!E26 | E6: ='NII数据源'!F26 | F6: ='NII数据源'!G26 | G6: ='NII数据源'!H26 | H6: ='NII数据源'!I26 | I6: ='NII数据源'!J26 | J6: ='NII数据源'!K26 | K6: ='NII数据源'!O26 | L6: =IF($K$20=0,0,K6/$K$20) | M6: ='NII数据源'!P26
A7: ='NII数据源'!A27 | B7: ='NII数据源'!B27 | C7: ='NII数据源'!D27 | D7: ='NII数据源'!E27 | E7: ='NII数据源'!F27 | F7: ='NII数据源'!G27 | G7: ='NII数据源'!H27 | H7: ='NII数据源'!I27 | I7: ='NII数据源'!J27 | J7: ='NII数据源'!K27 | K7: ='NII数据源'!O27 | L7: =IF($K$20=0,0,K7/$K$20) | M7: ='NII数据源'!P27
A8: ='NII数据源'!A28 | B8: ='NII数据源'!B28 | C8: ='NII数据源'!D28 | D8: ='NII数据源'!E28 | E8: ='NII数据源'!F28 | F8: ='NII数据源'!G28 | G8: ='NII数据源'!H28 | H8: ='NII数据源'!I28 | I8: ='NII数据源'!J28 | J8: ='NII数据源'!K28 | K8: ='NII数据源'!O28 | L8: =IF($K$20=0,0,K8/$K$20) | M8: ='NII数据源'!P28
A9: ='NII数据源'!A29 | B9: ='NII数据源'!B29 | C9: ='NII数据源'!D29 | D9: ='NII数据源'!E29 | E9: ='NII数据源'!F29 | F9: ='NII数据源'!G29 | G9: ='NII数据源'!H29 | H9: ='NII数据源'!I29 | I9: ='NII数据源'!J29 | J9: ='NII数据源'!K29 | K9: ='NII数据源'!O29 | L9: =IF($K$20=0,0,K9/$K$20) | M9: ='NII数据源'!P29
A10: ='NII数据源'!A30 | B10: ='NII数据源'!B30 | C10: ='NII数据源'!D30 | D10: ='NII数据源'!E30 | E10: ='NII数据源'!F30 | F10: ='NII数据源'!G30 | G10: ='NII数据源'!H30 | H10: ='NII数据源'!I30 | I10: ='NII数据源'!J30 | J10: ='NII数据源'!K30 | K10: ='NII数据源'!O30 | L10: =IF($K$20=0,0,K10/$K$20) | M10: ='NII数据源'!P30
A11: ='NII数据源'!A31 | B11: ='NII数据源'!B31 | C11: ='NII数据源'!D31 | D11: ='NII数据源'!E31 | E11: ='NII数据源'!F31 | F11: ='NII数据源'!G31 | G11: ='NII数据源'!H31 | H11: ='NII数据源'!I31 | I11: ='NII数据源'!J31 | J11: ='NII数据源'!K31 | K11: ='NII数据源'!O31 | L11: =IF($K$20=0,0,K11/$K$20) | M11: ='NII数据源'!P31
A12: ='NII数据源'!A32 | B12: ='NII数据源'!B32 | C12: ='NII数据源'!D32 | D12: ='NII数据源'!E32 | E12: ='NII数据源'!F32 | F12: ='NII数据源'!G32 | G12: ='NII数据源'!H32 | H12: ='NII数据源'!I32 | I12: ='NII数据源'!J32 | J12: ='NII数据源'!K32 | K12: ='NII数据源'!O32 | L12: =IF($K$20=0,0,K12/$K$20) | M12: ='NII数据源'!P32
A13: ='NII数据源'!A33 | B13: ='NII数据源'!B33 | C13: ='NII数据源'!D33 | D13: ='NII数据源'!E33 | E13: ='NII数据源'!F33 | F13: ='NII数据源'!G33 | G13: ='NII数据源'!H33 | H13: ='NII数据源'!I33 | I13: ='NII数据源'!J33 | J13: ='NII数据源'!K33 | K13: ='NII数据源'!O33 | L13: =IF($K$20=0,0,K13/$K$20) | M13: ='NII数据源'!P33
A14: ='NII数据源'!A34 | B14: ='NII数据源'!B34 | C14: ='NII数据源'!D34 | D14: ='NII数据源'!E34 | E14: ='NII数据源'!F34 | F14: ='NII数据源'!G34 | G14: ='NII数据源'!H34 | H14: ='NII数据源'!I34 | I14: ='NII数据源'!J34 | J14: ='NII数据源'!K34 | K14: ='NII数据源'!O34 | L14: =IF($K$20=0,0,K14/$K$20) | M14: ='NII数据源'!P34
A15: ='NII数据源'!A35 | B15: ='NII数据源'!B35 | C15: ='NII数据源'!D35 | D15: ='NII数据源'!E35 | E15: ='NII数据源'!F35 | F15: ='NII数据源'!G35 | G15: ='NII数据源'!H35 | H15: ='NII数据源'!I35 | I15: ='NII数据源'!J35 | J15: ='NII数据源'!K35 | K15: ='NII数据源'!O35 | L15: =IF($K$20=0,0,K15/$K$20) | M15: ='NII数据源'!P35
A16: ='NII数据源'!A36 | B16: ='NII数据源'!B36 | C16: ='NII数据源'!D36 | D16: ='NII数据源'!E36 | E16: ='NII数据源'!F36 | F16: ='NII数据源'!G36 | G16: ='NII数据源'!H36 | H16: ='NII数据源'!I36 | I16: ='NII数据源'!J36 | J16: ='NII数据源'!K36 | K16: ='NII数据源'!O36 | L16: =IF($K$20=0,0,K16/$K$20) | M16: ='NII数据源'!P36
... A19: ='NII数据源'!A39 | B19: ='NII数据源'!B39 | C19: ='NII数据源'!D39 | D19: ='NII数据源'!E39 | E19: ='NII数据源'!F39 | F19: ='NII数据源'!G39 | G19: ='NII数据源'!H39 | H19: ='NII数据源'!I39 | I19: ='NII数据源'!J39 | J19: ='NII数据源'!K39 | K19: ='NII数据源'!O39 | L19: =IF($K$20=0,0,K19/$K$20) | M19: ='NII数据源'!P39
A20: 【附】平均余额口径还原校验 —— 期末余额口径 vs 平均余额口径 | B20: 利息支出合计 | G20: =SUM(G5:G19) | H20: =SUM(H5:H19) | I20: =SUM(I5:I19) | J20: =IF(I20=0,0,K20/I20) | K20: =SUM(K5:K19) | L20: =IF(K20=0,0,SUM(L5:L19)) | M20: 合计行 I = 加权平均成本率，L = 占比合计应为 100%
B21: 期末余额口径利息支出（Σ 负债端 期末余额 × 利率） | K21: =SUMPRODUCT(('NII数据源'!$C$4:$C$39="负债")*('NII数据源'!$K$4:$K$39>0)*'NII数据源'!$I$4:$I$39,'NII数据源'!$K$4:$K$39) | M21: 与 K 列合计差额 = 平均余额法与期末余额法的利息差异
B22: 差额（平均口径 − 期末口径） | K22: =K20-K21 | M22: 负债端扩张通常快于资产端，差额可能为正

Sheet NII计量表
A1: 净利息收入（NII）计量表 — 中信银行 2025-12-31
A2: NII = 利息收入 − 利息支出 | NIM = NII ÷ 平均生息资产 | 本表所有数值引用「利息收入明细」「利息支出明细」，逐级联动 | 单位：亿元 / %
A4: 【一】生息资产与计息负债规模
A5: 平均生息资产合计（有效计息，利率 > 0） | B5: =SUMPRODUCT(('NII数据源'!$C$4:$C$39="资产")*('NII数据源'!$K$4:$K$39>0)*'NII数据源'!$J$4:$J$39) | C5: =IF($B$5=0,0,B5/$B$5) | D5: 亿元 | E5: 剔除 FVTPL / 现金 / 其它非生息 / 外币非生息（利率 = 0 的资产）
A6: 其中：人民币生息资产 | B6: =SUMPRODUCT(('NII数据源'!$G$4:$G$39="人民币")*('NII数据源'!$C$4:$C$39="资产")*('NII数据源'!$K$4:$K$39>0)*'NII数据源'!$J$4:$J$39) | C6: =IF($B$5=0,0,B6/$B$5) | D6: 亿元 | E6: 人民币计价且利率 > 0
A7: 其中：外币生息资产（折人民币） | B7: =SUMPRODUCT(('NII数据源'!$G$4:$G$39="外币")*('NII数据源'!$C$4:$C$39="资产")*('NII数据源'!$K$4:$K$39>0)*'NII数据源'!$J$4:$J$39) | C7: =IF($B$5=0,0,B7/$B$5) | D7: 亿元 | E7: 外币计价且利率 > 0
A8: 已剔除非生息资产（利率 = 0 的资产） | B8: =SUMPRODUCT(('NII数据源'!$C$4:$C$39="资产")*('NII数据源'!$K$4:$K$39=0)*'NII数据源'!$J$4:$J$39) | C8: =IF($B$5=0,0,B8/$B$5) | D8: 亿元 | E8: FVTPL / 现金 / 其它 / 外币非生息，单列备查
A9: 平均计息负债合计（有效计息，利率 > 0） | B9: ='利息支出明细'!I20 | C9: =IF($B$5=0,0,B9/$B$5) | D9: 亿元 | E9: 全部计息负债利率均 > 0
A10: 其中：存款类负债 | B10: =SUMIF('NII数据源'!$D$4:$D$39,"存款类",'NII数据源'!$J$4:$J$39) | C10: =IF($B$5=0,0,B10/$B$5) | D10: 亿元 | E10: 对公活期/定期 + 零售活期/定期
A11: 其中：同业负债 | B11: =SUMIF('NII数据源'!$D$4:$D$39,"同业负债",'NII数据源'!$J$4:$J$39) | C11: =IF($B$5=0,0,B11/$B$5) | D11: 亿元 | E11: 同业拆入/回购/NCD/同业存款/票据转贴现
A12: 其中：央行借款 | B12: =SUMIF('NII数据源'!$D$4:$D$39,"央行借款",'NII数据源'!$J$4:$J$39) | C12: =IF($B$5=0,0,B12/$B$5) | D12: 亿元 | E12: OMO / MLF / 结构性工具 / 再贴现
A13: 其中：外币负债（折人民币） | B13: =SUMIF('NII数据源'!$D$4:$D$39,"外币负债",'NII数据源'!$J$4:$J$39) | C13: =IF($B$5=0,0,B13/$B$5) | D13: 亿元 | E13: 外币存款 + 外币市场化负债
A15: 【二】利息收入与利息支出
A16: 利息收入合计（平均余额口径） | B16: ='利息收入明细'!K26 | D16: 亿元 | E16: 资产端
A17: 利息收入合计（期末余额口径） | B17: ='利息收入明细'!K27 | D17: 亿元 | E17: 资产端
A18: 利息支出合计（平均余额口径） | B18: ='利息支出明细'!K20 | D18: 亿元 | E18: 负债端
A19: 利息支出合计（期末余额口径） | B19: ='利息支出明细'!K21 | D19: 亿元 | E19: 负债端
A21: 【三】净利息收入 NII（核心指标）
A22: 净利息收入 NII（平均余额口径，主口径） | B22: =B16-B18 | D22: 亿元 | E22: NII = 利息收入 − 利息支出；本模版主口径
A23: 净利息收入 NII（期末余额口径） | B23: =B17-B19 | D23: 亿元 | E23: 简化口径，用于与未披露期初余额的报表直接对比
A24: 两口径差额（平均口径 − 期末口径） | B24: =B22-B23 | D24: 亿元 | E24: 反映年度平均余额与期末余额的规模差异
A26: 【四】利差与净息差核心比率
A27: 生息资产收益率（利息收入 ÷ 平均生息资产） | B27: =IF($B$5=0,0,$B$16/$B$5) | D27: % | E27: 资产端盈利能力
A28: 计息负债成本率（利息支出 ÷ 平均计息负债） | B28: =IF($B$9=0,0,$B$18/$B$9) | D28: % | E28: 负债端付息成本
A29: 净利差 NIS（净收益率 − 净成本率） | B29: =B27-B28 | D29: % | E29: 资产端与负债端定价之差
A30: 净息差 NIM（NII ÷ 平均生息资产） | B30: =IF($B$5=0,0,$B$22/$B$5) | D30: % | E30: ★ NII 计量最终输出指标
A31: 平均生息资产收益率（期末口径 NIM） | B31: =IF($B$5=0,0,$B$23/$B$5) | D31: % | E31: 简化口径 NIM
A33: 【五】资产负债结构与存款成本辅助比率
A34: 平均贷款余额（5 项贷款） | B34: =SUMIF('NII数据源'!$D$4:$D$39,"贷款类",'NII数据源'!$J$4:$J$39) | D34: 亿元 | E34: 对公/个人/信用卡/票据/非银
A35: 平均存款余额（4 项存款） | B35: =SUMIF('NII数据源'!$D$4:$D$39,"存款类",'NII数据源'!$J$4:$J$39) | D35: 亿元 | E35: 对公活期/定期 + 零售活期/定期
A36: 存贷比（平均贷款 ÷ 平均计息负债） | B36: =IF($B$9=0,0,$B$34/$B$9) | D36: % | E36: 监管上限 100%（现行为 75% 分档考核）
A37: 生息资产占资产端余额比重 | B37: =IF(SUMIF('NII数据源'!$C$4:$C$39,"资产",'NII数据源'!$J$4:$J$39)=0,0,$B$5/SUMIF('NII数据源'!$C$4:$C$39,"资产",'NII数据源'!$J$4:$J$39)) | D37: % | E37: 1 − 剔除非生息资产后的资产结构占比
A38: 贷存比（平均贷款 ÷ 平均存款） | B38: =IF($B$35=0,0,$B$34/$B$35) | D38: % | E38: 存款对贷款的覆盖程度，贷存比越低存款沉淀越充分
A39: 活期存款占存款比重（活期化率） | B39: =IF($B$35=0,0,SUMIF('NII数据源'!$F$4:$F$39,"活期",'NII数据源'!$J$4:$J$39)/$B$35) | D39: % | E39: 活期付息成本极低，活期化率越高 → 负债成本越低 → NIM 越高
A41: 【六】勾稽校验（校验 1~7 应全部为 0）
A42: 校验 1：利息收入明细合计 = 数据源 Σ 利息收入 | B42: =ROUND('利息收入明细'!K26-'NII数据源'!N40,6) | D42: 亿元 | E42: 明细 ↔ 数据源交叉勾稽
A43: 校验 2：利息支出明细合计 = 数据源 Σ 利息支出 | B43: =ROUND('利息支出明细'!K20-'NII数据源'!O40,6) | D43: 亿元 | E43: 明细 ↔ 数据源交叉勾稽
A44: 校验 3：利息收入占比合计 = 100% | B44: =ROUND('利息收入明细'!L26-1,8) | D44: 亿元 | E44: 占比无重复无遗漏
A45: 校验 4：利息支出占比合计 = 100% | B45: =ROUND('利息支出明细'!L20-1,8) | D45: 亿元 | E45: 占比无重复无遗漏
A46: 校验 5：NII = 利息收入 − 利息支出（核心恒等式） | B46: =ROUND($B$22-($B$16-$B$18),8) | D46: 亿元 | E46: NII 主口径恒等式自检
...

Sheet NII结构拆解
A1: NII 结构拆解分析 (Net Interest Income Decomposition)
A2: 按业务条线 / 币种 / 账户类型三维拆解 NII 贡献 | 全部由 SUMIF 引用「NII数据源」，联动更新 | 单位：亿元
A4: 【一】按业务条线拆解 —— 资产端
A5: 业务条线 | B5: 平均余额 (亿元) | C5: 余额占比 | D5: 利息收入 (亿元) | E5: 利息占比 | F5: 综合收益率 | G5: 余额贡献 (百分点) | H5: 利息贡献 (百分点) | I5: 说明
A6: 贷款类 | B6: =SUMIF('NII数据源'!$D$4:$D$39,"贷款类",'NII数据源'!$J$4:$J$39) | C6: =IF($B$11=0,0,B6/$B$11) | D6: =SUMIF('NII数据源'!$D$4:$D$39,"贷款类",'NII数据源'!$N$4:$N$39) | E6: =IF($D$11=0,0,D6/$D$11) | F6: =IF(B6=0,0,D6/B6) | G6: =IF($B$11=0,0,B6/$B$11*F6) | H6: =IF($B$11=0,0,B6/$B$11*$B$27) | I6: 核心生息资产，占比最高但收益率由信用卡拉升
A7: 债券投资类 | B7: =SUMIF('NII数据源'!$D$4:$D$39,"债券投资类",'NII数据源'!$J$4:$J$39) | C7: =IF($B$11=0,0,B7/$B$11) | D7: =SUMIF('NII数据源'!$D$4:$D$39,"债券投资类",'NII数据源'!$N$4:$N$39) | E7: =IF($D$11=0,0,D7/$D$11) | F7: =IF(B7=0,0,D7/B7) | G7: =IF($B$11=0,0,B7/$B$11*F7) | H7: =IF($B$11=0,0,B7/$B$11*$B$27) | I7: 低波动收益来源，AC/FVOCI 计入，票息 FVTPL 为 0
A8: 金融市场类 | B8: =SUMIF('NII数据源'!$D$4:$D$39,"金融市场类",'NII数据源'!$J$4:$J$39) | C8: =IF($B$11=0,0,B8/$B$11) | D8: =SUMIF('NII数据源'!$D$4:$D$39,"金融市场类",'NII数据源'!$N$4:$N$39) | E8: =IF($D$11=0,0,D8/$D$11) | F8: =IF(B8=0,0,D8/B8) | G8: =IF($B$11=0,0,B8/$B$11*F8) | H8: =IF($B$11=0,0,B8/$B$11*$B$27) | I8: 同业资产/准备金/结构化融资，利率随货币市场波动
A9: 非生息资产 | B9: =SUMIF('NII数据源'!$D$4:$D$39,"非生息资产",'NII数据源'!$J$4:$J$39) | C9: =IF($B$11=0,0,B9/$B$11) | D9: =SUMIF('NII数据源'!$D$4:$D$39,"非生息资产",'NII数据源'!$N$4:$N$39) | E9: =IF($D$11=0,0,D9/$D$11) | F9: =IF(B9=0,0,D9/B9) | G9: =IF($B$11=0,0,B9/$B$11*F9) | H9: =IF($B$11=0,0,B9/$B$11*$B$27) | I9: FVTPL/现金/其它，利率 0%，已从 NII 计量中剔除
A10: 外币资产 | B10: =SUMIF('NII数据源'!$D$4:$D$39,"外币资产",'NII数据源'!$J$4:$J$39) | C10: =IF($B$11=0,0,B10/$B$11) | D10: =SUMIF('NII数据源'!$D$4:$D$39,"外币资产",'NII数据源'!$N$4:$N$39) | E10: =IF($D$11=0,0,D10/$D$11) | F10: =IF(B10=0,0,D10/B10) | G10: =IF($B$11=0,0,B10/$B$11*F10) | H10: =IF($B$11=0,0,B10/$B$11*$B$27) | I10: 外币折人民币计价，受汇率与境外利率双重影响
A11: 资产端合计 | B11: =SUM(B6:B10) | D11: =SUM(D6:D10)
A13: 【二】按业务条线拆解 —— 负债端
A14: 业务条线 | B14: 平均余额 (亿元) | C14: 余额占比 | D14: 利息支出 (亿元) | E14: 利息占比 | F14: 综合成本率 | G14: 余额贡献 (百分点) | H14: 利息贡献 (百分点) | I14: 说明
A15: 存款类 | B15: =SUMIF('NII数据源'!$D$4:$D$39,"存款类",'NII数据源'!$J$4:$J$39) | C15: =IF($B$19=0,0,B15/$B$19) | D15: =SUMIF('NII数据源'!$D$4:$D$39,"存款类",'NII数据源'!$O$4:$O$39) | E15: =IF($D$19=0,0,D15/$D$19) | F15: =IF(B15=0,0,D15/B15) | G15: =IF($B$19=0,0,B15/$B$19*F15) | H15: =IF($B$19=0,0,B15/$B$19*$B$28) | I15: 最大负债来源，活期占比高是成本率低的关键
A16: 同业负债 | B16: =SUMIF('NII数据源'!$D$4:$D$39,"同业负债",'NII数据源'!$J$4:$J$39) | C16: =IF($B$19=0,0,B16/$B$19) | D16: =SUMIF('NII数据源'!$D$4:$D$39,"同业负债",'NII数据源'!$O$4:$O$39) | E16: =IF($D$19=0,0,D16/$D$19) | F16: =IF(B16=0,0,D16/B16) | G16: =IF($B$19=0,0,B16/$B$19*F16) | H16: =IF($B$19=0,0,B16/$B$19*$B$28) | I16: 市场化定价，重定价 β 接近 1，利率敏感度高
A17: 央行借款 | B17: =SUMIF('NII数据源'!$D$4:$D$39,"央行借款",'NII数据源'!$J$4:$J$39) | C17: =IF($B$19=0,0,B17/$B$19) | D17: =SUMIF('NII数据源'!$D$4:$D$39,"央行借款",'NII数据源'!$O$4:$O$39) | E17: =IF($D$19=0,0,D17/$D$19) | F17: =IF(B17=0,0,D17/B17) | G17: =IF($B$19=0,0,B17/$B$19*F17) | H17: =IF($B$19=0,0,B17/$B$19*$B$28) | I17: 政策工具，成本由政策利率决定，主动性可控
A18: 外币负债 | B18: =SUMIF('NII数据源'!$D$4:$D$39,"外币负债",'NII数据源'!$J$4:$J$39) | C18: =IF($B$19=0,0,B18/$B$19) | D18: =SUMIF('NII数据源'!$D$4:$D$39,"外币负债",'NII数据源'!$O$4:$O$39) | E18: =IF($D$19=0,0,D18/$D$19) | F18: =IF(B18=0,0,D18/B18) | G18: =IF($B$19=0,0,B18/$B$19*F18) | H18: =IF($B$19=0,0,B18/$B$19*$B$28) | I18: 外币折人民币，受汇率折算影响
A19: 负债端合计 | B19: =SUM(B15:B18) | D19: =SUM(D15:D18)
A21: 【三】按币种拆解
A22: 币种 / 方向 | B22: 平均余额 (亿元) | C22: 余额占比 | D22: 利息金额 (亿元) | E22: 利息占比 | F22: 综合利率 | G22: — | H22: — | I22: 说明
A23: 人民币·资产 | B23: =SUMPRODUCT(('NII数据源'!$G$4:$G$39="人民币")*('NII数据源'!$C$4:$C$39="资产")*'NII数据源'!$J$4:$J$39) | C23: =IF(SUM('NII数据源'!$J$4:$J$39)=0,0,B23/SUM('NII数据源'!$J$4:$J$39)) | D23: =SUMPRODUCT(('NII数据源'!$G$4:$G$39="人民币")*('NII数据源'!$C$4:$C$39="资产")*'NII数据源'!$N$4:$N$39) | E23: =IF(SUM('NII数据源'!$N$4:$N$39)+SUM('NII数据源'!$O$4:$O$39)=0,0,D23/(SUM('NII数据源'!$N$4:$N$39)+SUM('NII数据源'!$O$4:$O$39))) | F23: =IF(B23=0,0,D23/B23) | I23: 人民币计价资产
A24: 人民币·负债 | B24: =SUMPRODUCT(('NII数据源'!$G$4:$G$39="人民币")*('NII数据源'!$C$4:$C$39="负债")*'NII数据源'!$J$4:$J$39) | C24: =IF(SUM('NII数据源'!$J$4:$J$39)=0,0,B24/SUM('NII数据源'!$J$4:$J$39)) | D24: =SUMPRODUCT(('NII数据源'!$G$4:$G$39="人民币")*('NII数据源'!$C$4:$C$39="负债")*'NII数据源'!$O$4:$O$39) | E24: =IF(SUM('NII数据源'!$N$4:$N$39)+SUM('NII数据源'!$O$4:$O$39)=0,0,D24/(SUM('NII数据源'!$N$4:$N$39)+SUM('NII数据源'!$O$4:$O$39))) | F24: =IF(B24=0,0,D24/B24) | I24: 人民币计价负债
A25: 外币·资产 | B25: =SUMPRODUCT(('NII数据源'!$G$4:$G$39="外币")*('NII数据源'!$C$4:$C$39="资产")*'NII数据源'!$J$4:$J$39) | C25: =IF(SUM('NII数据源'!$J$4:$J$39)=0,0,B25/SUM('NII数据源'!$J$4:$J$39)) | D25: =SUMPRODUCT(('NII数据源'!$G$4:$G$39="外币")*('NII数据源'!$C$4:$C$39="资产")*'NII数据源'!$N$4:$N$39) | E25: =IF(SUM('NII数据源'!$N$4:$N$39)+SUM('NII数据源'!$O$4:$O$39)=0,0,D25/(SUM('NII数据源'!$N$4:$N$39)+SUM('NII数据源'!$O$4:$O$39))) | F25: =IF(B25=0,0,D25/B25) | I25: 外币折人民币资产
A26: 外币·负债 | B26: =SUMPRODUCT(('NII数据源'!$G$4:$G$39="外币")*('NII数据源'!$C$4:$C$39="负债")*'NII数据源'!$J$4:$J$39) | C26: =IF(SUM('NII数据源'!$J$4:$J$39)=0,0,B26/SUM('NII数据源'!$J$4:$J$39)) | D26: =SUMPRODUCT(('NII数据源'!$G$4:$G$39="外币")*('NII数据源'!$C$4:$C$39="负债")*'NII数据源'!$O$4:$O$39) | E26: =IF(SUM('NII数据源'!$N$4:$N$39)+SUM('NII数据源'!$O$4:$O$39)=0,0,D26/(SUM('NII数据源'!$N$4:$N$39)+SUM('NII数据源'!$O$4:$O$39))) | F26: =IF(B26=0,0,D26/B26) | I26: 外币折人民币负债
A27: 人民币净利息收入 | D27: =D23-D24 | I27: 人民币 NII = 人民币利息收入 − 人民币利息支出
A28: 外币净利息收入 | D28: =D25-D26 | I28: 外币 NII = 外币利息收入 − 外币利息支出
A29: NII 合计校验（应 = NII计量表 主口径） | D29: =SUM(D27:D28)-'NII计量表'!B22 | I29: 差额应为 0，证明币种维度与总表完全勾稽
A31: 【四】按账户类型拆解 —— 活期/定期结构
A32: 账户类型 | B32: 平均余额 (亿元) | C32: 余额占比 | D32: 利息金额 (亿元) | E32: 利息占比 | F32: 综合利率 | G32: — | H32: — | I32: 说明
A33: 活期类存款（对公+零售） | B33: =SUMIF('NII数据源'!$F$4:$F$39,"活期",'NII数据源'!$J$4:$J$39) | C33: =IF(SUMIF('NII数据源'!$D$4:$D$39,"存款类",'NII数据源'!$J$4:$J$39)=0,0,B33/SUMIF('NII数据源'!$D$4:$D$39,"存款类",'NII数据源'!$J$4:$J$39)) | D33: =SUMIF('NII数据源'!$F$4:$F$39,"活期",'NII数据源'!$O$4:$O$39) | E33: =IF(SUM('NII数据源'!$N$4:$N$39)+SUM('NII数据源'!$O$4:$O$39)=0,0,D33/(SUM('NII数据源'!$N$4:$N$39)+SUM('NII数据源'!$O$4:$O$39))) | F33: =IF(B33=0,0,D33/B33) | I33: 活期存款付息成本极低，是存款成本管控的核心抓手
A34: 定期类存款（对公+零售） | B34: =SUMIF('NII数据源'!$F$4:$F$39,"定期",'NII数据源'!$J$4:$J$39) | C34: =IF(SUMIF('NII数据源'!$D$4:$D$39,"存款类",'NII数据源'!$J$4:$J$39)=0,0,B34/SUMIF('NII数据源'!$D$4:$D$39,"存款类",'NII数据源'!$J$4:$J$39)) | D34: =SUMIF('NII数据源'!$F$4:$F$39,"定期",'NII数据源'!$O$4:$O$39) | E34: =IF(SUM('NII数据源'!$N$4:$N$39)+SUM('NII数据源'!$O$4:$O$39)=0,0,D34/(SUM('NII数据源'!$N$4:$N$39)+SUM('NII数据源'!$O$4:$O$39))) | F34: =IF(B34=0,0,D34/B34) | I34: 定期存款占比上升将直接推高负债成本率
A35: 信贷类资产（贷款 5 项） | B35: =SUMIF('NII数据源'!$F$4:$F$39,"信贷",'NII数据源'!$J$4:$J$39) | C35: =IF(SUMIF('NII数据源'!$D$4:$D$39,"贷款类",'NII数据源'!$J$4:$J$39)=0,0,B35/SUMIF('NII数据源'!$D$4:$D$39,"贷款类",'NII数据源'!$J$4:$J$39)) | D35: =SUMIF('NII数据源'!$F$4:$F$39,"信贷",'NII数据源'!$N$4:$N$39) | E35: =IF(SUM('NII数据源'!$N$4:$N$39)+SUM('NII数据源'!$O$4:$O$39)=0,0,D35/(SUM('NII数据源'!$N$4:$N$39)+SUM('NII数据源'!$O$4:$O$39))) | F35: =IF(B35=0,0,D35/B35) | I35: 贷款类资产平均余额，资产端规模主体
A36: 非息类资产（FVTPL/现金/其它） | B36: =SUMIF('NII数据源'!$F$4:$F$39,"非息",'NII数据源'!$J$4:$J$39) | C36: =IF(SUMIF('NII数据源'!$D$4:$D$39,"贷款类",'NII数据源'!$J$4:$J$39)=0,0,B36/SUMIF('NII数据源'!$D$4:$D$39,"贷款类",'NII数据源'!$J$4:$J$39)) | D36: =SUMIF('NII数据源'!$F$4:$F$39,"非息",'NII数据源'!$N$4:$N$39) | E36: =IF(SUM('NII数据源'!$N$4:$N$39)+SUM('NII数据源'!$O$4:$O$39)=0,0,D36/(SUM('NII数据源'!$N$4:$N$39)+SUM('NII数据源'!$O$4:$O$39))) | F36: =IF(B36=0,0,D36/B36) | I36: 利率 0%，不产生利息收入，仅作规模对照
A37: 存款活期化率（活期 ÷ 存款合计） | B37: =IF(SUMIF('NII数据源'!$D$4:$D$39,"存款类",'NII数据源'!$J$4:$J$39)=0,0,B33/SUMIF('NII数据源'!$D$4:$D$39,"存款类",'NII数据源'!$J$4:$J$39)) | I37: 活期化率越高 → 计息负债成本率越低 → NIM 越高
A38: 存款校验：活期 + 定期 = 存款类合计 | B38: =ROUND(B33+B34-SUMIF('NII数据源'!$D$4:$D$39,"存款类",'NII数据源'!$J$4:$J$39),6) | I38: 差额应为 0
A39: 定期存款占比（定期 ÷ 存款合计） | B39: =IF(SUMIF('NII数据源'!$D$4:$D$39,"存款类",'NII数据源'!$J$4:$J$39)=0,0,B34/SUMIF('NII数据源'!$D$4:$D$39,"存款类",'NII数据源'!$J$4:$J$39)) | I39: 定期占比越高 → 负债成本率越高 → NIM 越低

Sheet NII情景敏感性
A1: NII 情景敏感性分析 (NII Scenario Sensitivity) — 利率平行移动冲击
A2: ΔNII = −Δr × (Σ 资产余额×β − Σ 负债余额×β) | 重定价敞口由 SUMPRODUCT(平均余额, 重定价β) 计算，直接引用「NII数据源」 | 单位：亿元
A4: 【一】重定价敞口计算（核心驱动量）
A5: 有效生息资产重定价敞口 A_β = Σ(平均余额 × 重定价β) | C5: =SUMPRODUCT(('NII数据源'!$C$4:$C$39="资产")*('NII数据源'!$K$4:$K$39>0)*'NII数据源'!$J$4:$J$39,'NII数据源'!$M$4:$M$39) | D5: 亿元 | I5: 1 年内可重定价的生息资产规模（利率 > 0）
A6: 其中：贷款类 A_β | C6: =SUMPRODUCT(('NII数据源'!$D$4:$D$39="贷款类")*'NII数据源'!$J$4:$J$39,'NII数据源'!$M$4:$M$39) | D6: 亿元 | I6: 贷款重定价较慢，β 约 0.6~0.9
A7: 其中：债券投资类 A_β | C7: =SUMPRODUCT(('NII数据源'!$D$4:$D$39="债券投资类")*('NII数据源'!$K$4:$K$39>0)*'NII数据源'!$J$4:$J$39,'NII数据源'!$M$4:$M$39) | D7: 亿元 | I7: 债券票息重定价滞后，β 约 0.5
A8: 其中：金融市场类 A_β | C8: =SUMPRODUCT(('NII数据源'!$D$4:$D$39="金融市场类")*'NII数据源'!$J$4:$J$39,'NII数据源'!$M$4:$M$39) | D8: 亿元 | I8: 同业/准备金随货币市场波动，β 约 0.85~0.95
A9: 其中：外币资产 A_β | C9: =SUMPRODUCT(('NII数据源'!$D$4:$D$39="外币资产")*('NII数据源'!$K$4:$K$39>0)*'NII数据源'!$J$4:$J$39,'NII数据源'!$M$4:$M$39) | D9: 亿元 | I9: 外币资产折人民币，受境内外双重影响
A10: 有效计息负债重定价敞口 L_β = Σ(平均余额 × 重定价β) | C10: =SUMPRODUCT(('NII数据源'!$C$4:$C$39="负债")*'NII数据源'!$J$4:$J$39,'NII数据源'!$M$4:$M$39) | D10: 亿元 | I10: 1 年内可重定价的计息负债规模
A11: 其中：存款类 L_β | C11: =SUMPRODUCT(('NII数据源'!$D$4:$D$39="存款类")*'NII数据源'!$J$4:$J$39,'NII数据源'!$M$4:$M$39) | D11: 亿元 | I11: 活期 β 仅 0.25，是负债重定价慢的主因
A12: 其中：同业负债 L_β | C12: =SUMPRODUCT(('NII数据源'!$D$4:$D$39="同业负债")*'NII数据源'!$J$4:$J$39,'NII数据源'!$M$4:$M$39) | D12: 亿元 | I12: 市场化定价，β 0.9~0.98，重定价最快
A13: 其中：央行借款 L_β | C13: =SUMPRODUCT(('NII数据源'!$D$4:$D$39="央行借款")*'NII数据源'!$J$4:$J$39,'NII数据源'!$M$4:$M$39) | D13: 亿元 | I13: 政策工具，β 0.8~0.95
A14: 其中：外币负债 L_β | C14: =SUMPRODUCT(('NII数据源'!$D$4:$D$39="外币负债")*'NII数据源'!$J$4:$J$39,'NII数据源'!$M$4:$M$39) | D14: 亿元 | I14: 外币折人民币负债
A15: ★ 重定价缺口 RG = A_β − L_β | C15: =C5-C10 | D15: 亿元 | I15: ★ RG > 0 → 利率上行时 NII 受损（正缺口）；RG < 0 → 利率上行时 NII 受益（负缺口）
A16: 利率每平行上移 10bp 对 NII 的影响 | C16: =-C15*0.001 | D16: 亿元 | I16: =−RG × 0.001，单位：亿元 NII / 每 10bp
A17: NII 利率弹性（−RG ÷ 平均生息资产） | C17: =IF('NII计量表'!B5=0,0,-C15/'NII计量表'!B5) | D17: % | I17: ΔNII/NII ÷ Δr，近似为 −RG / 平均生息资产
A18: NII 盈亏平衡利率（ΔNII = 0 的临界点） | C18: =IF(C15=0,"无缺口（利率中性）","无解（存在永久敞口）") | I18: 令 ΔNII = 0 得 −Δr × RG = 0；当 RG ≠ 0 时无解，恒等式不成立即表示永久性敞口
A20: 【二】利率平行移动情景（以 NII 计量表 主口径为基准）
A21: 情景 | B21: Δr (bp) | C21: Δ利息收入 (亿元) | D21: Δ利息支出 (亿元) | E21: ΔNII (亿元) | F21: 情景后 NII (亿元) | G21: ΔNII % | H21: 情景后 NIM | I21: 情景解读
A22: 利率平行上移 250bp | B22: 250 | C22: =-$B$22/10000*$C$5 | D22: =-$B$22/10000*$C$10 | E22: =C22-D22 | F22: ='NII计量表'!B22+E22 | G22: =IF('NII计量表'!B22=0,0,E22/'NII计量表'!B22) | H22: =IF('NII计量表'!B5=0,0,F22/'NII计量表'!B5) | I22: 大幅加息：负债端市场化成本快速上行，NII 承压最重
A23: 利率平行上移 100bp | B23: 100 | C23: =-$B$23/10000*$C$5 | D23: =-$B$23/10000*$C$10 | E23: =C23-D23 | F23: ='NII计量表'!B22+E23 | G23: =IF('NII计量表'!B22=0,0,E23/'NII计量表'!B22) | H23: =IF('NII计量表'!B5=0,0,F23/'NII计量表'!B5) | I23: 常规加息周期：重定价缺口决定 NII 方向
A24: 利率平行上移 50bp | B24: 50 | C24: =-$B$24/10000*$C$5 | D24: =-$B$24/10000*$C$10 | E24: =C24-D24 | F24: ='NII计量表'!B22+E24 | G24: =IF('NII计量表'!B22=0,0,E24/'NII计量表'!B22) | H24: =IF('NII计量表'!B5=0,0,F24/'NII计量表'!B5) | I24: 温和加息：需关注 NIM 是否跌破 1.50% 监管参考线
A25: 基准情景（利率不变） | B25: 0 | C25: =-$B$25/10000*$C$5 | D25: =-$B$25/10000*$C$10 | E25: =C25-D25 | F25: ='NII计量表'!B22+E25 | G25: =IF('NII计量表'!B22=0,0,E25/'NII计量表'!B22) | H25: =IF('NII计量表'!B5=0,0,F25/'NII计量表'!B5) | I25: 基准情景：ΔNII = 0，NII = 计量表主口径
A26: 利率平行下移 50bp | B26: -50 | C26: =-$B$26/10000*$C$5 | D26: =-$B$26/10000*$C$10 | E26: =C26-D26 | F26: ='NII计量表'!B22+E26 | G26: =IF('NII计量表'!B22=0,0,E26/'NII计量表'!B22) | H26: =IF('NII计量表'!B5=0,0,F26/'NII计量表'!B5) | I26: 温和降息：负债成本下行，对 NII 形成支撑
A27: 利率平行下移 100bp | B27: -100 | C27: =-$B$27/10000*$C$5 | D27: =-$B$27/10000*$C$10 | E27: =C27-D27 | F27: ='NII计量表'!B22+E27 | G27: =IF('NII计量表'!B22=0,0,E27/'NII计量表'!B22) | H27: =IF('NII计量表'!B5=0,0,F27/'NII计量表'!B5) | I27: 降息周期：存款重定价滞后，短期利好 NIM
A28: 利率平行下移 250bp | B28: -250 | C28: =-$B$28/10000*$C$5 | D28: =-$B$28/10000*$C$10 | E28: =C28-D28 | F28: ='NII计量表'!B22+E28 | G28: =IF('NII计量表'!B22=0,0,E28/'NII计量表'!B22) | H28: =IF('NII计量表'!B5=0,0,F28/'NII计量表'!B5) | I28: 大幅降息：贷款重定价滞后，NIM 阶段性走高
A29: 最不利情景 ΔNII（最小值） | E29: =MIN(E22:E28) | F29: ='NII计量表'!B22+E29 | H29: =IF('NII计量表'!B5=0,0,F29/'NII计量表'!B5) | I29: 各情景中 NII 变动最不利者
A30: 最有利情景 ΔNII（最大值） | E30: =MAX(E22:E28) | F30: ='NII计量表'!B22+E30 | H30: =IF('NII计量表'!B5=0,0,F30/'NII计量表'!B5) | I30: 各情景中 NII 变动最有利者
A32: 【三】单边冲击（资产端 / 负债端 分开重定价）
A33: 情景 | B33: Δr (bp) | C33: Δ利息收入 (亿元) | D33: Δ利息支出 (亿元) | E33: ΔNII (亿元) | F33: 情景后 NII (亿元) | G33: ΔNII % | H33: 情景后 NIM | I33: 情景解读
A34: 仅负债端全额重定价 +100bp | B34: 100 | C34: =-$B$34/10000*$C$5*0.0 | D34: =-$B$34/10000*$C$10*1.0 | E34: =C34-D34 | F34: ='NII计量表'!B22+E34 | G34: =IF('NII计量表'!B22=0,0,E34/'NII计量表'!B22) | H34: =IF('NII计量表'!B5=0,0,F34/'NII计量表'!B5) | I34: 极端下限：负债 100% 重定价、资产 0% → NII 损失上限
A35: 仅资产端全额重定价 +100bp | B35: 100 | C35: =-$B$35/10000*$C$5*1.0 | D35: =-$B$35/10000*$C$10*0.0 | E35: =C35-D35 | F35: ='NII计量表'!B22+E35 | G35: =IF('NII计量表'!B22=0,0,E35/'NII计量表'!B22) | H35: =IF('NII计量表'!B5=0,0,F35/'NII计量表'!B5) | I35: 极端上限：资产 100% 重定价、负债 0% → NII 改善上限
A36: 实际重定价（按 β 加权）+100bp | B36: 100 | C36: =-$B$36/10000*$C$5*1.0 | D36: =-$B$36/10000*$C$10*1.0 | E36: =C36-D36 | F36: ='NII计量表'!B22+E36 | G36: =IF('NII计量表'!B22=0,0,E36/'NII计量表'!B22) | H36: =IF('NII计量表'!B5=0,0,F36/'NII计量表'!B5) | I36: 实际情景：各自按 β 加权重定价（= 上表 +100bp 情景）
A37: 负债重定价滞后 +100bp | B37: 100 | C37: =-$B$37/10000*$C$5*1.0 | D37: =-$B$37/10000*$C$10*0.3 | E37: =C37-D37 | F37: ='NII计量表'!B22+E37 | G37: =IF('NII计量表'!B22=0,0,E37/'NII计量表'!B22) | H37: =IF('NII计量表'!B5=0,0,F37/'NII计量表'!B5) | I37: 假设活期存款占比骤降、负债 β 有效降至 30% 的情形
A39: 【四】NII 风险敞口与核心敏感度
A40: 加息 100bp 下 NII 变化率（核心敏感度） | C40: =IF('NII计量表'!B22=0,0,E23/'NII计量表'!B22) | D40: % | I40: 银行经营分析的核心敏感度：绝对值越大，利率风险敞口越大
A41: 加息 100bp 下 NIM 变动（百分点） | C41: =IF('NII计量表'!B5=0,0,(H23-'NII计量表'!B30)) | D41: % | I41: 情景后 NIM 减基准 NIM
A42: 降息 100bp 下 NIM 变动（百分点） | C42: =IF('NII计量表'!B5=0,0,(H27-'NII计量表'!B30)) | D42: % | I42: 与上式对称但不一定等幅，取决于 β 分布
A43: NII 波动区间（最有利 − 最不利） | C43: =E30-E29 | D43: 亿元 | I43: 7 档情景下 NII 的最大波动幅度
A44: 敞口方向判定 | C44: =IF(C15>0,"正缺口：利率上行 NII 受损",IF(C15<0,"负缺口：利率上行 NII 受益","利率中性")) | D44: % | I44: 由重定价缺口 RG 的符号决定
...

Sheet 计算逻辑说明
A1: NII 净利息收入计量逻辑说明与 prcp 实体映射
A3: 【一】基础概念
A4: 净利息收入 NII | B4: Net Interest Income = 利息收入 − 利息支出，利润表核心科目，单位：亿元
A5: 净息差 NIM | B5: NIM = NII ÷ 平均生息资产 × 100%，衡量每一元生息资产创造的净利息收入
A6: 净利差 NIS | B6: NIS = 生息资产收益率 − 计息负债成本率，衡量资产端与负债端定价差
A7: 生息资产 | B7: 能够产生利息收入的资产：贷款、债券投资、同业资产、存款准备金等
A8: 计息负债 | B8: 需要支付利息的负债：各类存款、同业负债、央行借款等
A9: 非生息资产 | B9: 不产生利息的资产（FVTPL/现金/其它），NII 模版中单列并从生息资产中剔除
A10: 平均余额 | B10: 平均余额 = (期初余额 + 期末余额) ÷ 2，监管口径要求使用日均/平均余额而非期末余额
A11: 重定价系数 β | B11: 1 年内利率变动向该科目传导的比例，活期存款 β 低（0.25），隔夜回购 β 高（0.98）
A12: 重定价缺口 RG | B12: RG = Σ(资产余额×β) − Σ(负债余额×β)，决定利率变动对 NII 的方向和幅度
A13: 【二】核心计算公式
A14: 单账户利息收入 | B14: 利息收入_i = IF(资产 且 利率>0, 平均余额_i × 年化利率_i, 0)
A15: 单账户利息支出 | B15: 利息支出_i = IF(负债 且 利率>0, 平均余额_i × 年化利率_i, 0)
A16: 利息收入合计 | B16: Σ 全部生息资产账户的利息收入
A17: 利息支出合计 | B17: Σ 全部计息负债账户的利息支出
A18: 净利息收入 NII | B18: NII = 利息收入合计 − 利息支出合计 ★ 核心输出指标
A19: 平均生息资产 | B19: Σ 生息资产账户平均余额（利率 > 0）
A20: 生息资产收益率 | B20: 生息资产收益率 = 利息收入 ÷ 平均生息资产
A21: 计息负债成本率 | B21: 计息负债成本率 = 利息支出 ÷ 平均计息负债
A22: 净利差 NIS | B22: NIS = 生息资产收益率 − 计息负债成本率
A23: 净息差 NIM | B23: NIM = NII ÷ 平均生息资产 ★ 核心输出指标
A24: ΔNII 敏感度 | B24: ΔNII = −Δr × (A_β − L_β) = −Δr × 重定价缺口 RG
A25: NII 利率弹性 | B25: 弹性 ≈ −RG ÷ 平均生息资产，表示 Δr 变动 1% 时 NII 变动的相对比例
A26: 【三】完整公式（Excel 单元格级）
A27: 平均余额 | B27: NII数据源!J 列 = (H 期初余额 + I 期末余额) / 2
A28: 有效计息标记 | B28: NII数据源!L 列 = IF(K 年化利率 > 0, "是", "否")
A29: 单账户利息收入 | B29: NII数据源!N 列 = IF(AND(C="资产", L="是"), J 平均余额 × K 利率, 0)
A30: 单账户利息支出 | B30: NII数据源!O 列 = IF(AND(C="负债", L="是"), J 平均余额 × K 利率, 0)
A31: 利息收入合计 | B31: 利息收入明细!K26 合计行 = SUM(全部资产账户利息收入)
A32: 利息支出合计 | B32: 利息支出明细!K20 合计行 = SUM(全部负债账户利息支出)
A33: 业务条线汇总 | B33: SUMIF(业务条线范围, 条线名, 平均余额范围) / SUMIF(..., 利息金额范围)
A34: 账户类型汇总 | B34: SUMIF(账户类型范围, 类型名, ...) 精确匹配活期/定期/信贷/非息
A35: 净息差 NIM | B35: =NII计量表!B22 / NII计量表!B5
A36: 重定价敞口 A_β | B36: SUMPRODUCT((方向="资产")*(利率>0)*平均余额, 重定价β)
A37: 重定价敞口 L_β | B37: SUMPRODUCT((方向="负债")*平均余额, 重定价β)
A38: 重定价缺口 RG | B38: A_β − L_β
A39: ΔNII 情景值 | B39: ΔNII = −Δr/10000 × RG
A40: 【四】监管依据与参考区间
A41: NIM 定义 | B41: 《商业银行资产负债管理管理办法》：净息差 = 净利息收入 ÷ 平均生息资产
...
