Workbook

Sheet ①数据源
A1: ① NII 数据源 — 全部取自 prcp_basic_20251231.xlsx「基础数据」（方案 8 / 2025-12-31）
A2: 🟢 绿区(蓝字) = 可编辑：当前余额、加权平均利率、重定价β | 🟣 紫字 = 自动计算 | 月度利息 = 余额 × 利率 ÷ 100 ÷ 12（与参照物 EM 列口径一致，已逐笔核对偏差为 0） | 1年内到期 = 「②期限分布」前 12 桶合计 | 重定价β = MIN(0.98, MAX(0.10, 1年内到期 ÷ Σ分布)) 自动推导
A3: 账户编码 | B3: 账户名称 | C3: 大类 | D3: 业务条线 | E3: 账户类型 | F3: 当前余额 (亿元) | G3: 加权平均 利率 | H3: 月度利息 (亿元/月) | I3: 年度利息 (亿元/年) | J3: 1年内到期 (亿元) | K3: 期限分布 覆盖率 | L3: 重定价β | M3: 风险权重 | N3: ASF/RSF | O3: 数据来源
A4: S01010101000000 | B4: 1.1. 对公一般贷款 | C4: 资产 | D4: 信贷资产 | E4: 信贷 | F4: 245000 | G4: 0.041 | H4: =F4*G4/12 | I4: =H4*12 | J4: ='②期限分布'!BO4 | K4: =IF(F4=0,0,('②期限分布'!BP4)/F4) | L4: =IF('②期限分布'!BP4=0,0,MIN(0.98,MAX(0.1,'②期限分布'!BO4/'②期限分布'!BP4))) | M4: 100 | N4: RSF | O4: 基础数据!R7 (EJ/EL/EM)
A5: S01010102000000 | B5: 1.2. 个人贷款 | C5: 资产 | D5: 信贷资产 | E5: 信贷 | F5: 175000 | G5: 0.0395 | H5: =F5*G5/12 | I5: =H5*12 | J5: ='②期限分布'!BO5 | K5: =IF(F5=0,0,('②期限分布'!BP5)/F5) | L5: =IF('②期限分布'!BP5=0,0,MIN(0.98,MAX(0.1,'②期限分布'!BO5/'②期限分布'!BP5))) | M5: 55 | N5: RSF | O5: 基础数据!R8 (EJ/EL/EM)
A6: S01010103000000 | B6: 1.3. 信用卡贷款 | C6: 资产 | D6: 信贷资产 | E6: 信贷 | F6: 48000 | G6: 0.12 | H6: =F6*G6/12 | I6: =H6*12 | J6: ='②期限分布'!BO6 | K6: =IF(F6=0,0,('②期限分布'!BP6)/F6) | L6: =IF('②期限分布'!BP6=0,0,MIN(0.98,MAX(0.1,'②期限分布'!BO6/'②期限分布'!BP6))) | M6: 75 | N6: RSF | O6: 基础数据!R9 (EJ/EL/EM)
A7: S01010104000000 | B7: 1.4. 票据贴现 | C7: 资产 | D7: 信贷资产 | E7: 信贷 | F7: 32000 | G7: 0.025 | H7: =F7*G7/12 | I7: =H7*12 | J7: ='②期限分布'!BO7 | K7: =IF(F7=0,0,('②期限分布'!BP7)/F7) | L7: =IF('②期限分布'!BP7=0,0,MIN(0.98,MAX(0.1,'②期限分布'!BO7/'②期限分布'!BP7))) | M7: 100 | N7: RSF | O7: 基础数据!R10 (EJ/EL/EM)
A8: S01010105000000 | B8: 1.5. 非银贷款 | C8: 资产 | D8: 信贷资产 | E8: 信贷 | F8: 50000 | G8: 0.045 | H8: =F8*G8/12 | I8: =H8*12 | J8: ='②期限分布'!BO8 | K8: =IF(F8=0,0,('②期限分布'!BP8)/F8) | L8: =IF('②期限分布'!BP8=0,0,MIN(0.98,MAX(0.1,'②期限分布'!BO8/'②期限分布'!BP8))) | M8: 100 | N8: RSF | O8: 基础数据!R11 (EJ/EL/EM)
A9: S010102010100 | B9: 2.1.1 金市自营债券 | C9: 资产 | D9: 债券投资 | E9: 投资 | F9: 150000 | G9: 0.0255 | H9: =F9*G9/12 | I9: =H9*12 | J9: ='②期限分布'!BO9 | K9: =IF(F9=0,0,('②期限分布'!BP9)/F9) | L9: =IF('②期限分布'!BP9=0,0,MIN(0.98,MAX(0.1,'②期限分布'!BO9/'②期限分布'!BP9))) | M9: 0 | N9: RSF | O9: 基础数据!R14 (EJ/EL/EM)
A10: S010102010200 | B10: 2.1.2 司库债券 | C10: 资产 | D10: 债券投资 | E10: 投资 | F10: 100000 | G10: 0.0285 | H10: =F10*G10/12 | I10: =H10*12 | J10: ='②期限分布'!BO10 | K10: =IF(F10=0,0,('②期限分布'!BP10)/F10) | L10: =IF('②期限分布'!BP10=0,0,MIN(0.98,MAX(0.1,'②期限分布'!BO10/'②期限分布'!BP10))) | M10: 25 | N10: RSF | O10: 基础数据!R15 (EJ/EL/EM)
A11: S01010202000000 | B11: 2.2. 结构化融资 | C11: 资产 | D11: 金融市场 | E11: 金融 | F11: 50000 | G11: 0.038 | H11: =F11*G11/12 | I11: =H11*12 | J11: ='②期限分布'!BO11 | K11: =IF(F11=0,0,('②期限分布'!BP11)/F11) | L11: =IF('②期限分布'!BP11=0,0,MIN(0.98,MAX(0.1,'②期限分布'!BO11/'②期限分布'!BP11))) | M11: 100 | N11: RSF | O11: 基础数据!R16 (EJ/EL/EM)
A12: S01010203000000 | B12: 2.3. 同业资产（不含拆放非银） | C12: 资产 | D12: 金融市场 | E12: 金融 | F12: 70000 | G12: 0.023 | H12: =F12*G12/12 | I12: =H12*12 | J12: ='②期限分布'!BO12 | K12: =IF(F12=0,0,('②期限分布'!BP12)/F12) | L12: =IF('②期限分布'!BP12=0,0,MIN(0.98,MAX(0.1,'②期限分布'!BO12/'②期限分布'!BP12))) | M12: 20 | N12: RSF | O12: 基础数据!R17 (EJ/EL/EM)
A13: S01010204000000 | B13: 2.4. 存款准备金 | C13: 资产 | D13: 金融市场 | E13: 金融 | F13: 30000 | G13: 0.0162 | H13: =F13*G13/12 | I13: =H13*12 | J13: ='②期限分布'!BO13 | K13: =IF(F13=0,0,('②期限分布'!BP13)/F13) | L13: =IF('②期限分布'!BP13=0,0,MIN(0.98,MAX(0.1,'②期限分布'!BO13/'②期限分布'!BP13))) | M13: 0 | N13: RSF | O13: 基础数据!R18 (EJ/EL/EM)
A14: S01010301000000 | B14: 3.1. FVTPL类资产 | C14: 资产 | D14: 非生息资产 | E14: 非息 | F14: 30000 | G14: 0.032 | H14: =F14*G14/12 | I14: =H14*12 | J14: ='②期限分布'!BO14 | K14: =IF(F14=0,0,('②期限分布'!BP14)/F14) | L14: =IF('②期限分布'!BP14=0,0,MIN(0.98,MAX(0.1,'②期限分布'!BO14/'②期限分布'!BP14))) | M14: 100 | N14: RSF | O14: 基础数据!R20 (EJ/EL/EM)
A15: S01010302000000 | B15: 3.2. 其他非生息资产 | C15: 资产 | D15: 非生息资产 | E15: 非息 | F15: 20000 | G15: 0 | H15: =F15*G15/12 | I15: =H15*12 | J15: ='②期限分布'!BO15 | K15: =IF(F15=0,0,('②期限分布'!BP15)/F15) | L15: =IF('②期限分布'!BP15=0,0,MIN(0.98,MAX(0.1,'②期限分布'!BO15/'②期限分布'!BP15))) | M15: 50 | N15: RSF | O15: 基础数据!R21 (EJ/EL/EM)
... A27: S03000000000000 | B27: 所有者权益 | C27: 权益 | D27: 权益 | E27: 权益 | F27: 100000 | G27: 0 | H27: =F27*G27/12 | I27: =H27*12 | J27: ='②期限分布'!BO27 | K27: =IF(F27=0,0,('②期限分布'!BP27)/F27) | L27: =IF('②期限分布'!BP27=0,0,MIN(0.98,MAX(0.1,'②期限分布'!BO27/'②期限分布'!BP27))) | M27: 0 | N27: RSF | O27: 基础数据!R43 (EJ/EL/EM)
B28: 合计 / 加权平均 | F28: =SUM(F4:F27) | G28: =IF(F28=0,0,SUMPRODUCT($F$4:$F$27,$G$4:$G$27)/F28) | H28: =SUM(H4:H27) | I28: =SUM(I4:I27) | J28: =SUM('②期限分布'!BO4:BO27) | K28: =IF(F28=0,0,SUM('②期限分布'!BP4:BP27)/F28) | L28: =SUMPRODUCT($F$4:$F$27,$L$4:$L$27) | O28: L 列 = Σ(余额 × β) 全行重定价敞口

Sheet ②期限分布
A1: ② 剩余期限分布（64 桶，等额分期偿还结构）— 取自 prcp_basic_20251231.xlsx BX~EI 列
A2: 桶口径：1M~60M 月度 + 10Y/15Y/20Y/30Y 年端 | 资产端非零桶为前 16 个（等额分期），活期存款 3 桶（3 个月内），定期/市场化负债 12 桶（12 个月内） | Σ分布 ≤ 当前余额，差额为未到期续作本金（资产端覆盖 53.07%，负债端 99.98%）
A3: 账户编码 | B3: 账户名称 | C3: 1M | D3: 2M | E3: 3M | F3: 4M | G3: 5M | H3: 6M | I3: 7M | J3: 8M | K3: 9M | L3: 10M | M3: 11M | N3: 12M | O3: 13M | P3: 14M | Q3: 15M | R3: 16M | S3: 17M | T3: 18M | U3: 19M | V3: 20M | W3: 21M | X3: 22M | Y3: 23M | Z3: 24M | AA3: 25M | AB3: 26M | AC3: 27M | AD3: 28M | AE3: 29M | AF3: 30M | AG3: 31M | AH3: 32M | AI3: 33M | AJ3: 34M | AK3: 35M | AL3: 36M | AM3: 37M | AN3: 38M | AO3: 39M | AP3: 40M | AQ3: 41M | AR3: 42M | AS3: 43M | AT3: 44M | AU3: 45M | AV3: 46M | AW3: 47M | AX3: 48M | AY3: 49M | AZ3: 50M | BA3: 51M | BB3: 52M | BC3: 53M | BD3: 54M | BE3: 55M | BF3: 56M | BG3: 57M | BH3: 58M | BI3: 59M | BJ3: 60M | BK3: 10Y | BL3: 15Y | BM3: 20Y | BN3: 30Y | BO3: 1年内到期 (1M~12M) | BP3: Σ 分布合计 | BQ3: 当前余额 | BR3: 覆盖率
A4: S01010101000000 | B4: 1.1. 对公一般贷款 | C4: 5733 | D4: 5733 | E4: 5733 | F4: 5733 | G4: 5733 | H4: 5733 | I4: 5733 | J4: 5733 | K4: 5733 | L4: 5733 | M4: 5733 | N4: 5733 | BK4: 30625 | BL4: 15312.5 | BM4: 7644 | BN4: 7644 | BO4: =SUM(C4:N4) | BP4: =SUM(C4:BN4) | BQ4: ='①数据源'!F4 | BR4: =IF(BQ4=0,0,BP4/BQ4)
A5: S01010102000000 | B5: 1.2. 个人贷款 | C5: 4095 | D5: 4095 | E5: 4095 | F5: 4095 | G5: 4095 | H5: 4095 | I5: 4095 | J5: 4095 | K5: 4095 | L5: 4095 | M5: 4095 | N5: 4095 | BK5: 21875 | BL5: 10937.5 | BM5: 5460 | BN5: 5460 | BO5: =SUM(C5:N5) | BP5: =SUM(C5:BN5) | BQ5: ='①数据源'!F5 | BR5: =IF(BQ5=0,0,BP5/BQ5)
A6: S01010103000000 | B6: 1.3. 信用卡贷款 | C6: 1123.2 | D6: 1123.2 | E6: 1123.2 | F6: 1123.2 | G6: 1123.2 | H6: 1123.2 | I6: 1123.2 | J6: 1123.2 | K6: 1123.2 | L6: 1123.2 | M6: 1123.2 | N6: 1123.2 | BK6: 6000 | BL6: 3000 | BM6: 1497.6 | BN6: 1497.6 | BO6: =SUM(C6:N6) | BP6: =SUM(C6:BN6) | BQ6: ='①数据源'!F6 | BR6: =IF(BQ6=0,0,BP6/BQ6)
A7: S01010104000000 | B7: 1.4. 票据贴现 | C7: 748.8 | D7: 748.8 | E7: 748.8 | F7: 748.8 | G7: 748.8 | H7: 748.8 | I7: 748.8 | J7: 748.8 | K7: 748.8 | L7: 748.8 | M7: 748.8 | N7: 748.8 | BK7: 4000 | BL7: 2000 | BM7: 998.4 | BN7: 998.4 | BO7: =SUM(C7:N7) | BP7: =SUM(C7:BN7) | BQ7: ='①数据源'!F7 | BR7: =IF(BQ7=0,0,BP7/BQ7)
A8: S01010105000000 | B8: 1.5. 非银贷款 | C8: 1170 | D8: 1170 | E8: 1170 | F8: 1170 | G8: 1170 | H8: 1170 | I8: 1170 | J8: 1170 | K8: 1170 | L8: 1170 | M8: 1170 | N8: 1170 | BK8: 6250 | BL8: 3125 | BM8: 1560 | BN8: 1560 | BO8: =SUM(C8:N8) | BP8: =SUM(C8:BN8) | BQ8: ='①数据源'!F8 | BR8: =IF(BQ8=0,0,BP8/BQ8)
A9: S010102010100 | B9: 2.1.1 金市自营债券 | C9: 3510 | D9: 3510 | E9: 3510 | F9: 3510 | G9: 3510 | H9: 3510 | I9: 3510 | J9: 3510 | K9: 3510 | L9: 3510 | M9: 3510 | N9: 3510 | BK9: 18750 | BL9: 9375 | BM9: 4680 | BN9: 4680 | BO9: =SUM(C9:N9) | BP9: =SUM(C9:BN9) | BQ9: ='①数据源'!F9 | BR9: =IF(BQ9=0,0,BP9/BQ9)
A10: S010102010200 | B10: 2.1.2 司库债券 | C10: 2340 | D10: 2340 | E10: 2340 | F10: 2340 | G10: 2340 | H10: 2340 | I10: 2340 | J10: 2340 | K10: 2340 | L10: 2340 | M10: 2340 | N10: 2340 | BK10: 12500 | BL10: 6250 | BM10: 3120 | BN10: 3120 | BO10: =SUM(C10:N10) | BP10: =SUM(C10:BN10) | BQ10: ='①数据源'!F10 | BR10: =IF(BQ10=0,0,BP10/BQ10)
A11: S01010202000000 | B11: 2.2. 结构化融资 | C11: 1170 | D11: 1170 | E11: 1170 | F11: 1170 | G11: 1170 | H11: 1170 | I11: 1170 | J11: 1170 | K11: 1170 | L11: 1170 | M11: 1170 | N11: 1170 | BK11: 6250 | BL11: 3125 | BM11: 1560 | BN11: 1560 | BO11: =SUM(C11:N11) | BP11: =SUM(C11:BN11) | BQ11: ='①数据源'!F11 | BR11: =IF(BQ11=0,0,BP11/BQ11)
A12: S01010203000000 | B12: 2.3. 同业资产（不含拆放非银） | C12: 1638 | D12: 1638 | E12: 1638 | F12: 1638 | G12: 1638 | H12: 1638 | I12: 1638 | J12: 1638 | K12: 1638 | L12: 1638 | M12: 1638 | N12: 1638 | BK12: 8750 | BL12: 4375 | BM12: 2184 | BN12: 2184 | BO12: =SUM(C12:N12) | BP12: =SUM(C12:BN12) | BQ12: ='①数据源'!F12 | BR12: =IF(BQ12=0,0,BP12/BQ12)
A13: S01010204000000 | B13: 2.4. 存款准备金 | C13: 702 | D13: 702 | E13: 702 | F13: 702 | G13: 702 | H13: 702 | I13: 702 | J13: 702 | K13: 702 | L13: 702 | M13: 702 | N13: 702 | BK13: 3750 | BL13: 1875 | BM13: 936 | BN13: 936 | BO13: =SUM(C13:N13) | BP13: =SUM(C13:BN13) | BQ13: ='①数据源'!F13 | BR13: =IF(BQ13=0,0,BP13/BQ13)
A14: S01010301000000 | B14: 3.1. FVTPL类资产 | C14: 702 | D14: 702 | E14: 702 | F14: 702 | G14: 702 | H14: 702 | I14: 702 | J14: 702 | K14: 702 | L14: 702 | M14: 702 | N14: 702 | BK14: 3750 | BL14: 1875 | BM14: 936 | BN14: 936 | BO14: =SUM(C14:N14) | BP14: =SUM(C14:BN14) | BQ14: ='①数据源'!F14 | BR14: =IF(BQ14=0,0,BP14/BQ14)
A15: S01010302000000 | B15: 3.2. 其他非生息资产 | C15: 468 | D15: 468 | E15: 468 | F15: 468 | G15: 468 | H15: 468 | I15: 468 | J15: 468 | K15: 468 | L15: 468 | M15: 468 | N15: 468 | BK15: 2500 | BL15: 1250 | BM15: 624 | BN15: 624 | BO15: =SUM(C15:N15) | BP15: =SUM(C15:BN15) | BQ15: ='①数据源'!F15 | BR15: =IF(BQ15=0,0,BP15/BQ15)
... A19: S01020300000000 | B19: 3. 外币非生息资产 | C19: 234 | D19: 234 | E19: 234 | F19: 234 | G19: 234 | H19: 234 | I19: 234 | J19: 234 | K19: 234 | L19: 234 | M19: 234 | N19: 234 | BK19: 1250 | BL19: 625 | BM19: 312 | BN19: 312 | BO19: =SUM(C19:N19) | BP19: =SUM(C19:BN19) | BQ19: ='①数据源'!F19 | BR19: =IF(BQ19=0,0,BP19/BQ19)
A20: S020101010100 | B20: 1.1.1 对公活期存款 | C20: 130000 | D20: 78000 | E20: 52000 | BO20: =SUM(C20:N20) | BP20: =SUM(C20:BN20) | BQ20: ='①数据源'!F20 | BR20: =IF(BQ20=0,0,BP20/BQ20)
A21: S020101010200 | B21: 1.1.2 对公定期存款 | C21: 38830 | D21: 38830 | E21: 25872 | F21: 12936 | G21: 12936 | H21: 12936 | I21: 12936 | J21: 12936 | K21: 12936 | L21: 12936 | M21: 12936 | N21: 12936 | BO21: =SUM(C21:N21) | BP21: =SUM(C21:BN21) | BQ21: ='①数据源'!F21 | BR21: =IF(BQ21=0,0,BP21/BQ21)
A22: S020101020100 | B22: 1.2.1 零售活期存款 | C22: 60000 | D22: 36000 | E22: 24000 | BO22: =SUM(C22:N22) | BP22: =SUM(C22:BN22) | BQ22: ='①数据源'!F22 | BR22: =IF(BQ22=0,0,BP22/BQ22)
A23: S020101020200 | B23: 1.2.2 零售定期存款 | C23: 35300 | D23: 35300 | E23: 23520 | F23: 11760 | G23: 11760 | H23: 11760 | I23: 11760 | J23: 11760 | K23: 11760 | L23: 11760 | M23: 11760 | N23: 11760 | BO23: =SUM(C23:N23) | BP23: =SUM(C23:BN23) | BQ23: ='①数据源'!F23 | BR23: =IF(BQ23=0,0,BP23/BQ23)
A24: S02010200000000 | B24: 2. 人民币市场化负债 | C24: 21180 | D24: 21180 | E24: 14112 | F24: 7056 | G24: 7056 | H24: 7056 | I24: 7056 | J24: 7056 | K24: 7056 | L24: 7056 | M24: 7056 | N24: 7056 | BO24: =SUM(C24:N24) | BP24: =SUM(C24:BN24) | BQ24: ='①数据源'!F24 | BR24: =IF(BQ24=0,0,BP24/BQ24)
A25: S02020100000000 | B25: 1. 外币存款 | C25: 7060 | D25: 7060 | E25: 4704 | F25: 2352 | G25: 2352 | H25: 2352 | I25: 2352 | J25: 2352 | K25: 2352 | L25: 2352 | M25: 2352 | N25: 2352 | BO25: =SUM(C25:N25) | BP25: =SUM(C25:BN25) | BQ25: ='①数据源'!F25 | BR25: =IF(BQ25=0,0,BP25/BQ25)
A26: S02020200000000 | B26: 2. 外币市场化负债 | C26: 3530 | D26: 3530 | E26: 2352 | F26: 1176 | G26: 1176 | H26: 1176 | I26: 1176 | J26: 1176 | K26: 1176 | L26: 1176 | M26: 1176 | N26: 1176 | BO26: =SUM(C26:N26) | BP26: =SUM(C26:BN26) | BQ26: ='①数据源'!F26 | BR26: =IF(BQ26=0,0,BP26/BQ26)
A27: S03000000000000 | B27: 所有者权益 | BO27: =SUM(C27:N27) | BP27: =SUM(C27:BN27) | BQ27: ='①数据源'!F27 | BR27: =IF(BQ27=0,0,BP27/BQ27)
B28: 合计 | BO28: =SUM(BO4:BO27) | BP28: =SUM(BP4:BP27) | BQ28: =SUM(BQ4:BQ27) | BR28: =IF(BQ28=0,0,BP28/BQ28)

Sheet ③收益率曲线
A1: ③ 国债收益率曲线与折现因子 — 取自 prcp_basic_20251231.xlsx R47~R176
A2: 64 个关键期限（1M~60M 月度 + 10Y/15Y/20Y/30Y），中债登关键期限 + 线性插值 | DF = 1/(1+y)^t
A3: 期限 | B3: 年数 t | C3: 收益率 y(%) | D3: 折现因子 DF | E3: t × DF | F3: 数据来源 | G3: 说明
A4: 1M | B4: 0.083333333 | C4: 0.0127 | D4: =1/(1+C4)^B4 | E4: =B4*D4 | F4: 线性插值 | G4: 由关键期限线性插值
A5: 2M | B5: 0.16666667 | C5: 0.0127 | D5: =1/(1+C5)^B5 | E5: =B5*D5 | F5: 线性插值 | G5: 由关键期限线性插值
A6: 3M | B6: 0.25 | C6: 0.0127 | D6: =1/(1+C6)^B6 | E6: =B6*D6 | F6: 中债登 | G6: 关键期限官方数据
A7: 4M | B7: 0.33333333 | C7: 0.0128 | D7: =1/(1+C7)^B7 | E7: =B7*D7 | F7: 线性插值 | G7: 由关键期限线性插值
A8: 5M | B8: 0.41666667 | C8: 0.0129 | D8: =1/(1+C8)^B8 | E8: =B8*D8 | F8: 线性插值 | G8: 由关键期限线性插值
A9: 6M | B9: 0.5 | C9: 0.013 | D9: =1/(1+C9)^B9 | E9: =B9*D9 | F9: 中债登 | G9: 关键期限官方数据
A10: 7M | B10: 0.58333333 | C10: 0.0131 | D10: =1/(1+C10)^B10 | E10: =B10*D10 | F10: 线性插值 | G10: 由关键期限线性插值
A11: 8M | B11: 0.66666667 | C11: 0.01315 | D11: =1/(1+C11)^B11 | E11: =B11*D11 | F11: 线性插值 | G11: 由关键期限线性插值
A12: 9M | B12: 0.75 | C12: 0.0132 | D12: =1/(1+C12)^B12 | E12: =B12*D12 | F12: 中债登 | G12: 关键期限官方数据
A13: 10M | B13: 0.83333333 | C13: 0.01328 | D13: =1/(1+C13)^B13 | E13: =B13*D13 | F13: 线性插值 | G13: 由关键期限线性插值
A14: 11M | B14: 0.91666667 | C14: 0.01333 | D14: =1/(1+C14)^B14 | E14: =B14*D14 | F14: 线性插值 | G14: 由关键期限线性插值
A15: 12M | B15: 1 | C15: 0.013372 | D15: =1/(1+C15)^B15 | E15: =B15*D15 | F15: 中债登 | G15: 关键期限官方数据
... A67: 30Y | B67: 30 | C67: 0.022674 | D67: =1/(1+C67)^B67 | E67: =B67*D67 | F67: 中债登 | G67: 关键期限官方数据

Sheet ④利息收入明细
A1: ④ 利息收入明细 — 生息资产逐账户拆解
A2: 年度利息 = 当前余额 × 加权平均利率（= 参照物「平均利息收支」EM × 12） | 非生息资产单列备查
A3: 账户编码 | B3: 账户名称 | C3: 业务条线 | D3: 账户类型 | E3: 当前余额 (亿元) | F3: 加权平均 利率 | G3: 年度利息 (亿元/年) | H3: 利息收入 占比 | I3: 累计占比 | J3: 1年内到期 (亿元) | K3: 到期占比 | L3: 口径说明
A4: ='①数据源'!A4 | B4: ='①数据源'!B4 | C4: ='①数据源'!D4 | D4: ='①数据源'!E4 | E4: ='①数据源'!F4 | F4: ='①数据源'!G4 | G4: ='①数据源'!I4 | H4: =IF($G$18=0,0,G4/$G$18) | I4: =H4 | J4: ='①数据源'!J4 | K4: =IF(E4=0,0,J4/E4) | L4: 基础数据!R7 · β=0.529
A5: ='①数据源'!A5 | B5: ='①数据源'!B5 | C5: ='①数据源'!D5 | D5: ='①数据源'!E5 | E5: ='①数据源'!F5 | F5: ='①数据源'!G5 | G5: ='①数据源'!I5 | H5: =IF($G$18=0,0,G5/$G$18) | I5: =I4+H5 | J5: ='①数据源'!J5 | K5: =IF(E5=0,0,J5/E5) | L5: 基础数据!R8 · β=0.529
A6: ='①数据源'!A6 | B6: ='①数据源'!B6 | C6: ='①数据源'!D6 | D6: ='①数据源'!E6 | E6: ='①数据源'!F6 | F6: ='①数据源'!G6 | G6: ='①数据源'!I6 | H6: =IF($G$18=0,0,G6/$G$18) | I6: =I5+H6 | J6: ='①数据源'!J6 | K6: =IF(E6=0,0,J6/E6) | L6: 基础数据!R9 · β=0.529
A7: ='①数据源'!A7 | B7: ='①数据源'!B7 | C7: ='①数据源'!D7 | D7: ='①数据源'!E7 | E7: ='①数据源'!F7 | F7: ='①数据源'!G7 | G7: ='①数据源'!I7 | H7: =IF($G$18=0,0,G7/$G$18) | I7: =I6+H7 | J7: ='①数据源'!J7 | K7: =IF(E7=0,0,J7/E7) | L7: 基础数据!R10 · β=0.529
A8: ='①数据源'!A8 | B8: ='①数据源'!B8 | C8: ='①数据源'!D8 | D8: ='①数据源'!E8 | E8: ='①数据源'!F8 | F8: ='①数据源'!G8 | G8: ='①数据源'!I8 | H8: =IF($G$18=0,0,G8/$G$18) | I8: =I7+H8 | J8: ='①数据源'!J8 | K8: =IF(E8=0,0,J8/E8) | L8: 基础数据!R11 · β=0.529
A9: ='①数据源'!A9 | B9: ='①数据源'!B9 | C9: ='①数据源'!D9 | D9: ='①数据源'!E9 | E9: ='①数据源'!F9 | F9: ='①数据源'!G9 | G9: ='①数据源'!I9 | H9: =IF($G$18=0,0,G9/$G$18) | I9: =I8+H9 | J9: ='①数据源'!J9 | K9: =IF(E9=0,0,J9/E9) | L9: 基础数据!R14 · β=0.529
A10: ='①数据源'!A10 | B10: ='①数据源'!B10 | C10: ='①数据源'!D10 | D10: ='①数据源'!E10 | E10: ='①数据源'!F10 | F10: ='①数据源'!G10 | G10: ='①数据源'!I10 | H10: =IF($G$18=0,0,G10/$G$18) | I10: =I9+H10 | J10: ='①数据源'!J10 | K10: =IF(E10=0,0,J10/E10) | L10: 基础数据!R15 · β=0.529
A11: ='①数据源'!A11 | B11: ='①数据源'!B11 | C11: ='①数据源'!D11 | D11: ='①数据源'!E11 | E11: ='①数据源'!F11 | F11: ='①数据源'!G11 | G11: ='①数据源'!I11 | H11: =IF($G$18=0,0,G11/$G$18) | I11: =I10+H11 | J11: ='①数据源'!J11 | K11: =IF(E11=0,0,J11/E11) | L11: 基础数据!R16 · β=0.529
A12: ='①数据源'!A12 | B12: ='①数据源'!B12 | C12: ='①数据源'!D12 | D12: ='①数据源'!E12 | E12: ='①数据源'!F12 | F12: ='①数据源'!G12 | G12: ='①数据源'!I12 | H12: =IF($G$18=0,0,G12/$G$18) | I12: =I11+H12 | J12: ='①数据源'!J12 | K12: =IF(E12=0,0,J12/E12) | L12: 基础数据!R17 · β=0.529
A13: ='①数据源'!A13 | B13: ='①数据源'!B13 | C13: ='①数据源'!D13 | D13: ='①数据源'!E13 | E13: ='①数据源'!F13 | F13: ='①数据源'!G13 | G13: ='①数据源'!I13 | H13: =IF($G$18=0,0,G13/$G$18) | I13: =I12+H13 | J13: ='①数据源'!J13 | K13: =IF(E13=0,0,J13/E13) | L13: 基础数据!R18 · β=0.529
A14: ='①数据源'!A14 | B14: ='①数据源'!B14 | C14: ='①数据源'!D14 | D14: ='①数据源'!E14 | E14: ='①数据源'!F14 | F14: ='①数据源'!G14 | G14: ='①数据源'!I14 | H14: =IF($G$18=0,0,G14/$G$18) | I14: =I13+H14 | J14: ='①数据源'!J14 | K14: =IF(E14=0,0,J14/E14) | L14: 基础数据!R20 · β=0.529
A15: ='①数据源'!A16 | B15: ='①数据源'!B16 | C15: ='①数据源'!D16 | D15: ='①数据源'!E16 | E15: ='①数据源'!F16 | F15: ='①数据源'!G16 | G15: ='①数据源'!I16 | H15: =IF($G$18=0,0,G15/$G$18) | I15: =I14+H15 | J15: ='①数据源'!J16 | K15: =IF(E15=0,0,J15/E15) | L15: 基础数据!R23 · β=0.529
A16: ='①数据源'!A17 | B16: ='①数据源'!B17 | C16: ='①数据源'!D17 | D16: ='①数据源'!E17 | E16: ='①数据源'!F17 | F16: ='①数据源'!G17 | G16: ='①数据源'!I17 | H16: =IF($G$18=0,0,G16/$G$18) | I16: =I15+H16 | J16: ='①数据源'!J17 | K16: =IF(E16=0,0,J16/E16) | L16: 基础数据!R25 · β=0.529
A17: ='①数据源'!A18 | B17: ='①数据源'!B18 | C17: ='①数据源'!D18 | D17: ='①数据源'!E18 | E17: ='①数据源'!F18 | F17: ='①数据源'!G18 | G17: ='①数据源'!I18 | H17: =IF($G$18=0,0,G17/$G$18) | I17: =I16+H17 | J17: ='①数据源'!J18 | K17: =IF(E17=0,0,J17/E17) | L17: 基础数据!R26 · β=0.529
B18: 利息收入合计（生息资产） | E18: =SUM(E4:E17) | F18: =IF(E18=0,0,G18/E18) | G18: =SUM(G4:G17) | H18: =SUM(H4:H17) | I18: =I17 | J18: =SUM(J4:J17) | K18: =IF(E18=0,0,J18/E18) | L18: F 列 = 加权平均收益率 · H 列合计应为 100% · K 列 = 1 年内到期占比
A20: 【附】非生息资产（加权平均利率 = 0，不计入利息收入与 NIM 分母）
B21: ='①数据源'!B15 | E21: ='①数据源'!F15 | F21: ='①数据源'!G15 | G21: ='①数据源'!I15 | L21: 利率 0%，无利息收入，已从 NIM 分母剔除
B22: ='①数据源'!B19 | E22: ='①数据源'!F19 | F22: ='①数据源'!G19 | G22: ='①数据源'!I19 | L22: 利率 0%，无利息收入，已从 NIM 分母剔除
B23: 非生息资产合计（备查） | E23: =SUM(E21:E22) | G23: =SUM(G21:G22)

Sheet ⑤利息支出明细
A1: ⑤ 利息支出明细 — 计息负债逐账户拆解
A2: 年度利息 = 当前余额 × 加权平均利率 | 活期存款为 3 桶结构（3 个月内到期），重定价快于资产端
A3: 账户编码 | B3: 账户名称 | C3: 业务条线 | D3: 账户类型 | E3: 当前余额 (亿元) | F3: 加权平均 利率 | G3: 年度利息 (亿元/年) | H3: 利息支出 占比 | I3: 累计占比 | J3: 1年内到期 (亿元) | K3: 到期占比 | L3: 口径说明
A4: ='①数据源'!A20 | B4: ='①数据源'!B20 | C4: ='①数据源'!D20 | D4: ='①数据源'!E20 | E4: ='①数据源'!F20 | F4: ='①数据源'!G20 | G4: ='①数据源'!I20 | H4: =IF($G$11=0,0,G4/$G$11) | I4: =H4 | J4: ='①数据源'!J20 | K4: =IF(E4=0,0,J4/E4) | L4: 基础数据!R33 · β=0.980
A5: ='①数据源'!A21 | B5: ='①数据源'!B21 | C5: ='①数据源'!D21 | D5: ='①数据源'!E21 | E5: ='①数据源'!F21 | F5: ='①数据源'!G21 | G5: ='①数据源'!I21 | H5: =IF($G$11=0,0,G5/$G$11) | I5: =I4+H5 | J5: ='①数据源'!J21 | K5: =IF(E5=0,0,J5/E5) | L5: 基础数据!R34 · β=0.980
A6: ='①数据源'!A22 | B6: ='①数据源'!B22 | C6: ='①数据源'!D22 | D6: ='①数据源'!E22 | E6: ='①数据源'!F22 | F6: ='①数据源'!G22 | G6: ='①数据源'!I22 | H6: =IF($G$11=0,0,G6/$G$11) | I6: =I5+H6 | J6: ='①数据源'!J22 | K6: =IF(E6=0,0,J6/E6) | L6: 基础数据!R36 · β=0.980
A7: ='①数据源'!A23 | B7: ='①数据源'!B23 | C7: ='①数据源'!D23 | D7: ='①数据源'!E23 | E7: ='①数据源'!F23 | F7: ='①数据源'!G23 | G7: ='①数据源'!I23 | H7: =IF($G$11=0,0,G7/$G$11) | I7: =I6+H7 | J7: ='①数据源'!J23 | K7: =IF(E7=0,0,J7/E7) | L7: 基础数据!R37 · β=0.980
A8: ='①数据源'!A24 | B8: ='①数据源'!B24 | C8: ='①数据源'!D24 | D8: ='①数据源'!E24 | E8: ='①数据源'!F24 | F8: ='①数据源'!G24 | G8: ='①数据源'!I24 | H8: =IF($G$11=0,0,G8/$G$11) | I8: =I7+H8 | J8: ='①数据源'!J24 | K8: =IF(E8=0,0,J8/E8) | L8: 基础数据!R38 · β=0.980
A9: ='①数据源'!A25 | B9: ='①数据源'!B25 | C9: ='①数据源'!D25 | D9: ='①数据源'!E25 | E9: ='①数据源'!F25 | F9: ='①数据源'!G25 | G9: ='①数据源'!I25 | H9: =IF($G$11=0,0,G9/$G$11) | I9: =I8+H9 | J9: ='①数据源'!J25 | K9: =IF(E9=0,0,J9/E9) | L9: 基础数据!R40 · β=0.980
A10: ='①数据源'!A26 | B10: ='①数据源'!B26 | C10: ='①数据源'!D26 | D10: ='①数据源'!E26 | E10: ='①数据源'!F26 | F10: ='①数据源'!G26 | G10: ='①数据源'!I26 | H10: =IF($G$11=0,0,G10/$G$11) | I10: =I9+H10 | J10: ='①数据源'!J26 | K10: =IF(E10=0,0,J10/E10) | L10: 基础数据!R41 · β=0.980
B11: 利息支出合计（计息负债） | E11: =SUM(E4:E10) | F11: =IF(E11=0,0,G11/E11) | G11: =SUM(G4:G10) | H11: =SUM(H4:H10) | I11: =I10 | J11: =SUM(J4:J10) | K11: =IF(E11=0,0,J11/E11) | L11: F 列 = 加权平均成本率 · H 列合计应为 100% · K 列 = 1 年内到期占比

Sheet ⑥NII计量表
A1: ⑥ 净利息收入（NII）计量表 — 基于 prcp_basic_20251231.xlsx 真实数据
A2: NII = 利息收入 − 利息支出 | NIM = NII ÷ 生息资产 | 引用「④利息收入明细」「⑤利息支出明细」逐级联动 | 单位：亿元 / 亿元每年 / %
A4: 【一】生息资产与计息负债规模
A5: 生息资产合计（加权平均利率 > 0） | B5: ='④利息收入明细'!E18 | C5: =IF($B$5=0,0,B5/$B$5) | D5: 亿元 | E5: 剔除非生息资产后的 NIM 分母
A6: 其中：已剔除非生息资产 | B6: ='④利息收入明细'!E23 | C6: =IF($B$5=0,0,B6/$B$5) | D6: 亿元 | E6: 加权平均利率 = 0，不计入分母
A7: 计息负债合计 | B7: ='⑤利息支出明细'!E11 | C7: =IF($B$5=0,0,B7/$B$5) | D7: 亿元 | E7: 7 个计息负债账户
A8: 其中：存款类负债 | B8: =SUMIF('①数据源'!$E$4:$E$27,"活期",'①数据源'!$F$4:$F$27)+SUMIF('①数据源'!$E$4:$E$27,"定期",'①数据源'!$F$4:$F$27) | C8: =IF($B$5=0,0,B8/$B$5) | D8: 亿元 | E8: 活期 380,000 + 定期 420,000
A9: 其中：市场化负债 | B9: =SUMIF('①数据源'!$E$4:$E$27,"同业",'①数据源'!$F$4:$F$27) | C9: =IF($B$5=0,0,B9/$B$5) | D9: 亿元 | E9: 人民币市场化负债
A10: 其中：外币负债 | B10: =SUMIF('①数据源'!$E$4:$E$27,"外币",'①数据源'!$F$4:$F$27)-SUMIF('①数据源'!$C$4:$C$27,"负债",'①数据源'!$F$4:$F$27) | C10: =IF($B$5=0,0,B10/$B$5) | D10: 亿元 | E10: 负债端外币 = 全部外币 − 资产端外币
A11: 所有者权益 | B11: ='①数据源'!F27 | C11: =IF($B$5=0,0,B11/$B$5) | D11: 亿元 | E11: 不产生利息收支，仅作规模对照
A13: 【二】利息收入与利息支出
A14: 利息收入合计（年度） | B14: ='④利息收入明细'!G18 | D14: 亿元/年 | E14: 14 个生息资产账户
A15: 利息支出合计（年度） | B15: ='⑤利息支出明细'!G11 | D15: 亿元/年 | E15: 7 个计息负债账户
A16: 参照物校验：Σ月度利息 × 12（资产） | B16: =SUMIF('①数据源'!$C$4:$C$27,"资产",'①数据源'!$H$4:$H$27)*12 | D16: 亿元/年 | E16: 应与利息收入合计相等
A17: 参照物校验：Σ月度利息 × 12（负债） | B17: =SUMIF('①数据源'!$C$4:$C$27,"负债",'①数据源'!$H$4:$H$27)*12 | D17: 亿元/年 | E17: 应与利息支出合计相等
A19: 【三】净利息收入 NII（核心指标）
A20: ★ 净利息收入 NII | B20: =B14-B15 | D20: 亿元/年 | E20: NII = 利息收入 − 利息支出
A21: 月度净利息收入（对照参照物 EM 口径） | B21: =SUMIF('①数据源'!$C$4:$C$27,"资产",'①数据源'!$H$4:$H$27)-SUMIF('①数据源'!$C$4:$C$27,"负债",'①数据源'!$H$4:$H$27) | D21: 亿元/月 | E21: =NII ÷ 12，与参照物「平均利息收支」列完全对齐
A23: 【四】利差与净息差核心比率
A24: 生息资产收益率（利息收入 ÷ 生息资产） | B24: =IF($B$5=0,0,$B$14/$B$5) | D24: % | E24: 资产端盈利能力
A25: 计息负债成本率（利息支出 ÷ 计息负债） | B25: =IF($B$7=0,0,$B$15/$B$7) | D25: % | E25: 负债端付息成本
A26: 净利差 NIS（净收益率 − 净成本率） | B26: =B24-B25 | D26: % | E26: 资产端与负债端定价之差
A27: ★ 净息差 NIM（NII ÷ 生息资产） | B27: =IF($B$5=0,0,$B$20/$B$5) | D27: % | E27: ★ NII 计量最终输出指标
A29: 【五】资产负债结构与存款成本辅助比率
A30: 信贷资产余额（贷款 5 项） | B30: =SUMIF('①数据源'!$E$4:$E$27,"信贷",'①数据源'!$F$4:$F$27) | D30: 亿元 | E30: 对公 / 个人 / 信用卡 / 票据 / 非银
A31: 存款余额（活期 + 定期） | B31: =SUMIF('①数据源'!$E$4:$E$27,"活期",'①数据源'!$F$4:$F$27)+SUMIF('①数据源'!$E$4:$E$27,"定期",'①数据源'!$F$4:$F$27) | D31: 亿元 | E31: 对公 + 零售
A32: 存贷比（信贷资产 ÷ 计息负债） | B32: =IF($B$7=0,0,$B$30/$B$7) | D32: % | E32: 监管上限 100%
A33: 贷存比（信贷资产 ÷ 存款余额） | B33: =IF($B$31=0,0,$B$30/$B$31) | D33: % | E33: 存款对贷款的覆盖程度
A34: 存款活期化率（活期 ÷ 存款合计） | B34: =IF($B$31=0,0,SUMIF('①数据源'!$E$4:$E$27,"活期",'①数据源'!$F$4:$F$27)/$B$31) | D34: % | E34: 活期付息成本低，活期化率越高 → NIM 越高
A36: 【六】勾稽校验（校验 1~9 应全部为 0）
A37: 校验 1：④明细 = ①Σ年度利息（资产，利率>0） | B37: =ROUND('④利息收入明细'!G18-SUMIF('①数据源'!$C$4:$C$27,"资产",'①数据源'!$I$4:$I$27),6) | D37: 亿元 | E37: 明细 ↔ 数据源交叉勾稽
A38: 校验 2：⑤明细 = ①Σ年度利息（负债） | B38: =ROUND('⑤利息支出明细'!G11-SUMIF('①数据源'!$C$4:$C$27,"负债",'①数据源'!$I$4:$I$27),6) | D38: 亿元 | E38: 明细 ↔ 数据源交叉勾稽
A39: 校验 3：①Σ全部年度利息 = 资产 + 负债 | B39: =ROUND(SUM('①数据源'!$I$4:$I$27)-SUMIF('①数据源'!$C$4:$C$27,"资产",'①数据源'!$I$4:$I$27)-SUMIF('①数据源'!$C$4:$C$27,"负债",'①数据源'!$I$4:$I$27),6) | D39: 亿元 | E39: 权益年度利息应为 0
A40: 校验 4：Σ月度利息 × 12 = Σ年度利息（资产） | B40: =ROUND(SUMIF('①数据源'!$C$4:$C$27,"资产",'①数据源'!$H$4:$H$27)*12-SUMIF('①数据源'!$C$4:$C$27,"资产",'①数据源'!$I$4:$I$27),6) | D40: 亿元 | E40: 参照物 EM 口径
A41: 校验 5：Σ月度利息 × 12 = Σ年度利息（负债） | B41: =ROUND(SUMIF('①数据源'!$C$4:$C$27,"负债",'①数据源'!$H$4:$H$27)*12-SUMIF('①数据源'!$C$4:$C$27,"负债",'①数据源'!$I$4:$I$27),6) | D41: 亿元 | E41: 参照物 EM 口径
A42: 校验 6：④利息收入占比合计 = 100% | B42: =ROUND('④利息收入明细'!H18-1,8) | D42: 亿元 | E42: 占比无重复无遗漏
A43: 校验 7：⑤利息支出占比合计 = 100% | B43: =ROUND('⑤利息支出明细'!H11-1,8) | D43: 亿元 | E43: 占比无重复无遗漏
A44: 校验 8：NII = 利息收入 − 利息支出（核心恒等式） | B44: =ROUND($B$20-($B$14-$B$15),8) | D44: 亿元 | E44: NII 主口径恒等式自检
A45: 校验 9：年度 NII = 月度 NII × 12 | B45: =ROUND($B$20-$B$21*12,6) | D45: 亿元 | E45: 年度与月度口径对齐
A46: 信息项：Σ期限分布 − Σ当前余额（差额 = 未覆盖续作本金） | B46: ='②期限分布'!BP28-'②期限分布'!BQ28 | D46: 亿元 | E46: 资产端覆盖 53.07%，负债端 99.98%
...

Sheet ⑦期限结构与重定价
A1: ⑦ 剩余期限结构与重定价缺口分析
A2: A_β / L_β = Σ(余额 × β)，β 由「②期限分布」1 年内（12 桶）到期占比推导 | ΔNII = −Δr × (A_β − L_β)
A4: 【一】账户重定价属性明细（24 个末级账户）
A5: 账户名称 | B5: 方向 | C5: 当前余额 (亿元) | D5: 重定价β | E5: 重定价敞口 (亿元) | F5: 1年内到期 (亿元) | G5: 到期占比 | H5: 到期 / 非到期结构说明
A6: ='①数据源'!B4 | B6: ='①数据源'!C4 | C6: ='①数据源'!F4 | D6: ='①数据源'!L4 | E6: =C6*D6 | F6: ='①数据源'!J4 | G6: =IF(C6=0,0,F6/C6) | H6: 16 桶等额分期，1 年内到期约 1/4，重定价滞后于负债端
A7: ='①数据源'!B5 | B7: ='①数据源'!C5 | C7: ='①数据源'!F5 | D7: ='①数据源'!L5 | E7: =C7*D7 | F7: ='①数据源'!J5 | G7: =IF(C7=0,0,F7/C7) | H7: 16 桶等额分期，1 年内到期约 1/4，重定价滞后于负债端
A8: ='①数据源'!B6 | B8: ='①数据源'!C6 | C8: ='①数据源'!F6 | D8: ='①数据源'!L6 | E8: =C8*D8 | F8: ='①数据源'!J6 | G8: =IF(C8=0,0,F8/C8) | H8: 16 桶等额分期，1 年内到期约 1/4，重定价滞后于负债端
A9: ='①数据源'!B7 | B9: ='①数据源'!C7 | C9: ='①数据源'!F7 | D9: ='①数据源'!L7 | E9: =C9*D9 | F9: ='①数据源'!J7 | G9: =IF(C9=0,0,F9/C9) | H9: 16 桶等额分期，1 年内到期约 1/4，重定价滞后于负债端
A10: ='①数据源'!B8 | B10: ='①数据源'!C8 | C10: ='①数据源'!F8 | D10: ='①数据源'!L8 | E10: =C10*D10 | F10: ='①数据源'!J8 | G10: =IF(C10=0,0,F10/C10) | H10: 16 桶等额分期，1 年内到期约 1/4，重定价滞后于负债端
A11: ='①数据源'!B9 | B11: ='①数据源'!C9 | C11: ='①数据源'!F9 | D11: ='①数据源'!L9 | E11: =C11*D11 | F11: ='①数据源'!J9 | G11: =IF(C11=0,0,F11/C11) | H11: 16 桶分期；到期后按市价重定价，久期较长
A12: ='①数据源'!B10 | B12: ='①数据源'!C10 | C12: ='①数据源'!F10 | D12: ='①数据源'!L10 | E12: =C12*D12 | F12: ='①数据源'!J10 | G12: =IF(C12=0,0,F12/C12) | H12: 16 桶分期；到期后按市价重定价，久期较长
A13: ='①数据源'!B11 | B13: ='①数据源'!C11 | C13: ='①数据源'!F11 | D13: ='①数据源'!L11 | E13: =C13*D13 | F13: ='①数据源'!J11 | G13: =IF(C13=0,0,F13/C13) | H13: 同业 / 准备金 / 结构化融资，货币市场驱动，β 较高
A14: ='①数据源'!B12 | B14: ='①数据源'!C12 | C14: ='①数据源'!F12 | D14: ='①数据源'!L12 | E14: =C14*D14 | F14: ='①数据源'!J12 | G14: =IF(C14=0,0,F14/C14) | H14: 同业 / 准备金 / 结构化融资，货币市场驱动，β 较高
A15: ='①数据源'!B13 | B15: ='①数据源'!C13 | C15: ='①数据源'!F13 | D15: ='①数据源'!L13 | E15: =C15*D15 | F15: ='①数据源'!J13 | G15: =IF(C15=0,0,F15/C15) | H15: 同业 / 准备金 / 结构化融资，货币市场驱动，β 较高
A16: ='①数据源'!B14 | B16: ='①数据源'!C14 | C16: ='①数据源'!F14 | D16: ='①数据源'!L14 | E16: =C16*D16 | F16: ='①数据源'!J14 | G16: =IF(C16=0,0,F16/C16) | H16: 利率 0%，无重定价敞口
A17: ='①数据源'!B15 | B17: ='①数据源'!C15 | C17: ='①数据源'!F15 | D17: ='①数据源'!L15 | E17: =C17*D17 | F17: ='①数据源'!J15 | G17: =IF(C17=0,0,F17/C17) | H17: 利率 0%，无重定价敞口
... A29: ='①数据源'!B27 | B29: ='①数据源'!C27 | C29: ='①数据源'!F27 | D29: ='①数据源'!L27 | E29: =C29*D29 | F29: ='①数据源'!J27 | G29: =IF(C29=0,0,F29/C29) | H29: 无利息，不参与 NII
A30: 资产重定价敞口 A_β 合计 | C30: =SUMIF($B$6:$B$29,"资产",$C$6:$C$29) | D30: =IF(C30=0,0,E30/C30) | E30: =SUMIF($B$6:$B$29,"资产",$E$6:$E$29) | F30: =SUMIF($B$6:$B$29,"资产",$F$6:$F$29) | G30: =IF(C30=0,0,F30/C30) | H30: D 列 = 组合加权平均 β
A31: 负债重定价敞口 L_β 合计 | C31: =SUMIF($B$6:$B$29,"负债",$C$6:$C$29) | D31: =IF(C31=0,0,E31/C31) | E31: =SUMIF($B$6:$B$29,"负债",$E$6:$E$29) | F31: =SUMIF($B$6:$B$29,"负债",$F$6:$F$29) | G31: =IF(C31=0,0,F31/C31) | H31: D 列 = 组合加权平均 β
A32: ★ 重定价缺口 RG = A_β − L_β | E32: =E30-E31 | H32: ★ RG > 0 → 利率上行时 NII 受损；RG < 0 → 利率上行时 NII 受益
A33: 利率每平行上移 10bp 对 NII 的影响 | E33: =-E32*0.001 | H33: =−RG × 0.001（亿元/年 / 10bp）
A34: NII 利率弹性（−RG ÷ 生息资产） | E34: =IF('⑥NII计量表'!B5=0,0,-E32/'⑥NII计量表'!B5) | H34: ΔNII/NII ÷ Δr
A36: 【二】按业务条线的期限与重定价结构
A37: 业务条线 | B37: 方向 | C37: 当前余额 (亿元) | D37: 组合 β | E37: 重定价敞口 (亿元) | F37: 1年内到期 (亿元) | G37: 到期占比 | H37: 说明
A38: 信贷资产 | B38: 资产 | C38: =SUMIF($A$6:$A$29,$A38,$C$6:$C$29) | D38: =IF(C38=0,0,E38/C38) | E38: =SUMIF($A$6:$A$29,$A38,$E$6:$E$29) | F38: =SUMIF($A$6:$A$29,$A38,$F$6:$F$29) | G38: =IF(C38=0,0,F38/C38) | H38: 16 桶等额分期，1 年内到期约 1/4，重定价滞后于负债端
A39: 债券投资 | B39: 资产 | C39: =SUMIF($A$6:$A$29,$A39,$C$6:$C$29) | D39: =IF(C39=0,0,E39/C39) | E39: =SUMIF($A$6:$A$29,$A39,$E$6:$E$29) | F39: =SUMIF($A$6:$A$29,$A39,$F$6:$F$29) | G39: =IF(C39=0,0,F39/C39) | H39: 16 桶分期；到期后按市价重定价，久期较长
A40: 金融市场 | B40: 资产 | C40: =SUMIF($A$6:$A$29,$A40,$C$6:$C$29) | D40: =IF(C40=0,0,E40/C40) | E40: =SUMIF($A$6:$A$29,$A40,$E$6:$E$29) | F40: =SUMIF($A$6:$A$29,$A40,$F$6:$F$29) | G40: =IF(C40=0,0,F40/C40) | H40: 同业 / 准备金 / 结构化融资，货币市场驱动，β 较高
A41: 非生息资产 | B41: 资产 | C41: =SUMIF($A$6:$A$29,$A41,$C$6:$C$29) | D41: =IF(C41=0,0,E41/C41) | E41: =SUMIF($A$6:$A$29,$A41,$E$6:$E$29) | F41: =SUMIF($A$6:$A$29,$A41,$F$6:$F$29) | G41: =IF(C41=0,0,F41/C41) | H41: 利率 0%，无重定价敞口
A42: 外币资产 | B42: 资产 | C42: =SUMIF($A$6:$A$29,$A42,$C$6:$C$29) | D42: =IF(C42=0,0,E42/C42) | E42: =SUMIF($A$6:$A$29,$A42,$E$6:$E$29) | F42: =SUMIF($A$6:$A$29,$A42,$F$6:$F$29) | G42: =IF(C42=0,0,F42/C42) | H42: 折人民币计价，境内利率 + 汇率双重影响
A43: 活期存款 | B43: 负债 | C43: =SUMIF($A$6:$A$29,$A43,$C$6:$C$29) | D43: =IF(C43=0,0,E43/C43) | E43: =SUMIF($A$6:$A$29,$A43,$E$6:$E$29) | F43: =SUMIF($A$6:$A$29,$A43,$F$6:$F$29) | G43: =IF(C43=0,0,F43/C43) | H43: 3 桶（3 个月内）结构，1 年内基本全部到期，β = 1
A44: 定期存款 | B44: 负债 | C44: =SUMIF($A$6:$A$29,$A44,$C$6:$C$29) | D44: =IF(C44=0,0,E44/C44) | E44: =SUMIF($A$6:$A$29,$A44,$E$6:$E$29) | F44: =SUMIF($A$6:$A$29,$A44,$F$6:$F$29) | G44: =IF(C44=0,0,F44/C44) | H44: 12 桶（12 个月内）结构，到期可续作定价
A45: 市场化负债 | B45: 负债 | C45: =SUMIF($A$6:$A$29,$A45,$C$6:$C$29) | D45: =IF(C45=0,0,E45/C45) | E45: =SUMIF($A$6:$A$29,$A45,$E$6:$E$29) | F45: =SUMIF($A$6:$A$29,$A45,$F$6:$F$29) | G45: =IF(C45=0,0,F45/C45) | H45: 12 桶货币市场工具，β 接近 1
A46: 外币负债 | B46: 负债 | C46: =SUMIF($A$6:$A$29,$A46,$C$6:$C$29) | D46: =IF(C46=0,0,E46/C46) | E46: =SUMIF($A$6:$A$29,$A46,$E$6:$E$29) | F46: =SUMIF($A$6:$A$29,$A46,$F$6:$F$29) | G46: =IF(C46=0,0,F46/C46) | H46: 折人民币负债，境内外利差影响
A48: 校验：资产条线敞口合计 = A_β 合计 | E48: =ROUND(SUM(E38:E42)-E30,6) | H48: 差额应为 0
A49: 校验：负债条线敞口合计 = L_β 合计 | E49: =ROUND(SUM(E43:E46)-E31,6) | H49: 差额应为 0
A51: 【三】重定价到期结构（按期限桶汇总，亿元）
A52: 期限桶 | B52: 年数 t | C52: 资产端分布 | D52: 负债端分布 | E52: 净头寸 | F52: 累计资产 | G52: 累计负债 | H52: 说明
A53: 1M | B53: 0.083333333 | C53: =SUMIF('①数据源'!$C$4:$C$27,"资产",'②期限分布'!C$4:C$27) | D53: =SUMIF('①数据源'!$C$4:$C$27,"负债",'②期限分布'!C$4:C$27) | E53: =C53-D53 | F53: =C53 | G53: =D53 | H53: 活期存款集中于 1M~3M → 负债端 1 年内到期占比高
A54: 2M | B54: 0.16666667 | C54: =SUMIF('①数据源'!$C$4:$C$27,"资产",'②期限分布'!D$4:D$27) | D54: =SUMIF('①数据源'!$C$4:$C$27,"负债",'②期限分布'!D$4:D$27) | E54: =C54-D54 | F54: =F53+C54 | G54: =G53+D54 | H54: 活期存款集中于 1M~3M → 负债端 1 年内到期占比高
A55: 3M | B55: 0.25 | C55: =SUMIF('①数据源'!$C$4:$C$27,"资产",'②期限分布'!E$4:E$27) | D55: =SUMIF('①数据源'!$C$4:$C$27,"负债",'②期限分布'!E$4:E$27) | E55: =C55-D55 | F55: =F54+C55 | G55: =G54+D55 | H55: 活期存款集中于 1M~3M → 负债端 1 年内到期占比高
...

Sheet ⑧NII结构拆解
A1: ⑧ NII 结构拆解 — 业务条线 / 账户类型 双维度
A2: 全部由 SUMIF 引用「①数据源」，联动更新 | 单位：亿元 / 亿元每年 / %
A4: 【一】按业务条线拆解
A5: 维度 | B5: 方向 | C5: 当前余额 (亿元) | D5: 余额占比 | E5: 年度利息 (亿元/年) | F5: 利息占比 | G5: 综合利率 | H5: 重定价敞口 (亿元) | I5: 说明
A6: 信贷资产 | B6: 资产 | C6: =SUMIF('①数据源'!$D$4:$D$27,"信贷资产",'①数据源'!$F$4:$F$27) | D6: =IF(SUMIF($B$6:$B$14,$B6,$C$6:$C$14)=0,0,C6/SUMIF($B$6:$B$14,$B6,$C$6:$C$14)) | E6: =SUMIF('①数据源'!$D$4:$D$27,"信贷资产",'①数据源'!$I$4:$I$27) | F6: =IF(SUMIF($B$6:$B$14,$B6,$E$6:$E$14)=0,0,E6/SUMIF($B$6:$B$14,$B6,$E$6:$E$14)) | G6: =IF(C6=0,0,E6/C6) | H6: =SUMIF('①数据源'!$D$4:$D$27,"信贷资产",'①数据源'!$F$4:$F$27,'①数据源'!$L$4:$L$27) | I6: 16 桶等额分期，1 年内到期约 1/4，重定价滞后于负债端
A7: 债券投资 | B7: 资产 | C7: =SUMIF('①数据源'!$D$4:$D$27,"债券投资",'①数据源'!$F$4:$F$27) | D7: =IF(SUMIF($B$6:$B$14,$B7,$C$6:$C$14)=0,0,C7/SUMIF($B$6:$B$14,$B7,$C$6:$C$14)) | E7: =SUMIF('①数据源'!$D$4:$D$27,"债券投资",'①数据源'!$I$4:$I$27) | F7: =IF(SUMIF($B$6:$B$14,$B7,$E$6:$E$14)=0,0,E7/SUMIF($B$6:$B$14,$B7,$E$6:$E$14)) | G7: =IF(C7=0,0,E7/C7) | H7: =SUMIF('①数据源'!$D$4:$D$27,"债券投资",'①数据源'!$F$4:$F$27,'①数据源'!$L$4:$L$27) | I7: 16 桶分期；到期后按市价重定价，久期较长
A8: 金融市场 | B8: 资产 | C8: =SUMIF('①数据源'!$D$4:$D$27,"金融市场",'①数据源'!$F$4:$F$27) | D8: =IF(SUMIF($B$6:$B$14,$B8,$C$6:$C$14)=0,0,C8/SUMIF($B$6:$B$14,$B8,$C$6:$C$14)) | E8: =SUMIF('①数据源'!$D$4:$D$27,"金融市场",'①数据源'!$I$4:$I$27) | F8: =IF(SUMIF($B$6:$B$14,$B8,$E$6:$E$14)=0,0,E8/SUMIF($B$6:$B$14,$B8,$E$6:$E$14)) | G8: =IF(C8=0,0,E8/C8) | H8: =SUMIF('①数据源'!$D$4:$D$27,"金融市场",'①数据源'!$F$4:$F$27,'①数据源'!$L$4:$L$27) | I8: 同业 / 准备金 / 结构化融资，货币市场驱动，β 较高
A9: 非生息资产 | B9: 资产 | C9: =SUMIF('①数据源'!$D$4:$D$27,"非生息资产",'①数据源'!$F$4:$F$27) | D9: =IF(SUMIF($B$6:$B$14,$B9,$C$6:$C$14)=0,0,C9/SUMIF($B$6:$B$14,$B9,$C$6:$C$14)) | E9: =SUMIF('①数据源'!$D$4:$D$27,"非生息资产",'①数据源'!$I$4:$I$27) | F9: =IF(SUMIF($B$6:$B$14,$B9,$E$6:$E$14)=0,0,E9/SUMIF($B$6:$B$14,$B9,$E$6:$E$14)) | G9: =IF(C9=0,0,E9/C9) | H9: =SUMIF('①数据源'!$D$4:$D$27,"非生息资产",'①数据源'!$F$4:$F$27,'①数据源'!$L$4:$L$27) | I9: 利率 0%，无重定价敞口
A10: 外币资产 | B10: 资产 | C10: =SUMIF('①数据源'!$D$4:$D$27,"外币资产",'①数据源'!$F$4:$F$27) | D10: =IF(SUMIF($B$6:$B$14,$B10,$C$6:$C$14)=0,0,C10/SUMIF($B$6:$B$14,$B10,$C$6:$C$14)) | E10: =SUMIF('①数据源'!$D$4:$D$27,"外币资产",'①数据源'!$I$4:$I$27) | F10: =IF(SUMIF($B$6:$B$14,$B10,$E$6:$E$14)=0,0,E10/SUMIF($B$6:$B$14,$B10,$E$6:$E$14)) | G10: =IF(C10=0,0,E10/C10) | H10: =SUMIF('①数据源'!$D$4:$D$27,"外币资产",'①数据源'!$F$4:$F$27,'①数据源'!$L$4:$L$27) | I10: 折人民币计价，境内利率 + 汇率双重影响
A11: 活期存款 | B11: 负债 | C11: =SUMIF('①数据源'!$D$4:$D$27,"活期存款",'①数据源'!$F$4:$F$27) | D11: =IF(SUMIF($B$6:$B$14,$B11,$C$6:$C$14)=0,0,C11/SUMIF($B$6:$B$14,$B11,$C$6:$C$14)) | E11: =SUMIF('①数据源'!$D$4:$D$27,"活期存款",'①数据源'!$I$4:$I$27) | F11: =IF(SUMIF($B$6:$B$14,$B11,$E$6:$E$14)=0,0,E11/SUMIF($B$6:$B$14,$B11,$E$6:$E$14)) | G11: =IF(C11=0,0,E11/C11) | H11: =SUMIF('①数据源'!$D$4:$D$27,"活期存款",'①数据源'!$F$4:$F$27,'①数据源'!$L$4:$L$27) | I11: 3 桶（3 个月内）结构，1 年内基本全部到期，β = 1
A12: 定期存款 | B12: 负债 | C12: =SUMIF('①数据源'!$D$4:$D$27,"定期存款",'①数据源'!$F$4:$F$27) | D12: =IF(SUMIF($B$6:$B$14,$B12,$C$6:$C$14)=0,0,C12/SUMIF($B$6:$B$14,$B12,$C$6:$C$14)) | E12: =SUMIF('①数据源'!$D$4:$D$27,"定期存款",'①数据源'!$I$4:$I$27) | F12: =IF(SUMIF($B$6:$B$14,$B12,$E$6:$E$14)=0,0,E12/SUMIF($B$6:$B$14,$B12,$E$6:$E$14)) | G12: =IF(C12=0,0,E12/C12) | H12: =SUMIF('①数据源'!$D$4:$D$27,"定期存款",'①数据源'!$F$4:$F$27,'①数据源'!$L$4:$L$27) | I12: 12 桶（12 个月内）结构，到期可续作定价
A13: 市场化负债 | B13: 负债 | C13: =SUMIF('①数据源'!$D$4:$D$27,"市场化负债",'①数据源'!$F$4:$F$27) | D13: =IF(SUMIF($B$6:$B$14,$B13,$C$6:$C$14)=0,0,C13/SUMIF($B$6:$B$14,$B13,$C$6:$C$14)) | E13: =SUMIF('①数据源'!$D$4:$D$27,"市场化负债",'①数据源'!$I$4:$I$27) | F13: =IF(SUMIF($B$6:$B$14,$B13,$E$6:$E$14)=0,0,E13/SUMIF($B$6:$B$14,$B13,$E$6:$E$14)) | G13: =IF(C13=0,0,E13/C13) | H13: =SUMIF('①数据源'!$D$4:$D$27,"市场化负债",'①数据源'!$F$4:$F$27,'①数据源'!$L$4:$L$27) | I13: 12 桶货币市场工具，β 接近 1
A14: 外币负债 | B14: 负债 | C14: =SUMIF('①数据源'!$D$4:$D$27,"外币负债",'①数据源'!$F$4:$F$27) | D14: =IF(SUMIF($B$6:$B$14,$B14,$C$6:$C$14)=0,0,C14/SUMIF($B$6:$B$14,$B14,$C$6:$C$14)) | E14: =SUMIF('①数据源'!$D$4:$D$27,"外币负债",'①数据源'!$I$4:$I$27) | F14: =IF(SUMIF($B$6:$B$14,$B14,$E$6:$E$14)=0,0,E14/SUMIF($B$6:$B$14,$B14,$E$6:$E$14)) | G14: =IF(C14=0,0,E14/C14) | H14: =SUMIF('①数据源'!$D$4:$D$27,"外币负债",'①数据源'!$F$4:$F$27,'①数据源'!$L$4:$L$27) | I14: 折人民币负债，境内外利差影响
A16: 【二】按账户类型拆解
A17: 维度 | B17: 方向 | C17: 当前余额 (亿元) | D17: 余额占比 | E17: 年度利息 (亿元/年) | F17: 利息占比 | G17: 综合利率 | H17: 重定价敞口 (亿元) | I17: 说明
A18: 信贷 | B18: 资产 | C18: =SUMIF('①数据源'!$D$4:$D$27,"信贷",'①数据源'!$F$4:$F$27) | D18: =IF(SUMIF($B$18:$B$25,$B18,$C$18:$C$25)=0,0,C18/SUMIF($B$18:$B$25,$B18,$C$18:$C$25)) | E18: =SUMIF('①数据源'!$D$4:$D$27,"信贷",'①数据源'!$I$4:$I$27) | F18: =IF(SUMIF($B$18:$B$25,$B18,$E$18:$E$25)=0,0,E18/SUMIF($B$18:$B$25,$B18,$E$18:$E$25)) | G18: =IF(C18=0,0,E18/C18) | H18: =SUMIF('①数据源'!$D$4:$D$27,"信贷",'①数据源'!$F$4:$F$27,'①数据源'!$L$4:$L$27) | I18: 贷款类，余额最大，信用卡 12% 拉高综合利率
A19: 投资 | B19: 资产 | C19: =SUMIF('①数据源'!$D$4:$D$27,"投资",'①数据源'!$F$4:$F$27) | D19: =IF(SUMIF($B$18:$B$25,$B19,$C$18:$C$25)=0,0,C19/SUMIF($B$18:$B$25,$B19,$C$18:$C$25)) | E19: =SUMIF('①数据源'!$D$4:$D$27,"投资",'①数据源'!$I$4:$I$27) | F19: =IF(SUMIF($B$18:$B$25,$B19,$E$18:$E$25)=0,0,E19/SUMIF($B$18:$B$25,$B19,$E$18:$E$25)) | G19: =IF(C19=0,0,E19/C19) | H19: =SUMIF('①数据源'!$D$4:$D$27,"投资",'①数据源'!$F$4:$F$27,'①数据源'!$L$4:$L$27) | I19: 金市 + 司库债券，票息 2.55~2.85%
A20: 金融 | B20: 资产 | C20: =SUMIF('①数据源'!$D$4:$D$27,"金融",'①数据源'!$F$4:$F$27) | D20: =IF(SUMIF($B$18:$B$25,$B20,$C$18:$C$25)=0,0,C20/SUMIF($B$18:$B$25,$B20,$C$18:$C$25)) | E20: =SUMIF('①数据源'!$D$4:$D$27,"金融",'①数据源'!$I$4:$I$27) | F20: =IF(SUMIF($B$18:$B$25,$B20,$E$18:$E$25)=0,0,E20/SUMIF($B$18:$B$25,$B20,$E$18:$E$25)) | G20: =IF(C20=0,0,E20/C20) | H20: =SUMIF('①数据源'!$D$4:$D$27,"金融",'①数据源'!$F$4:$F$27,'①数据源'!$L$4:$L$27) | I20: 同业资产 / 准备金 / 结构化融资
A21: 非息 | B21: 资产 | C21: =SUMIF('①数据源'!$D$4:$D$27,"非息",'①数据源'!$F$4:$F$27) | D21: =IF(SUMIF($B$18:$B$25,$B21,$C$18:$C$25)=0,0,C21/SUMIF($B$18:$B$25,$B21,$C$18:$C$25)) | E21: =SUMIF('①数据源'!$D$4:$D$27,"非息",'①数据源'!$I$4:$I$27) | F21: =IF(SUMIF($B$18:$B$25,$B21,$E$18:$E$25)=0,0,E21/SUMIF($B$18:$B$25,$B21,$E$18:$E$25)) | G21: =IF(C21=0,0,E21/C21) | H21: =SUMIF('①数据源'!$D$4:$D$27,"非息",'①数据源'!$F$4:$F$27,'①数据源'!$L$4:$L$27) | I21: 非生息资产，利率 0%
A22: 外币 | B22: 资产 | C22: =SUMIF('①数据源'!$D$4:$D$27,"外币",'①数据源'!$F$4:$F$27) | D22: =IF(SUMIF($B$18:$B$25,$B22,$C$18:$C$25)=0,0,C22/SUMIF($B$18:$B$25,$B22,$C$18:$C$25)) | E22: =SUMIF('①数据源'!$D$4:$D$27,"外币",'①数据源'!$I$4:$I$27) | F22: =IF(SUMIF($B$18:$B$25,$B22,$E$18:$E$25)=0,0,E22/SUMIF($B$18:$B$25,$B22,$E$18:$E$25)) | G22: =IF(C22=0,0,E22/C22) | H22: =SUMIF('①数据源'!$D$4:$D$27,"外币",'①数据源'!$F$4:$F$27,'①数据源'!$L$4:$L$27) | I22: 外币资产（折人民币）
A23: 活期 | B23: 负债 | C23: =SUMIF('①数据源'!$D$4:$D$27,"活期",'①数据源'!$F$4:$F$27) | D23: =IF(SUMIF($B$18:$B$25,$B23,$C$18:$C$25)=0,0,C23/SUMIF($B$18:$B$25,$B23,$C$18:$C$25)) | E23: =SUMIF('①数据源'!$D$4:$D$27,"活期",'①数据源'!$I$4:$I$27) | F23: =IF(SUMIF($B$18:$B$25,$B23,$E$18:$E$25)=0,0,E23/SUMIF($B$18:$B$25,$B23,$E$18:$E$25)) | G23: =IF(C23=0,0,E23/C23) | H23: =SUMIF('①数据源'!$D$4:$D$27,"活期",'①数据源'!$F$4:$F$27,'①数据源'!$L$4:$L$27) | I23: 3 桶结构，1 年内全部到期，β = 1
A24: 定期 | B24: 负债 | C24: =SUMIF('①数据源'!$D$4:$D$27,"定期",'①数据源'!$F$4:$F$27) | D24: =IF(SUMIF($B$18:$B$25,$B24,$C$18:$C$25)=0,0,C24/SUMIF($B$18:$B$25,$B24,$C$18:$C$25)) | E24: =SUMIF('①数据源'!$D$4:$D$27,"定期",'①数据源'!$I$4:$I$27) | F24: =IF(SUMIF($B$18:$B$25,$B24,$E$18:$E$25)=0,0,E24/SUMIF($B$18:$B$25,$B24,$E$18:$E$25)) | G24: =IF(C24=0,0,E24/C24) | H24: =SUMIF('①数据源'!$D$4:$D$27,"定期",'①数据源'!$F$4:$F$27,'①数据源'!$L$4:$L$27) | I24: 12 桶结构，到期可续作
A25: 同业 | B25: 负债 | C25: =SUMIF('①数据源'!$D$4:$D$27,"同业",'①数据源'!$F$4:$F$27) | D25: =IF(SUMIF($B$18:$B$25,$B25,$C$18:$C$25)=0,0,C25/SUMIF($B$18:$B$25,$B25,$C$18:$C$25)) | E25: =SUMIF('①数据源'!$D$4:$D$27,"同业",'①数据源'!$I$4:$I$27) | F25: =IF(SUMIF($B$18:$B$25,$B25,$E$18:$E$25)=0,0,E25/SUMIF($B$18:$B$25,$B25,$E$18:$E$25)) | G25: =IF(C25=0,0,E25/C25) | H25: =SUMIF('①数据源'!$D$4:$D$27,"同业",'①数据源'!$F$4:$F$27,'①数据源'!$L$4:$L$27) | I25: 人民币市场化负债，货币市场工具
A27: 【三】NII 贡献分解与校验
A28: 资产端年度利息合计 | B28: =SUM(E6:E10) | D28: 亿元/年 | I28: 信贷 + 投资 + 金融 + 非息 + 外币
A29: 负债端年度利息合计 | B29: =SUM(E11:E14) | D29: 亿元/年 | I29: 活期 + 定期 + 市场化 + 外币
A30: ★ NII（条线加总） | B30: =B28-B29 | D30: 亿元/年 | I30: =资产端 − 负债端
A31: 对照：⑥NII计量表 NII | B31: ='⑥NII计量表'!B20 | D31: 亿元/年 | I31: 交叉验证
A32: 校验差额（应为 0） | B32: =B30-B31 | D32: 亿元/年 | I32: 条线维度与总表完全勾稽

Sheet ⑨情景敏感性
A1: ⑨ NII 情景敏感性分析 — 利率平行移动冲击
A2: ΔNII = −Δr × (A_β − L_β) | 敞口 ←「⑦期限结构与重定价」，NII ←「⑥NII计量表」
A4: 【一】利率平行移动情景
A5: 情景 | B5: Δr (bp) | C5: Δ利息收入 (亿元/年) | D5: Δ利息支出 (亿元/年) | E5: ΔNII (亿元/年) | F5: 情景后 NII (亿元/年) | G5: ΔNII % | H5: 情景后 NIM | I5: 情景解读
A6: 利率平行上移 250bp | B6: 250 | C6: =-$B$6/10000*'⑦期限结构与重定价'!$E$30 | D6: =-$B$6/10000*'⑦期限结构与重定价'!$E$31 | E6: =C6-D6 | F6: ='⑥NII计量表'!$B$20+E6 | G6: =IF('⑥NII计量表'!$B$20=0,0,E6/'⑥NII计量表'!$B$20) | H6: =IF('⑥NII计量表'!$B$5=0,0,F6/'⑥NII计量表'!$B$5) | I6: 大幅加息：资产端分期重定价滞后，NII 承压
A7: 利率平行上移 100bp | B7: 100 | C7: =-$B$7/10000*'⑦期限结构与重定价'!$E$30 | D7: =-$B$7/10000*'⑦期限结构与重定价'!$E$31 | E7: =C7-D7 | F7: ='⑥NII计量表'!$B$20+E7 | G7: =IF('⑥NII计量表'!$B$20=0,0,E7/'⑥NII计量表'!$B$20) | H7: =IF('⑥NII计量表'!$B$5=0,0,F7/'⑥NII计量表'!$B$5) | I7: 常规加息周期：重定价缺口决定 NII 方向
A8: 利率平行上移 50bp | B8: 50 | C8: =-$B$8/10000*'⑦期限结构与重定价'!$E$30 | D8: =-$B$8/10000*'⑦期限结构与重定价'!$E$31 | E8: =C8-D8 | F8: ='⑥NII计量表'!$B$20+E8 | G8: =IF('⑥NII计量表'!$B$20=0,0,E8/'⑥NII计量表'!$B$20) | H8: =IF('⑥NII计量表'!$B$5=0,0,F8/'⑥NII计量表'!$B$5) | I8: 温和加息：关注 NIM 是否跌破 1.50% 参考线
A9: 基准情景（利率不变） | B9: 0 | C9: =-$B$9/10000*'⑦期限结构与重定价'!$E$30 | D9: =-$B$9/10000*'⑦期限结构与重定价'!$E$31 | E9: =C9-D9 | F9: ='⑥NII计量表'!$B$20+E9 | G9: =IF('⑥NII计量表'!$B$20=0,0,E9/'⑥NII计量表'!$B$20) | H9: =IF('⑥NII计量表'!$B$5=0,0,F9/'⑥NII计量表'!$B$5) | I9: 基准：ΔNII = 0，NII = 计量表主口径
A10: 利率平行下移 50bp | B10: -50 | C10: =-$B$10/10000*'⑦期限结构与重定价'!$E$30 | D10: =-$B$10/10000*'⑦期限结构与重定价'!$E$31 | E10: =C10-D10 | F10: ='⑥NII计量表'!$B$20+E10 | G10: =IF('⑥NII计量表'!$B$20=0,0,E10/'⑥NII计量表'!$B$20) | H10: =IF('⑥NII计量表'!$B$5=0,0,F10/'⑥NII计量表'!$B$5) | I10: 温和降息：负债端成本下行，NII 受益
A11: 利率平行下移 100bp | B11: -100 | C11: =-$B$11/10000*'⑦期限结构与重定价'!$E$30 | D11: =-$B$11/10000*'⑦期限结构与重定价'!$E$31 | E11: =C11-D11 | F11: ='⑥NII计量表'!$B$20+E11 | G11: =IF('⑥NII计量表'!$B$20=0,0,E11/'⑥NII计量表'!$B$20) | H11: =IF('⑥NII计量表'!$B$5=0,0,F11/'⑥NII计量表'!$B$5) | I11: 降息周期：存款重定价滞后，短期利好 NIM
A12: 利率平行下移 250bp | B12: -250 | C12: =-$B$12/10000*'⑦期限结构与重定价'!$E$30 | D12: =-$B$12/10000*'⑦期限结构与重定价'!$E$31 | E12: =C12-D12 | F12: ='⑥NII计量表'!$B$20+E12 | G12: =IF('⑥NII计量表'!$B$20=0,0,E12/'⑥NII计量表'!$B$20) | H12: =IF('⑥NII计量表'!$B$5=0,0,F12/'⑥NII计量表'!$B$5) | I12: 大幅降息：贷款重定价滞后，NIM 阶段性走高
A13: 最不利情景 ΔNII（最小值） | E13: =MIN(E6:E12) | F13: ='⑥NII计量表'!$B$20+E13 | H13: =IF('⑥NII计量表'!$B$5=0,0,F13/'⑥NII计量表'!$B$5) | I13: 各情景中 NII 变动最不利者
A14: 最有利情景 ΔNII（最大值） | E14: =MAX(E6:E12) | F14: ='⑥NII计量表'!$B$20+E14 | H14: =IF('⑥NII计量表'!$B$5=0,0,F14/'⑥NII计量表'!$B$5) | I14: 各情景中 NII 变动最有利者
A16: 【二】单边冲击（资产端 / 负债端 分开重定价）
A17: 情景 | B17: Δr (bp) | C17: Δ利息收入 (亿元/年) | D17: Δ利息支出 (亿元/年) | E17: ΔNII (亿元/年) | F17: 情景后 NII (亿元/年) | G17: ΔNII % | H17: 情景后 NIM | I17: 情景解读
A18: 仅负债端全额重定价 +100bp | B18: 100 | C18: =-$B$18/10000*'⑦期限结构与重定价'!$E$30*0.0 | D18: =-$B$18/10000*'⑦期限结构与重定价'!$E$31*1.0 | E18: =C18-D18 | F18: ='⑥NII计量表'!$B$20+E18 | G18: =IF('⑥NII计量表'!$B$20=0,0,E18/'⑥NII计量表'!$B$20) | H18: =IF('⑥NII计量表'!$B$5=0,0,F18/'⑥NII计量表'!$B$5) | I18: 极端下限：负债 100% 重定价、资产 0% → NII 损失上限
A19: 仅资产端全额重定价 +100bp | B19: 100 | C19: =-$B$19/10000*'⑦期限结构与重定价'!$E$30*1.0 | D19: =-$B$19/10000*'⑦期限结构与重定价'!$E$31*0.0 | E19: =C19-D19 | F19: ='⑥NII计量表'!$B$20+E19 | G19: =IF('⑥NII计量表'!$B$20=0,0,E19/'⑥NII计量表'!$B$20) | H19: =IF('⑥NII计量表'!$B$5=0,0,F19/'⑥NII计量表'!$B$5) | I19: 极端上限：资产 100% 重定价、负债 0% → NII 改善上限
A20: 实际重定价（按 β 加权）+100bp | B20: 100 | C20: =-$B$20/10000*'⑦期限结构与重定价'!$E$30*1.0 | D20: =-$B$20/10000*'⑦期限结构与重定价'!$E$31*1.0 | E20: =C20-D20 | F20: ='⑥NII计量表'!$B$20+E20 | G20: =IF('⑥NII计量表'!$B$20=0,0,E20/'⑥NII计量表'!$B$20) | H20: =IF('⑥NII计量表'!$B$5=0,0,F20/'⑥NII计量表'!$B$5) | I20: 实际情景：各自按 β 加权（= 上表 +100bp）
A21: 负债重定价滞后 +100bp | B21: 100 | C21: =-$B$21/10000*'⑦期限结构与重定价'!$E$30*1.0 | D21: =-$B$21/10000*'⑦期限结构与重定价'!$E$31*0.3 | E21: =C21-D21 | F21: ='⑥NII计量表'!$B$20+E21 | G21: =IF('⑥NII计量表'!$B$20=0,0,E21/'⑥NII计量表'!$B$20) | H21: =IF('⑥NII计量表'!$B$5=0,0,F21/'⑥NII计量表'!$B$5) | I21: 假设存款久期锁定、有效 β 降至 30%
A23: 【三】NII 风险敞口判定
A24: 加息 100bp 下 NII 变化率（核心敏感度） | C24: =IF('⑥NII计量表'!$B$20=0,0,E7/'⑥NII计量表'!$B$20) | D24: 亿元/年 | I24: 绝对值越大，利率风险敞口越大
A25: 加息 100bp 下 NIM 变动（百分点） | C25: =IF('⑥NII计量表'!$B$5=0,0,(H7-'⑥NII计量表'!$B$27)) | D25: % | I25: 情景后 NIM − 基准 NIM
A26: 降息 100bp 下 NIM 变动（百分点） | C26: =IF('⑥NII计量表'!$B$5=0,0,(H11-'⑥NII计量表'!$B$27)) | D26: % | I26: 与上式未必等幅，取决于 β 分布
A27: NII 波动区间（最有利 − 最不利） | C27: =E14-E13 | D27: 亿元/年 | I27: 7 档情景下 NII 最大波动幅度
A28: 敞口方向判定 | C28: =IF('⑦期限结构与重定价'!$E$32>0,"正缺口：利率上行 NII 受损",IF('⑦期限结构与重定价'!$E$32<0,"负缺口：利率上行 NII 受益","利率中性")) | I28: 由 RG 符号决定
A29: 敞口强弱判定 | C29: =IF(ABS(E7/'⑥NII计量表'!$B$20)>0.05,"高敏感（>|5%|）",IF(ABS(E7/'⑥NII计量表'!$B$20)>0.02,"中敏感（2~5%）","低敏感（<2%）")) | I29: 阈值：100bp 冲击下 NII 变动幅度
A30: +250bp 情景 NIM 是否跌破 1.50% 下限 | C30: =IF(H6<'⑥NII计量表'!$B$49,"跌破 1.50% 下限","未跌破") | I30: 极端加息情景的监管红线检验

Sheet ⑩计算逻辑说明
A1: ⑩ NII 计量逻辑说明 · 数据来源映射 · prcp 实体对应
A3: 【一】数据来源（prcp_basic_20251231.xlsx / sheet「基础数据」，方案 8 / 2025-12-31）
A4: 当前余额 | B4: ①数据源!F 列 ← 基础数据 EJ 列（列 140），原始单位元，已换算为亿元
A5: 加权平均利率 | B5: ①数据源!G 列 ← 基础数据 EL 列（列 142），单位 %
A6: 月度利息（EM） | B6: ①数据源!H 列 ← 基础数据 EM 列（列 143）= 余额 × 利率 ÷ 100 ÷ 12
A7: 年度利息 | B7: ①数据源!I 列 = H × 12；已与 余额 × 利率 逐笔核对，偏差为 0
A8: 剩余期限分布 | B8: ②期限分布!C~BJ 列 ← 基础数据 BX~EI 列（列 76~139），共 64 桶
A9: 1 年内到期 | B9: ②期限分布 第 3+NB 列 = SUM(1M~12M 十二个桶)
A10: 收益率曲线 | B10: ③收益率曲线 ← 基础数据 R47~R111，64 点，中债登关键期限 + 线性插值
A11: 折现因子 | B11: ③收益率曲线!D 列 = 1/(1+y)^t，与基础数据 R113~R176 口径一致
A12: 重定价 β | B12: ①数据源!L 列 = min(0.98, max(0.10, Σ前12桶 ÷ Σ全部桶))，由期限分布推导
A13: 【二】核心计量公式
A14: 月度利息 M_i | B14: M_i = 当前余额_i × 加权平均利率_i ÷ 100 ÷ 12
A15: 年度利息 I_i | B15: I_i = M_i × 12 = 当前余额_i × 加权平均利率_i
A16: 利息收入 | B16: Σ 资产端 I_i（仅加权平均利率 > 0 的生息资产）
A17: 利息支出 | B17: Σ 负债端 I_i（全部计息负债）
A18: ★ 净利息收入 NII | B18: NII = 利息收入 − 利息支出（亿元/年）
A19: 生息资产收益率 | B19: =利息收入 ÷ 生息资产余额
A20: 计息负债成本率 | B20: =利息支出 ÷ 计息负债余额
A21: 净利差 NIS | B21: =生息资产收益率 − 计息负债成本率
A22: ★ 净息差 NIM | B22: NIM = NII ÷ 生息资产余额
A23: 重定价敞口 | B23: A_β = Σ(资产余额 × β)；L_β = Σ(负债余额 × β)
A24: ★ 重定价缺口 RG | B24: RG = A_β − L_β；RG > 0 → 利率上行时 NII 受损
A25: ΔNII 敏感度 | B25: ΔNII = −Δr × RG；NII 利率弹性 = −RG ÷ 生息资产
A26: 【三】期限分布口径说明（重要）
A27: 等额分期结构 | B27: 资产端非零桶为前 16 个（1M~16M 等额）；活期存款 3 桶；定期 / 市场化负债 12 桶
A28: Σ桶 ≤ 当前余额 | B28: Σ 分布合计仅覆盖余额 53.07%（资产）/ 99.98%（负债），差额为未到期续作本金
A29: 对 NII 的影响 | B29: NII 由 余额 × 加权利率 直接决定，不依赖期限分布；期限分布仅用于推导重定价 β
A30: 活期存款 β = 1 | B30: 活期存款 3 桶结构，1 年内 100% 到期，β 上限取 1，是负债端重定价最快的部分
A31: 资产端 β ≈ 0.20 | B31: 资产端 16 桶等额分期，1 年内到期约 1/4，β 显著低于负债端
A32: 【四】prcp 平台实体映射
A33: KpiScheme（指标方案） | B33: NII 指标方案主体，绑定账户册方案 CoaScheme（方案 8）
A34: KpiDefinition（指标定义） | B34: NII 定义：formula = Σ(资产利息) − Σ(负债利息)，unit = 亿元/年
A35: KpiDefinition（关联指标） | B35: NIM 定义引用 NII 作为输入，形成 NII → NIM 计量链路
A36: KpiValue（指标值） | B36: 落库字段：value + value_date + scheme_id + definition_id
A37: CoaNode（账户节点） | B37: 24 个末级账户对应 prcp_coa_node，node_code 即 ①数据源!A 列账户编码
A38: prcp_data_basic | B38: 余额与期限分布对应 prcp_data_basic 的 orig_* / rem_* 64 桶列
A39: MetricCoefficient（系数） | B39: 各账户加权平均利率对应系数表，支持按方案覆盖
A40: SimScheme（测算方案） | B40: 利率情景（Δr = ±250/100/50 bp）对应测算方案，批量重算 NII
A41: 【五】本模版相比早期版本的关键修正
...
