Workbook

Sheet ①分母口径数据源
A1: ① 分母口径数据源 — 取自 prcp_basic_20251231.xlsx「基础数据」（方案 8 / 2025-12-31）
A2: 🟢 绿区(蓝字) = 可编辑 | 🟣 紫字 = 自动计算 | ★分母归属 = 生息资产(EA) / 非生息(NEA)，决定该账户是否进入 NIM 分母 | 年度利息 = 余额 × 加权平均利率（= 参照物 EM × 12）
A3: 账户编码 | B3: 账户名称 | C3: 大类 | D3: 业务条线 | E3: 账户类型 | F3: 当前余额 (亿元) | G3: 加权平均 利率 | H3: 年度利息 (亿元/年) | I3: ★分母归属 | J3: 是否生息资产 | K3: 计息负债 | L3: 1年内到期 (亿元) | M3: 重定价β | N3: 风险权重 | O3: 口径说明
A4: S01010101000000 | B4: 1.1. 对公一般贷款 | C4: 资产 | D4: 信贷资产 | E4: 信贷 | F4: 245000 | G4: 0.041 | H4: =F4*G4 | I4: EA | J4: =IF(AND($C4="资产",$G4>0),"是","否") | K4: =IF($C4="负债","是","否") | L4: ='②期限分布'!BO4 | M4: =IF('②期限分布'!BP4=0,0,MIN(0.98,MAX(0.1,'②期限分布'!BO4/'②期限分布'!BP4))) | N4: 100 | O4: 产生利息收入 → 计入 NIM 分母
A5: S01010102000000 | B5: 1.2. 个人贷款 | C5: 资产 | D5: 信贷资产 | E5: 信贷 | F5: 175000 | G5: 0.0395 | H5: =F5*G5 | I5: EA | J5: =IF(AND($C5="资产",$G5>0),"是","否") | K5: =IF($C5="负债","是","否") | L5: ='②期限分布'!BO5 | M5: =IF('②期限分布'!BP5=0,0,MIN(0.98,MAX(0.1,'②期限分布'!BO5/'②期限分布'!BP5))) | N5: 55 | O5: 产生利息收入 → 计入 NIM 分母
A6: S01010103000000 | B6: 1.3. 信用卡贷款 | C6: 资产 | D6: 信贷资产 | E6: 信贷 | F6: 48000 | G6: 0.12 | H6: =F6*G6 | I6: EA | J6: =IF(AND($C6="资产",$G6>0),"是","否") | K6: =IF($C6="负债","是","否") | L6: ='②期限分布'!BO6 | M6: =IF('②期限分布'!BP6=0,0,MIN(0.98,MAX(0.1,'②期限分布'!BO6/'②期限分布'!BP6))) | N6: 75 | O6: 产生利息收入 → 计入 NIM 分母
A7: S01010104000000 | B7: 1.4. 票据贴现 | C7: 资产 | D7: 信贷资产 | E7: 信贷 | F7: 32000 | G7: 0.025 | H7: =F7*G7 | I7: EA | J7: =IF(AND($C7="资产",$G7>0),"是","否") | K7: =IF($C7="负债","是","否") | L7: ='②期限分布'!BO7 | M7: =IF('②期限分布'!BP7=0,0,MIN(0.98,MAX(0.1,'②期限分布'!BO7/'②期限分布'!BP7))) | N7: 100 | O7: 产生利息收入 → 计入 NIM 分母
A8: S01010105000000 | B8: 1.5. 非银贷款 | C8: 资产 | D8: 信贷资产 | E8: 信贷 | F8: 50000 | G8: 0.045 | H8: =F8*G8 | I8: EA | J8: =IF(AND($C8="资产",$G8>0),"是","否") | K8: =IF($C8="负债","是","否") | L8: ='②期限分布'!BO8 | M8: =IF('②期限分布'!BP8=0,0,MIN(0.98,MAX(0.1,'②期限分布'!BO8/'②期限分布'!BP8))) | N8: 100 | O8: 产生利息收入 → 计入 NIM 分母
A9: S010102010100 | B9: 2.1.1 金市自营债券 | C9: 资产 | D9: 债券投资 | E9: 投资 | F9: 150000 | G9: 0.0255 | H9: =F9*G9 | I9: EA | J9: =IF(AND($C9="资产",$G9>0),"是","否") | K9: =IF($C9="负债","是","否") | L9: ='②期限分布'!BO9 | M9: =IF('②期限分布'!BP9=0,0,MIN(0.98,MAX(0.1,'②期限分布'!BO9/'②期限分布'!BP9))) | N9: 0 | O9: 票息收入 → 计入 NIM 分母（FVTPL 票息 0 则不计入）
A10: S010102010200 | B10: 2.1.2 司库债券 | C10: 资产 | D10: 债券投资 | E10: 投资 | F10: 100000 | G10: 0.0285 | H10: =F10*G10 | I10: EA | J10: =IF(AND($C10="资产",$G10>0),"是","否") | K10: =IF($C10="负债","是","否") | L10: ='②期限分布'!BO10 | M10: =IF('②期限分布'!BP10=0,0,MIN(0.98,MAX(0.1,'②期限分布'!BO10/'②期限分布'!BP10))) | N10: 25 | O10: 票息收入 → 计入 NIM 分母（FVTPL 票息 0 则不计入）
A11: S01010202000000 | B11: 2.2. 结构化融资 | C11: 资产 | D11: 金融市场 | E11: 金融 | F11: 50000 | G11: 0.038 | H11: =F11*G11 | I11: EA | J11: =IF(AND($C11="资产",$G11>0),"是","否") | K11: =IF($C11="负债","是","否") | L11: ='②期限分布'!BO11 | M11: =IF('②期限分布'!BP11=0,0,MIN(0.98,MAX(0.1,'②期限分布'!BO11/'②期限分布'!BP11))) | N11: 100 | O11: 同业/准备金/结构化利息收入 → 计入分母
A12: S01010203000000 | B12: 2.3. 同业资产（不含拆放非银） | C12: 资产 | D12: 金融市场 | E12: 金融 | F12: 70000 | G12: 0.023 | H12: =F12*G12 | I12: EA | J12: =IF(AND($C12="资产",$G12>0),"是","否") | K12: =IF($C12="负债","是","否") | L12: ='②期限分布'!BO12 | M12: =IF('②期限分布'!BP12=0,0,MIN(0.98,MAX(0.1,'②期限分布'!BO12/'②期限分布'!BP12))) | N12: 20 | O12: 同业/准备金/结构化利息收入 → 计入分母
A13: S01010204000000 | B13: 2.4. 存款准备金 | C13: 资产 | D13: 金融市场 | E13: 金融 | F13: 30000 | G13: 0.0162 | H13: =F13*G13 | I13: EA | J13: =IF(AND($C13="资产",$G13>0),"是","否") | K13: =IF($C13="负债","是","否") | L13: ='②期限分布'!BO13 | M13: =IF('②期限分布'!BP13=0,0,MIN(0.98,MAX(0.1,'②期限分布'!BO13/'②期限分布'!BP13))) | N13: 0 | O13: 同业/准备金/结构化利息收入 → 计入分母
A14: S01010301000000 | B14: 3.1. FVTPL类资产 | C14: 资产 | D14: 非生息资产 | E14: 非息 | F14: 30000 | G14: 0.032 | H14: =F14*G14 | I14: EA | J14: =IF(AND($C14="资产",$G14>0),"是","否") | K14: =IF($C14="负债","是","否") | L14: ='②期限分布'!BO14 | M14: =IF('②期限分布'!BP14=0,0,MIN(0.98,MAX(0.1,'②期限分布'!BO14/'②期限分布'!BP14))) | N14: 100 | O14: 利率 0% → 不计入 NIM 分母，但计入总资产
A15: S01010302000000 | B15: 3.2. 其他非生息资产 | C15: 资产 | D15: 非生息资产 | E15: 非息 | F15: 20000 | G15: 0 | H15: =F15*G15 | I15: NEA | J15: =IF(AND($C15="资产",$G15>0),"是","否") | K15: =IF($C15="负债","是","否") | L15: ='②期限分布'!BO15 | M15: =IF('②期限分布'!BP15=0,0,MIN(0.98,MAX(0.1,'②期限分布'!BO15/'②期限分布'!BP15))) | N15: 50 | O15: 利率 0% → 不计入 NIM 分母，但计入总资产
... A27: S03000000000000 | B27: 所有者权益 | C27: 权益 | D27: 权益 | E27: 权益 | F27: 100000 | G27: 0 | H27: =F27*G27 | I27: - | J27: =IF(AND($C27="资产",$G27>0),"是","否") | K27: =IF($C27="负债","是","否") | L27: ='②期限分布'!BO27 | M27: =IF('②期限分布'!BP27=0,0,MIN(0.98,MAX(0.1,'②期限分布'!BO27/'②期限分布'!BP27))) | N27: 0 | O27: 无利息收支，不进入任何口径
B28: 合计 / 加权平均 | F28: =SUM(F4:F27) | G28: =IF(F28=0,0,SUMPRODUCT($F$4:$F$27,$G$4:$G$27)/F28) | H28: =SUM(H4:H27) | L28: =SUM('②期限分布'!BO4:BO27) | M28: =SUMPRODUCT($F$4:$F$27,$M$4:$M$27) | O28: M 列 = Σ(余额 × β) 全行重定价敞口

Sheet ②期限分布
A1: ② 剩余期限分布（64 桶，等额分期偿还结构）— 取自 prcp_basic_20251231.xlsx BX~EI 列
A2: 用于 NIM 的「有效计息资产」重定价分析 | 资产端 16 桶（1M~16M 等额）· 活期存款 3 桶 · 定期/市场化负债 12 桶 | Σ分布 ≤ 当前余额，差额为未到期续作本金
A3: 账户编码 | B3: 账户名称 | C3: 1M | D3: 2M | E3: 3M | F3: 4M | G3: 5M | H3: 6M | I3: 7M | J3: 8M | K3: 9M | L3: 10M | M3: 11M | N3: 12M | O3: 13M | P3: 14M | Q3: 15M | R3: 16M | S3: 17M | T3: 18M | U3: 19M | V3: 20M | W3: 21M | X3: 22M | Y3: 23M | Z3: 24M | AA3: 25M | AB3: 26M | AC3: 27M | AD3: 28M | AE3: 29M | AF3: 30M | AG3: 31M | AH3: 32M | AI3: 33M | AJ3: 34M | AK3: 35M | AL3: 36M | AM3: 37M | AN3: 38M | AO3: 39M | AP3: 40M | AQ3: 41M | AR3: 42M | AS3: 43M | AT3: 44M | AU3: 45M | AV3: 46M | AW3: 47M | AX3: 48M | AY3: 49M | AZ3: 50M | BA3: 51M | BB3: 52M | BC3: 53M | BD3: 54M | BE3: 55M | BF3: 56M | BG3: 57M | BH3: 58M | BI3: 59M | BJ3: 60M | BK3: 10Y | BL3: 15Y | BM3: 20Y | BN3: 30Y | BO3: 1年内到期 (1M~12M) | BP3: Σ 分布合计 | BQ3: 覆盖率
A4: S01010101000000 | B4: 1.1. 对公一般贷款 | C4: 5733 | D4: 5733 | E4: 5733 | F4: 5733 | G4: 5733 | H4: 5733 | I4: 5733 | J4: 5733 | K4: 5733 | L4: 5733 | M4: 5733 | N4: 5733 | BK4: 30625 | BL4: 15312.5 | BM4: 7644 | BN4: 7644 | BO4: =SUM(C4:N4) | BP4: =SUM(C4:BN4) | BQ4: =IF(F4=0,0,BP4/F4)
A5: S01010102000000 | B5: 1.2. 个人贷款 | C5: 4095 | D5: 4095 | E5: 4095 | F5: 4095 | G5: 4095 | H5: 4095 | I5: 4095 | J5: 4095 | K5: 4095 | L5: 4095 | M5: 4095 | N5: 4095 | BK5: 21875 | BL5: 10937.5 | BM5: 5460 | BN5: 5460 | BO5: =SUM(C5:N5) | BP5: =SUM(C5:BN5) | BQ5: =IF(F5=0,0,BP5/F5)
A6: S01010103000000 | B6: 1.3. 信用卡贷款 | C6: 1123.2 | D6: 1123.2 | E6: 1123.2 | F6: 1123.2 | G6: 1123.2 | H6: 1123.2 | I6: 1123.2 | J6: 1123.2 | K6: 1123.2 | L6: 1123.2 | M6: 1123.2 | N6: 1123.2 | BK6: 6000 | BL6: 3000 | BM6: 1497.6 | BN6: 1497.6 | BO6: =SUM(C6:N6) | BP6: =SUM(C6:BN6) | BQ6: =IF(F6=0,0,BP6/F6)
A7: S01010104000000 | B7: 1.4. 票据贴现 | C7: 748.8 | D7: 748.8 | E7: 748.8 | F7: 748.8 | G7: 748.8 | H7: 748.8 | I7: 748.8 | J7: 748.8 | K7: 748.8 | L7: 748.8 | M7: 748.8 | N7: 748.8 | BK7: 4000 | BL7: 2000 | BM7: 998.4 | BN7: 998.4 | BO7: =SUM(C7:N7) | BP7: =SUM(C7:BN7) | BQ7: =IF(F7=0,0,BP7/F7)
A8: S01010105000000 | B8: 1.5. 非银贷款 | C8: 1170 | D8: 1170 | E8: 1170 | F8: 1170 | G8: 1170 | H8: 1170 | I8: 1170 | J8: 1170 | K8: 1170 | L8: 1170 | M8: 1170 | N8: 1170 | BK8: 6250 | BL8: 3125 | BM8: 1560 | BN8: 1560 | BO8: =SUM(C8:N8) | BP8: =SUM(C8:BN8) | BQ8: =IF(F8=0,0,BP8/F8)
A9: S010102010100 | B9: 2.1.1 金市自营债券 | C9: 3510 | D9: 3510 | E9: 3510 | F9: 3510 | G9: 3510 | H9: 3510 | I9: 3510 | J9: 3510 | K9: 3510 | L9: 3510 | M9: 3510 | N9: 3510 | BK9: 18750 | BL9: 9375 | BM9: 4680 | BN9: 4680 | BO9: =SUM(C9:N9) | BP9: =SUM(C9:BN9) | BQ9: =IF(F9=0,0,BP9/F9)
A10: S010102010200 | B10: 2.1.2 司库债券 | C10: 2340 | D10: 2340 | E10: 2340 | F10: 2340 | G10: 2340 | H10: 2340 | I10: 2340 | J10: 2340 | K10: 2340 | L10: 2340 | M10: 2340 | N10: 2340 | BK10: 12500 | BL10: 6250 | BM10: 3120 | BN10: 3120 | BO10: =SUM(C10:N10) | BP10: =SUM(C10:BN10) | BQ10: =IF(F10=0,0,BP10/F10)
A11: S01010202000000 | B11: 2.2. 结构化融资 | C11: 1170 | D11: 1170 | E11: 1170 | F11: 1170 | G11: 1170 | H11: 1170 | I11: 1170 | J11: 1170 | K11: 1170 | L11: 1170 | M11: 1170 | N11: 1170 | BK11: 6250 | BL11: 3125 | BM11: 1560 | BN11: 1560 | BO11: =SUM(C11:N11) | BP11: =SUM(C11:BN11) | BQ11: =IF(F11=0,0,BP11/F11)
A12: S01010203000000 | B12: 2.3. 同业资产（不含拆放非银） | C12: 1638 | D12: 1638 | E12: 1638 | F12: 1638 | G12: 1638 | H12: 1638 | I12: 1638 | J12: 1638 | K12: 1638 | L12: 1638 | M12: 1638 | N12: 1638 | BK12: 8750 | BL12: 4375 | BM12: 2184 | BN12: 2184 | BO12: =SUM(C12:N12) | BP12: =SUM(C12:BN12) | BQ12: =IF(F12=0,0,BP12/F12)
A13: S01010204000000 | B13: 2.4. 存款准备金 | C13: 702 | D13: 702 | E13: 702 | F13: 702 | G13: 702 | H13: 702 | I13: 702 | J13: 702 | K13: 702 | L13: 702 | M13: 702 | N13: 702 | BK13: 3750 | BL13: 1875 | BM13: 936 | BN13: 936 | BO13: =SUM(C13:N13) | BP13: =SUM(C13:BN13) | BQ13: =IF(F13=0,0,BP13/F13)
A14: S01010301000000 | B14: 3.1. FVTPL类资产 | C14: 702 | D14: 702 | E14: 702 | F14: 702 | G14: 702 | H14: 702 | I14: 702 | J14: 702 | K14: 702 | L14: 702 | M14: 702 | N14: 702 | BK14: 3750 | BL14: 1875 | BM14: 936 | BN14: 936 | BO14: =SUM(C14:N14) | BP14: =SUM(C14:BN14) | BQ14: =IF(F14=0,0,BP14/F14)
A15: S01010302000000 | B15: 3.2. 其他非生息资产 | C15: 468 | D15: 468 | E15: 468 | F15: 468 | G15: 468 | H15: 468 | I15: 468 | J15: 468 | K15: 468 | L15: 468 | M15: 468 | N15: 468 | BK15: 2500 | BL15: 1250 | BM15: 624 | BN15: 624 | BO15: =SUM(C15:N15) | BP15: =SUM(C15:BN15) | BQ15: =IF(F15=0,0,BP15/F15)
... A19: S01020300000000 | B19: 3. 外币非生息资产 | C19: 234 | D19: 234 | E19: 234 | F19: 234 | G19: 234 | H19: 234 | I19: 234 | J19: 234 | K19: 234 | L19: 234 | M19: 234 | N19: 234 | BK19: 1250 | BL19: 625 | BM19: 312 | BN19: 312 | BO19: =SUM(C19:N19) | BP19: =SUM(C19:BN19) | BQ19: =IF(F19=0,0,BP19/F19)
A20: S020101010100 | B20: 1.1.1 对公活期存款 | C20: 130000 | D20: 78000 | E20: 52000 | BO20: =SUM(C20:N20) | BP20: =SUM(C20:BN20) | BQ20: =IF(F20=0,0,BP20/F20)
A21: S020101010200 | B21: 1.1.2 对公定期存款 | C21: 38830 | D21: 38830 | E21: 25872 | F21: 12936 | G21: 12936 | H21: 12936 | I21: 12936 | J21: 12936 | K21: 12936 | L21: 12936 | M21: 12936 | N21: 12936 | BO21: =SUM(C21:N21) | BP21: =SUM(C21:BN21) | BQ21: =IF(F21=0,0,BP21/F21)
A22: S020101020100 | B22: 1.2.1 零售活期存款 | C22: 60000 | D22: 36000 | E22: 24000 | BO22: =SUM(C22:N22) | BP22: =SUM(C22:BN22) | BQ22: =IF(F22=0,0,BP22/F22)
A23: S020101020200 | B23: 1.2.2 零售定期存款 | C23: 35300 | D23: 35300 | E23: 23520 | F23: 11760 | G23: 11760 | H23: 11760 | I23: 11760 | J23: 11760 | K23: 11760 | L23: 11760 | M23: 11760 | N23: 11760 | BO23: =SUM(C23:N23) | BP23: =SUM(C23:BN23) | BQ23: =IF(F23=0,0,BP23/F23)
A24: S02010200000000 | B24: 2. 人民币市场化负债 | C24: 21180 | D24: 21180 | E24: 14112 | F24: 7056 | G24: 7056 | H24: 7056 | I24: 7056 | J24: 7056 | K24: 7056 | L24: 7056 | M24: 7056 | N24: 7056 | BO24: =SUM(C24:N24) | BP24: =SUM(C24:BN24) | BQ24: =IF(F24=0,0,BP24/F24)
A25: S02020100000000 | B25: 1. 外币存款 | C25: 7060 | D25: 7060 | E25: 4704 | F25: 2352 | G25: 2352 | H25: 2352 | I25: 2352 | J25: 2352 | K25: 2352 | L25: 2352 | M25: 2352 | N25: 2352 | BO25: =SUM(C25:N25) | BP25: =SUM(C25:BN25) | BQ25: =IF(F25=0,0,BP25/F25)
A26: S02020200000000 | B26: 2. 外币市场化负债 | C26: 3530 | D26: 3530 | E26: 2352 | F26: 1176 | G26: 1176 | H26: 1176 | I26: 1176 | J26: 1176 | K26: 1176 | L26: 1176 | M26: 1176 | N26: 1176 | BO26: =SUM(C26:N26) | BP26: =SUM(C26:BN26) | BQ26: =IF(F26=0,0,BP26/F26)
A27: S03000000000000 | B27: 所有者权益 | BO27: =SUM(C27:N27) | BP27: =SUM(C27:BN27) | BQ27: =IF(F27=0,0,BP27/F27)
B28: 合计 | BO28: =SUM(BO4:BO27) | BP28: =SUM(BP4:BP27)

Sheet ③生息资产界定
A1: ③ 生息资产界定表 — 决定 NIM 分母的每一个账户
A2: 判定规则：资产端 且 加权平均利率 > 0 → 生息资产(EA) 计入分母；利率 = 0 → 非生息(NEA) 不计入分母 | 负债端与权益不进分母，仅提供分子
A3: 账户编码 | B3: 账户名称 | C3: 业务条线 | D3: 账户类型 | E3: 当前余额 (亿元) | F3: 加权平均 利率 | G3: 年度利息 (亿元/年) | H3: ★分母归属 | I3: 计入分母 余额(亿元) | J3: 不计入分母 余额(亿元) | K3: 余额占比 | L3: 判定依据
A4: ='①分母口径数据源'!A4 | B4: ='①分母口径数据源'!B4 | C4: ='①分母口径数据源'!D4 | D4: ='①分母口径数据源'!E4 | E4: ='①分母口径数据源'!F4 | F4: ='①分母口径数据源'!G4 | G4: ='①分母口径数据源'!H4 | H4: ='①分母口径数据源'!I4 | I4: =IF($H4="EA",$E4,0) | J4: =IF($H4="NEA",$E4,0) | K4: =IF(SUM($E$4:$E$19)=0,0,$E4/SUM($E$4:$E$19)) | L4: =IF($H4="EA","计入分母：产生利息收入","不计入：利率 0%，无利息收入")
A5: ='①分母口径数据源'!A5 | B5: ='①分母口径数据源'!B5 | C5: ='①分母口径数据源'!D5 | D5: ='①分母口径数据源'!E5 | E5: ='①分母口径数据源'!F5 | F5: ='①分母口径数据源'!G5 | G5: ='①分母口径数据源'!H5 | H5: ='①分母口径数据源'!I5 | I5: =IF($H5="EA",$E5,0) | J5: =IF($H5="NEA",$E5,0) | K5: =IF(SUM($E$4:$E$19)=0,0,$E5/SUM($E$4:$E$19)) | L5: =IF($H5="EA","计入分母：产生利息收入","不计入：利率 0%，无利息收入")
A6: ='①分母口径数据源'!A6 | B6: ='①分母口径数据源'!B6 | C6: ='①分母口径数据源'!D6 | D6: ='①分母口径数据源'!E6 | E6: ='①分母口径数据源'!F6 | F6: ='①分母口径数据源'!G6 | G6: ='①分母口径数据源'!H6 | H6: ='①分母口径数据源'!I6 | I6: =IF($H6="EA",$E6,0) | J6: =IF($H6="NEA",$E6,0) | K6: =IF(SUM($E$4:$E$19)=0,0,$E6/SUM($E$4:$E$19)) | L6: =IF($H6="EA","计入分母：产生利息收入","不计入：利率 0%，无利息收入")
A7: ='①分母口径数据源'!A7 | B7: ='①分母口径数据源'!B7 | C7: ='①分母口径数据源'!D7 | D7: ='①分母口径数据源'!E7 | E7: ='①分母口径数据源'!F7 | F7: ='①分母口径数据源'!G7 | G7: ='①分母口径数据源'!H7 | H7: ='①分母口径数据源'!I7 | I7: =IF($H7="EA",$E7,0) | J7: =IF($H7="NEA",$E7,0) | K7: =IF(SUM($E$4:$E$19)=0,0,$E7/SUM($E$4:$E$19)) | L7: =IF($H7="EA","计入分母：产生利息收入","不计入：利率 0%，无利息收入")
A8: ='①分母口径数据源'!A8 | B8: ='①分母口径数据源'!B8 | C8: ='①分母口径数据源'!D8 | D8: ='①分母口径数据源'!E8 | E8: ='①分母口径数据源'!F8 | F8: ='①分母口径数据源'!G8 | G8: ='①分母口径数据源'!H8 | H8: ='①分母口径数据源'!I8 | I8: =IF($H8="EA",$E8,0) | J8: =IF($H8="NEA",$E8,0) | K8: =IF(SUM($E$4:$E$19)=0,0,$E8/SUM($E$4:$E$19)) | L8: =IF($H8="EA","计入分母：产生利息收入","不计入：利率 0%，无利息收入")
A9: ='①分母口径数据源'!A9 | B9: ='①分母口径数据源'!B9 | C9: ='①分母口径数据源'!D9 | D9: ='①分母口径数据源'!E9 | E9: ='①分母口径数据源'!F9 | F9: ='①分母口径数据源'!G9 | G9: ='①分母口径数据源'!H9 | H9: ='①分母口径数据源'!I9 | I9: =IF($H9="EA",$E9,0) | J9: =IF($H9="NEA",$E9,0) | K9: =IF(SUM($E$4:$E$19)=0,0,$E9/SUM($E$4:$E$19)) | L9: =IF($H9="EA","计入分母：产生利息收入","不计入：利率 0%，无利息收入")
A10: ='①分母口径数据源'!A10 | B10: ='①分母口径数据源'!B10 | C10: ='①分母口径数据源'!D10 | D10: ='①分母口径数据源'!E10 | E10: ='①分母口径数据源'!F10 | F10: ='①分母口径数据源'!G10 | G10: ='①分母口径数据源'!H10 | H10: ='①分母口径数据源'!I10 | I10: =IF($H10="EA",$E10,0) | J10: =IF($H10="NEA",$E10,0) | K10: =IF(SUM($E$4:$E$19)=0,0,$E10/SUM($E$4:$E$19)) | L10: =IF($H10="EA","计入分母：产生利息收入","不计入：利率 0%，无利息收入")
A11: ='①分母口径数据源'!A11 | B11: ='①分母口径数据源'!B11 | C11: ='①分母口径数据源'!D11 | D11: ='①分母口径数据源'!E11 | E11: ='①分母口径数据源'!F11 | F11: ='①分母口径数据源'!G11 | G11: ='①分母口径数据源'!H11 | H11: ='①分母口径数据源'!I11 | I11: =IF($H11="EA",$E11,0) | J11: =IF($H11="NEA",$E11,0) | K11: =IF(SUM($E$4:$E$19)=0,0,$E11/SUM($E$4:$E$19)) | L11: =IF($H11="EA","计入分母：产生利息收入","不计入：利率 0%，无利息收入")
A12: ='①分母口径数据源'!A12 | B12: ='①分母口径数据源'!B12 | C12: ='①分母口径数据源'!D12 | D12: ='①分母口径数据源'!E12 | E12: ='①分母口径数据源'!F12 | F12: ='①分母口径数据源'!G12 | G12: ='①分母口径数据源'!H12 | H12: ='①分母口径数据源'!I12 | I12: =IF($H12="EA",$E12,0) | J12: =IF($H12="NEA",$E12,0) | K12: =IF(SUM($E$4:$E$19)=0,0,$E12/SUM($E$4:$E$19)) | L12: =IF($H12="EA","计入分母：产生利息收入","不计入：利率 0%，无利息收入")
A13: ='①分母口径数据源'!A13 | B13: ='①分母口径数据源'!B13 | C13: ='①分母口径数据源'!D13 | D13: ='①分母口径数据源'!E13 | E13: ='①分母口径数据源'!F13 | F13: ='①分母口径数据源'!G13 | G13: ='①分母口径数据源'!H13 | H13: ='①分母口径数据源'!I13 | I13: =IF($H13="EA",$E13,0) | J13: =IF($H13="NEA",$E13,0) | K13: =IF(SUM($E$4:$E$19)=0,0,$E13/SUM($E$4:$E$19)) | L13: =IF($H13="EA","计入分母：产生利息收入","不计入：利率 0%，无利息收入")
A14: ='①分母口径数据源'!A14 | B14: ='①分母口径数据源'!B14 | C14: ='①分母口径数据源'!D14 | D14: ='①分母口径数据源'!E14 | E14: ='①分母口径数据源'!F14 | F14: ='①分母口径数据源'!G14 | G14: ='①分母口径数据源'!H14 | H14: ='①分母口径数据源'!I14 | I14: =IF($H14="EA",$E14,0) | J14: =IF($H14="NEA",$E14,0) | K14: =IF(SUM($E$4:$E$19)=0,0,$E14/SUM($E$4:$E$19)) | L14: =IF($H14="EA","计入分母：产生利息收入","不计入：利率 0%，无利息收入")
A15: ='①分母口径数据源'!A15 | B15: ='①分母口径数据源'!B15 | C15: ='①分母口径数据源'!D15 | D15: ='①分母口径数据源'!E15 | E15: ='①分母口径数据源'!F15 | F15: ='①分母口径数据源'!G15 | G15: ='①分母口径数据源'!H15 | H15: ='①分母口径数据源'!I15 | I15: =IF($H15="EA",$E15,0) | J15: =IF($H15="NEA",$E15,0) | K15: =IF(SUM($E$4:$E$19)=0,0,$E15/SUM($E$4:$E$19)) | L15: =IF($H15="EA","计入分母：产生利息收入","不计入：利率 0%，无利息收入")
... A19: ='①分母口径数据源'!A19 | B19: ='①分母口径数据源'!B19 | C19: ='①分母口径数据源'!D19 | D19: ='①分母口径数据源'!E19 | E19: ='①分母口径数据源'!F19 | F19: ='①分母口径数据源'!G19 | G19: ='①分母口径数据源'!H19 | H19: ='①分母口径数据源'!I19 | I19: =IF($H19="EA",$E19,0) | J19: =IF($H19="NEA",$E19,0) | K19: =IF(SUM($E$4:$E$19)=0,0,$E19/SUM($E$4:$E$19)) | L19: =IF($H19="EA","计入分母：产生利息收入","不计入：利率 0%，无利息收入")
B20: 资产端合计 | E20: =SUM(E4:E19) | G20: =SUM(G4:G19) | I20: =SUM(I4:I19) | J20: =SUM(J4:J19) | K20: =SUM(K4:K19) | L20: I 列 = 生息资产（NIM 分母），J 列 = 非生息资产
B21: ★ 生息资产合计（NIM 分母） | E21: =I20 | F21: =IF(E21=0,0,G21/E21) | G21: =SUMIF($H$4:$H$19,"EA",$G$4:$G$19) | L21: F 列 = 生息资产加权平均收益率 ★ NIM 分子/分母
B22: 非生息资产合计（不计入分母） | E22: =J20 | L22: 现金 / 其它非生息资产
A24: 【校验】与参照物总量核对
B25: 参照物总资产（基础数据 EJ 列 R4） | E25: 1080000 | L25: 参照物总资产（基础数据 R4 EJ 列）
B26: 校验：资产端合计 − 参照物总资产（应为 0） | E26: =ROUND(E20-E25,6) | L26: 末级账户余额加总应等于总资产

Sheet ④计息负债明细
A1: ④ 计息负债明细 — NIM 分子的负债端构成
A2: 计息负债全部计入 NIM 分子（利息支出）；活期存款 3 桶结构，1 年内 100% 到期，成本刚性
A3: 账户编码 | B3: 账户名称 | C3: 业务条线 | D3: 账户类型 | E3: 当前余额 (亿元) | F3: 加权平均 利率 | G3: 年度利息 (亿元/年) | H3: 利息支出 占比 | I3: 累计占比 | J3: 1年内到期 (亿元) | K3: 到期占比 | L3: 结构说明
A4: ='①分母口径数据源'!A20 | B4: ='①分母口径数据源'!B20 | C4: ='①分母口径数据源'!D20 | D4: ='①分母口径数据源'!E20 | E4: ='①分母口径数据源'!F20 | F4: ='①分母口径数据源'!G20 | G4: ='①分母口径数据源'!H20 | H4: =IF($G$11=0,0,G4/$G$11) | I4: =H4 | J4: ='①分母口径数据源'!L20 | K4: =IF(E4=0,0,J4/E4) | L4: 3 桶（1M~3M），1 年内 100% 到期，成本几乎不随政策利率变动
A5: ='①分母口径数据源'!A21 | B5: ='①分母口径数据源'!B21 | C5: ='①分母口径数据源'!D21 | D5: ='①分母口径数据源'!E21 | E5: ='①分母口径数据源'!F21 | F5: ='①分母口径数据源'!G21 | G5: ='①分母口径数据源'!H21 | H5: =IF($G$11=0,0,G5/$G$11) | I5: =I4+H5 | J5: ='①分母口径数据源'!L21 | K5: =IF(E5=0,0,J5/E5) | L5: 12 桶（1M~12M），到期续作时重定价
A6: ='①分母口径数据源'!A22 | B6: ='①分母口径数据源'!B22 | C6: ='①分母口径数据源'!D22 | D6: ='①分母口径数据源'!E22 | E6: ='①分母口径数据源'!F22 | F6: ='①分母口径数据源'!G22 | G6: ='①分母口径数据源'!H22 | H6: =IF($G$11=0,0,G6/$G$11) | I6: =I5+H6 | J6: ='①分母口径数据源'!L22 | K6: =IF(E6=0,0,J6/E6) | L6: 3 桶（1M~3M），1 年内 100% 到期，成本几乎不随政策利率变动
A7: ='①分母口径数据源'!A23 | B7: ='①分母口径数据源'!B23 | C7: ='①分母口径数据源'!D23 | D7: ='①分母口径数据源'!E23 | E7: ='①分母口径数据源'!F23 | F7: ='①分母口径数据源'!G23 | G7: ='①分母口径数据源'!H23 | H7: =IF($G$11=0,0,G7/$G$11) | I7: =I6+H7 | J7: ='①分母口径数据源'!L23 | K7: =IF(E7=0,0,J7/E7) | L7: 12 桶（1M~12M），到期续作时重定价
A8: ='①分母口径数据源'!A24 | B8: ='①分母口径数据源'!B24 | C8: ='①分母口径数据源'!D24 | D8: ='①分母口径数据源'!E24 | E8: ='①分母口径数据源'!F24 | F8: ='①分母口径数据源'!G24 | G8: ='①分母口径数据源'!H24 | H8: =IF($G$11=0,0,G8/$G$11) | I8: =I7+H8 | J8: ='①分母口径数据源'!L24 | K8: =IF(E8=0,0,J8/E8) | L8: 12 桶货币市场工具，SHIBOR/DR 联动，β 接近 1
A9: ='①分母口径数据源'!A25 | B9: ='①分母口径数据源'!B25 | C9: ='①分母口径数据源'!D25 | D9: ='①分母口径数据源'!E25 | E9: ='①分母口径数据源'!F25 | F9: ='①分母口径数据源'!G25 | G9: ='①分母口径数据源'!H25 | H9: =IF($G$11=0,0,G9/$G$11) | I9: =I8+H9 | J9: ='①分母口径数据源'!L25 | K9: =IF(E9=0,0,J9/E9) | L9: 折人民币，受境内外利差与汇率影响
A10: ='①分母口径数据源'!A26 | B10: ='①分母口径数据源'!B26 | C10: ='①分母口径数据源'!D26 | D10: ='①分母口径数据源'!E26 | E10: ='①分母口径数据源'!F26 | F10: ='①分母口径数据源'!G26 | G10: ='①分母口径数据源'!H26 | H10: =IF($G$11=0,0,G10/$G$11) | I10: =I9+H10 | J10: ='①分母口径数据源'!L26 | K10: =IF(E10=0,0,J10/E10) | L10: 折人民币，受境内外利差与汇率影响
B11: 计息负债合计 | E11: =SUM(E4:E10) | F11: =IF(E11=0,0,G11/E11) | G11: =SUM(G4:G10) | H11: =SUM(H4:H10) | I11: =I10 | J11: =SUM(J4:J10) | K11: =IF(E11=0,0,J11/E11) | L11: F 列 = 计息负债加权平均成本率
A13: 【附】按账户类型分组小计
B14: 活期存款 | E14: =SUMIF('①分母口径数据源'!$D$4:$D$27,"活期存款",'①分母口径数据源'!$F$4:$F$27) | F14: =IF(E14=0,0,SUMIF('①分母口径数据源'!$D$4:$D$27,"活期存款",'①分母口径数据源'!$H$4:$H$27)/E14) | G14: =SUMIF('①分母口径数据源'!$D$4:$D$27,"活期存款",'①分母口径数据源'!$H$4:$H$27) | L14: 3 桶（1M~3M），1 年内 100% 到期，成本几乎不随政策利率变动
B15: 定期存款 | E15: =SUMIF('①分母口径数据源'!$D$4:$D$27,"定期存款",'①分母口径数据源'!$F$4:$F$27) | F15: =IF(E15=0,0,SUMIF('①分母口径数据源'!$D$4:$D$27,"定期存款",'①分母口径数据源'!$H$4:$H$27)/E15) | G15: =SUMIF('①分母口径数据源'!$D$4:$D$27,"定期存款",'①分母口径数据源'!$H$4:$H$27) | L15: 12 桶（1M~12M），到期续作时重定价
B16: 市场化负债 | E16: =SUMIF('①分母口径数据源'!$D$4:$D$27,"市场化负债",'①分母口径数据源'!$F$4:$F$27) | F16: =IF(E16=0,0,SUMIF('①分母口径数据源'!$D$4:$D$27,"市场化负债",'①分母口径数据源'!$H$4:$H$27)/E16) | G16: =SUMIF('①分母口径数据源'!$D$4:$D$27,"市场化负债",'①分母口径数据源'!$H$4:$H$27) | L16: 12 桶货币市场工具，SHIBOR/DR 联动，β 接近 1
B17: 外币负债 | E17: =SUMIF('①分母口径数据源'!$D$4:$D$27,"外币负债",'①分母口径数据源'!$F$4:$F$27) | F17: =IF(E17=0,0,SUMIF('①分母口径数据源'!$D$4:$D$27,"外币负债",'①分母口径数据源'!$H$4:$H$27)/E17) | G17: =SUMIF('①分母口径数据源'!$D$4:$D$27,"外币负债",'①分母口径数据源'!$H$4:$H$27) | L17: 折人民币，受境内外利差与汇率影响
B18: 存款活期化率（活期 ÷ 存款合计） | E18: =IF((E14+E15)=0,0,E14/(E14+E15)) | L18: 活期付息成本最低，活期化率是 NIM 的关键结构变量

Sheet ⑤NIM计量表
A1: ⑤ 净息差（NIM）计量表 — 基于 prcp_basic_20251231.xlsx 真实数据
A2: NIM = 利息净收入 ÷ 平均生息资产 | NIS = 生息资产收益率 − 计息负债成本率 | 本表核心是「分母界定」，分子与「NII计量模版」完全一致 | 单位：亿元 / 亿元每年 / %
A4: 【一】NIM 分母口径界定（本模版核心）
A5: ★ 生息资产（NIM 分母，利率 > 0） | B5: ='③生息资产界定'!E21 | C5: =IF($B$7=0,0,B5/$B$7) | D5: 亿元 | E5: 16 个资产账户中利率 > 0 的部分
A6: 非生息资产（不计入分母） | B6: ='③生息资产界定'!E22 | C6: =IF($B$7=0,0,B6/$B$7) | D6: 亿元 | E6: 现金 / 其它非生息资产，利率 0%
A7: 资产端合计（= 参照物总资产） | B7: ='③生息资产界定'!E20 | C7: =IF($B$7=0,0,B7/$B$7) | D7: 亿元 | E7: 生息 + 非生息
A8: 所有者权益（不进入分母） | B8: 100000 | D8: 亿元 | E8: 参照物 10 万亿；NIM 分母不含权益
A9: 计息负债（进入分子，不进入分母） | B9: ='④计息负债明细'!E11 | D9: 亿元 | E9: NIM = NII ÷ 生息资产，负债只影响分子
A11: 【二】分子：利息收入与利息支出
A12: 利息收入合计（生息资产） | B12: ='③生息资产界定'!G21 | D12: 亿元/年 | E12: Σ 生息资产 余额 × 加权平均利率
A13: 利息支出合计（计息负债） | B13: ='④计息负债明细'!G11 | D13: 亿元/年 | E13: Σ 计息负债 余额 × 加权平均利率
A15: 【三】★ 核心指标：NIM 与 NIS
A16: 利息净收入 NII（= 与 NII计量模版一致） | B16: =B12-B13 | D16: 亿元/年 | E16: 校验点：应与 NII计量模版!⑥NII 完全一致
A17: ★ 净息差 NIM（NII ÷ 生息资产） | B17: =IF($B$5=0,0,$B$16/$B$5) | D17: % | E17: ★ NIM 计量最终输出指标（监管口径分母）
A18: 生息资产收益率（利息收入 ÷ 生息资产） | B18: =IF($B$5=0,0,$B$12/$B$5) | D18: % | E18: 资产端盈利能力
A19: 计息负债成本率（利息支出 ÷ 计息负债） | B19: =IF($B$9=0,0,$B$13/$B$9) | D19: % | E19: 负债端付息成本
A20: ★ 净利差 NIS（净收益率 − 净成本率） | B20: =B18-B19 | D20: % | E20: ★ 资产端与负债端的定价之差
A22: 【四】★ NIM ≠ NIS：分母错配的量化拆解（常见误区澄清）
A23: 生息资产 ÷ 计息负债（规模比） | B23: =IF($B$9=0,0,$B$5/$B$9) | D23: 倍 | E23: 生息资产规模是计息负债的多少倍
A24: 负债支持率 k = 计息负债 ÷ 生息资产 | B24: =IF($B$5=0,0,$B$9/$B$5) | D24: % | E24: ★ 恒小于 100%，因非生息资产不由负债全额融资
A25: ★ 校验：收益率 − 成本率 × k − NIM（应为 0） | B25: =ROUND($B$18-$B$19*$B$24-$B$17,10) | D25: 倍 | E25: ★ 正确关系：NIM = 生息资产收益率 − 计息负债成本率 × k（加权差，非相乘）
A26: NIS − NIM（利差与息差的差额） | B26: =$B$20-$B$17 | D26: 个百分点 | E26: ⚠ NIM 通常 > NIS：分子中利息支出按计息负债计，分母用生息资产，两者口径不一致
A27: ⚠ 常见误区：NIS × k（错误做法，非 NIM） | B27: =$B$20*$B$24 | D27: % | E27: 净利差×负债率 ≠ 净息差；两处分母不同，必须用「收益率 − 成本率×k」
A28: 误区造成的偏差（NIS × k − NIM） | B28: =$B$27-$B$17 | D28: 个百分点 | E28: 本例偏差约 −0.26pp，若误用会严重低估 NIM
A30: 【五】多口径 NIM 对比（分母界定如何影响结果）
A31: 口径 1（★监管口径）：NII ÷ 生息资产 | B31: =$B$17 | C31: =B31-$B$31 | E31: 本行采用口径，剔除利率 0 的非生息资产
A32: 口径 2：NII ÷ 资产端合计（含非生息） | B32: =IF($B$7=0,0,$B$16/$B$7) | C32: =B32-$B$31 | D32: % | E32: 分母含非生息，NIM 被系统性低估
A33: 口径 3：NII ÷ 计息负债 | B33: =IF($B$9=0,0,$B$16/$B$9) | C33: =B33-$B$31 | D33: % | E33: 分子分母口径不匹配，非监管定义，仅作对照
A34: 口径 4：NII ÷ 总资产（含权益） | B34: =IF(($B$7+$B$8)=0,0,$B$16/($B$7+$B$8)) | C34: =B34-$B$31 | D34: % | E34: 分母含权益，杠杆调整后口径
A35: 口径 5：NII ÷ 风险加权资产（RWA 近似） | B35: =IF(SUMIF('①分母口径数据源'!$C$4:$C$27,"资产",'①分母口径数据源'!$F$4:$F$27)=0,0,$B$16/SUMIF('①分母口径数据源'!$C$4:$C$27,"资产",'①分母口径数据源'!$F$4:$F$27)) | C35: =B35-$B$31 | D35: % | E35: 无表外资产，RWA 口径近似等于资产端合计
A36: 口径敏感度：口径 1 与口径 2 差异 | B36: =$B$31-$B$32 | E36: 仅因分母是否含非生息资产，NIM 可差 多个百分点
A38: 【六】杜邦三分解：NIM 的三个驱动因子
A39: 资产效率 = 生息资产 ÷ 资产端合计 | B39: =IF($B$7=0,0,$B$5/$B$7) | E39: 非生息资产占比的倒数，越大越好
A40: 负债支持率 k = 计息负债 ÷ 生息资产 | B40: =$B$24 | D40: % | E40: 与【四】同源，两处分母不同
A41: 资产端贡献 = 生息资产收益率 | B41: =$B$18 | D41: % | E41: 每元生息资产产生的利息收入
A42: 负债端贡献 = 成本率 × k | B42: =$B$19*$B$40 | D42: % | E42: 每元生息资产承担的利息支出（已按 k 折算）
A43: ★ NIM 复核 = 资产端 − 负债端 | B43: =$B$41-$B$42 | D43: % | E43: ★ 应等于 NIM
A44: 校验：复核值 − NIM（应为 0） | B44: =ROUND($B$43-$B$17,10) | E44: 分解恒等式自检
A45: （附）总资产口径净息差 = NIM × 资产效率 | B45: =$B$17*$B$39 | D45: % | E45: 分母换成资产端合计，即口径 2 的 NIM
A47: 【七】结构比率
...

Sheet ⑥NIM驱动分解
A1: ⑥ NIM 驱动因素分解 — 量、价、结构三维
A2: ΔNIM ≈ Σ(条线余额占比 × 条线利差) | 量（规模摊薄）/ 价（利率变动）/ 结构（活期化、信贷占比）三条路径 | 全部引用 ① 与 NIM计量表
A4: 【一】按业务条线的 NIM 贡献分解（资产端）
A5: 业务条线 | B5: 方向 | C5: 余额 (亿元) | D5: 余额占比 | E5: 综合利率 | F5: 利息金额 (亿元/年) | G5: 利息占比 | H5: 说明
A6: 外币负债 | B6: 负债 | C6: =SUMIF('①分母口径数据源'!$D$4:$D$27,"外币负债",'①分母口径数据源'!$F$4:$F$27) | D6: =IF(SUMIF($B$6:$B$14,$B6,$C$6:$C$14)=0,0,C6/SUMIF($B$6:$B$14,$B6,$C$6:$C$14)) | E6: =IF(C6=0,0,SUMIF('①分母口径数据源'!$D$4:$D$27,"外币负债",'①分母口径数据源'!$H$4:$H$27)/C6) | F6: =SUMIF('①分母口径数据源'!$D$4:$D$27,"外币负债",'①分母口径数据源'!$H$4:$H$27) | G6: =IF(SUMIF($B$6:$B$14,$B6,$F$6:$F$14)=0,0,F6/SUMIF($B$6:$B$14,$B6,$F$6:$F$14)) | H6: 余额 6 万亿，成本 2.60%
A16: 【二】NIM 三因子拆解：量 / 价 / 结构
A17: 驱动因子 | B17: 维度 | C17: 当前值 | D17: 基准 | E17: 变动量 | F17: 对 NIM 影响 (百分点) | G17: 敏感度 | H17: 说明
A18: 生息资产规模 | B18: 量 | C18: ='⑤NIM计量表'!B5 | D18: ='⑤NIM计量表'!B5 | E18: — | F18: — | G18: 规模变动 | H18: NIM 是比率，规模扩张对 NIM 中性（分子分母同增）
A25: 【三】结构优化情景（测算 NIM 提升空间）
A26: 假设与口径：① 分子按调整后余额 × 利率重算；② 分母为调整后的生息资产；③ 不考虑规模总量变化
A27: 参数：非生息资产转生息的收益率 | C27: 0.02 | H27: 可编辑；默认 2.00%（参考同业活期水平）
A29: 优化情景 | B29: 维度 | C29: 调整幅度 | D29: 新 NIM | E29: ΔNIM (百分点) | F29: 可行性 | G29: 生效分母 (亿元) | H29: 说明
A30: 活期化率 −10pp：10% 定期余额转入活期 | B30: 结构 | C30: −10pp | D30: =('⑤NIM计量表'!$B$12-'⑤NIM计量表'!$B$13+SUMIF('①分母口径数据源'!$E$4:$E$27,"定期",'①分母口径数据源'!$H$4:$H$27)*0.1-SUMIF('①分母口径数据源'!$E$4:$E$27,"活期",'①分母口径数据源'!$H$4:$H$27)*0.1)/'⑤NIM计量表'!$B$5 | E30: =D30-'⑤NIM计量表'!$B$17 | F30: 中 | G30: ='⑤NIM计量表'!$B$5 | H30: 新利息支出 = 原支出 − 定期利息×10% + 活期利息×10%
A31: 活期化率 +10pp：10% 活期余额转入定期 | B31: 结构 | C31: +10pp | D31: =('⑤NIM计量表'!$B$12-'⑤NIM计量表'!$B$13-SUMIF('①分母口径数据源'!$E$4:$E$27,"定期",'①分母口径数据源'!$H$4:$H$27)*0.1+SUMIF('①分母口径数据源'!$E$4:$E$27,"活期",'①分母口径数据源'!$H$4:$H$27)*0.1)/'⑤NIM计量表'!$B$5 | E31: =D31-'⑤NIM计量表'!$B$17 | F31: 低 | G31: ='⑤NIM计量表'!$B$5 | H31: 新利息支出 = 原支出 + 定期利息×10% − 活期利息×10%
A32: 信贷占比 +5pp：债券置换为信贷 | B32: 结构 | C32: +5pp | D32: =('⑤NIM计量表'!$B$12+'⑤NIM计量表'!$B$5*0.05*((SUMIF('①分母口径数据源'!$E$4:$E$27,"信贷",'①分母口径数据源'!$H$4:$H$27)/SUMIF('①分母口径数据源'!$E$4:$E$27,"信贷",'①分母口径数据源'!$F$4:$F$27))-(SUMIF('①分母口径数据源'!$E$4:$E$27,"投资",'①分母口径数据源'!$H$4:$H$27)/SUMIF('①分母口径数据源'!$E$4:$E$27,"投资",'①分母口径数据源'!$F$4:$F$27)))-'⑤NIM计量表'!$B$13)/'⑤NIM计量表'!$B$5 | E32: =D32-'⑤NIM计量表'!$B$17 | F32: 中低 | G32: ='⑤NIM计量表'!$B$5 | H32: 新利息收入 = 原收入 + 生息资产×5pp×(信贷利率 − 债券利率)
A33: 计息负债成本 −10bp | B33: 价 | C33: −10bp | D33: =('⑤NIM计量表'!$B$12-('⑤NIM计量表'!$B$13-'⑤NIM计量表'!$B$9*0.001))/'⑤NIM计量表'!$B$5 | E33: =D33-'⑤NIM计量表'!$B$17 | F33: 高 | G33: ='⑤NIM计量表'!$B$5 | H33: ★ 新利息支出 = 原支出 − 计息负债×10bp；最直接可控的 NIM 提升手段
A34: 市场化负债成本 −10bp | B34: 价 | C34: −10bp | D34: =('⑤NIM计量表'!$B$12-('⑤NIM计量表'!$B$13-SUMIF('①分母口径数据源'!$E$4:$E$27,"同业",'①分母口径数据源'!$H$4:$H$27)+SUMIF('①分母口径数据源'!$E$4:$E$27,"同业",'①分母口径数据源'!$F$4:$F$27)*0.001))/'⑤NIM计量表'!$B$5 | E34: =D34-'⑤NIM计量表'!$B$17 | F34: 高 | G34: ='⑤NIM计量表'!$B$5 | H34: 仅下调同业/市场化负债成本 10bp，其余负债成本不变
A35: 生息资产收益率 +10bp | B35: 价 | C35: +10bp | D35: =('⑤NIM计量表'!$B$12+'⑤NIM计量表'!$B$5*0.001-'⑤NIM计量表'!$B$13)/'⑤NIM计量表'!$B$5 | E35: =D35-'⑤NIM计量表'!$B$17 | F35: 中低 | G35: ='⑤NIM计量表'!$B$5 | H35: 新利息收入 = 原收入 + 生息资产×10bp；受客户议价与投放能力约束
A36: 非生息资产 −50%：按 2% 转为生息 | B36: 结构 | C36: −50% | D36: =('⑤NIM计量表'!$B$12+('⑤NIM计量表'!$B$7-'⑤NIM计量表'!$B$5)*$C$27*0.5-'⑤NIM计量表'!$B$13)/('⑤NIM计量表'!$B$5+('⑤NIM计量表'!$B$7-'⑤NIM计量表'!$B$5)*0.5) | E36: =D36-'⑤NIM计量表'!$B$17 | F36: 中 | G36: ='⑤NIM计量表'!$B$5+('⑤NIM计量表'!$B$7-'⑤NIM计量表'!$B$5)*0.5 | H36: 非生息资产的一半转为生息，收益率取左侧可编辑参数；分母同步扩大
A38: 【四】NIM 提升路径汇总
A39: ★ 最大 ΔNIM 情景 | B39: =INDEX($A$30:$A$36,MATCH(MAX($E$30:$E$36),$E$30:$E$36,0)) | E39: =MAX($E$30:$E$36) | F39: =INDEX($F$30:$F$36,MATCH(MAX($E$30:$E$36),$E$30:$E$36,0)) | H39: 6 类优化情景中 ΔNIM 最大者（自动排序）
A40: 最优情景下的新 NIM | D40: =MAX($D$30:$D$36) | H40: 可达到的最高 NIM 水平
A41: 基准 NIM（对照） | D41: ='⑤NIM计量表'!$B$17 | H41: 与上一行之差即优化空间

Sheet ⑦情景敏感性
A1: ⑦ NIM 情景敏感性分析
A2: ΔNIM = Δ分子 ÷ 分母 − 原 NIM | 分子变动引用「①分母口径数据源」的 β 加权敞口 | 分母保持不变（规模中性）
A4: 【一】利率平行移动情景
A5: 情景 | B5: Δr (bp) | C5: Δ利息收入 (亿元/年) | D5: Δ利息支出 (亿元/年) | E5: ΔNII (亿元/年) | F5: 情景后 NII (亿元/年) | G5: 情景后 NIM | H5: ΔNIM | I5: 情景解读
A6: 利率平行上移 250bp | B6: 250 | C6: =-$B$6/10000*SUMPRODUCT(('①分母口径数据源'!$I$4:$I$27="EA")*'①分母口径数据源'!$F$4:$F$27*'①分母口径数据源'!$M$4:$M$27) | D6: =-$B$6/10000*SUMPRODUCT(('①分母口径数据源'!$K$4:$K$27="是")*'①分母口径数据源'!$F$4:$F$27*'①分母口径数据源'!$M$4:$M$27) | E6: =C6-D6 | F6: ='⑤NIM计量表'!$B$16+E6 | G6: =IF('⑤NIM计量表'!$B$5=0,0,F6/'⑤NIM计量表'!$B$5) | H6: =G6-'⑤NIM计量表'!$B$17 | I6: 大幅加息：负债端 β≈0.98 成本上升快于资产端 β≈0.53
A7: 利率平行上移 100bp | B7: 100 | C7: =-$B$7/10000*SUMPRODUCT(('①分母口径数据源'!$I$4:$I$27="EA")*'①分母口径数据源'!$F$4:$F$27*'①分母口径数据源'!$M$4:$M$27) | D7: =-$B$7/10000*SUMPRODUCT(('①分母口径数据源'!$K$4:$K$27="是")*'①分母口径数据源'!$F$4:$F$27*'①分母口径数据源'!$M$4:$M$27) | E7: =C7-D7 | F7: ='⑤NIM计量表'!$B$16+E7 | G7: =IF('⑤NIM计量表'!$B$5=0,0,F7/'⑤NIM计量表'!$B$5) | H7: =G7-'⑤NIM计量表'!$B$17 | I7: 常规加息：负规模调整，NIM 承压
A8: 利率平行上移 50bp | B8: 50 | C8: =-$B$8/10000*SUMPRODUCT(('①分母口径数据源'!$I$4:$I$27="EA")*'①分母口径数据源'!$F$4:$F$27*'①分母口径数据源'!$M$4:$M$27) | D8: =-$B$8/10000*SUMPRODUCT(('①分母口径数据源'!$K$4:$K$27="是")*'①分母口径数据源'!$F$4:$F$27*'①分母口径数据源'!$M$4:$M$27) | E8: =C8-D8 | F8: ='⑤NIM计量表'!$B$16+E8 | G8: =IF('⑤NIM计量表'!$B$5=0,0,F8/'⑤NIM计量表'!$B$5) | H8: =G8-'⑤NIM计量表'!$B$17 | I8: 温和加息
A9: 基准情景（利率不变） | B9: 0 | C9: =-$B$9/10000*SUMPRODUCT(('①分母口径数据源'!$I$4:$I$27="EA")*'①分母口径数据源'!$F$4:$F$27*'①分母口径数据源'!$M$4:$M$27) | D9: =-$B$9/10000*SUMPRODUCT(('①分母口径数据源'!$K$4:$K$27="是")*'①分母口径数据源'!$F$4:$F$27*'①分母口径数据源'!$M$4:$M$27) | E9: =C9-D9 | F9: ='⑤NIM计量表'!$B$16+E9 | G9: =IF('⑤NIM计量表'!$B$5=0,0,F9/'⑤NIM计量表'!$B$5) | H9: =G9-'⑤NIM计量表'!$B$17 | I9: 基准：ΔNIM = 0
A10: 利率平行下移 50bp | B10: -50 | C10: =-$B$10/10000*SUMPRODUCT(('①分母口径数据源'!$I$4:$I$27="EA")*'①分母口径数据源'!$F$4:$F$27*'①分母口径数据源'!$M$4:$M$27) | D10: =-$B$10/10000*SUMPRODUCT(('①分母口径数据源'!$K$4:$K$27="是")*'①分母口径数据源'!$F$4:$F$27*'①分母口径数据源'!$M$4:$M$27) | E10: =C10-D10 | F10: ='⑤NIM计量表'!$B$16+E10 | G10: =IF('⑤NIM计量表'!$B$5=0,0,F10/'⑤NIM计量表'!$B$5) | H10: =G10-'⑤NIM计量表'!$B$17 | I10: 温和降息：成本端受益更快
A11: 利率平行下移 100bp | B11: -100 | C11: =-$B$11/10000*SUMPRODUCT(('①分母口径数据源'!$I$4:$I$27="EA")*'①分母口径数据源'!$F$4:$F$27*'①分母口径数据源'!$M$4:$M$27) | D11: =-$B$11/10000*SUMPRODUCT(('①分母口径数据源'!$K$4:$K$27="是")*'①分母口径数据源'!$F$4:$F$27*'①分母口径数据源'!$M$4:$M$27) | E11: =C11-D11 | F11: ='⑤NIM计量表'!$B$16+E11 | G11: =IF('⑤NIM计量表'!$B$5=0,0,F11/'⑤NIM计量表'!$B$5) | H11: =G11-'⑤NIM计量表'!$B$17 | I11: 降息周期：NIM 走阔
A12: 利率平行下移 250bp | B12: -250 | C12: =-$B$12/10000*SUMPRODUCT(('①分母口径数据源'!$I$4:$I$27="EA")*'①分母口径数据源'!$F$4:$F$27*'①分母口径数据源'!$M$4:$M$27) | D12: =-$B$12/10000*SUMPRODUCT(('①分母口径数据源'!$K$4:$K$27="是")*'①分母口径数据源'!$F$4:$F$27*'①分母口径数据源'!$M$4:$M$27) | E12: =C12-D12 | F12: ='⑤NIM计量表'!$B$16+E12 | G12: =IF('⑤NIM计量表'!$B$5=0,0,F12/'⑤NIM计量表'!$B$5) | H12: =G12-'⑤NIM计量表'!$B$17 | I12: 大幅降息：NIM 显著走阔
A13: 最不利情景 ΔNIM（最小值） | H13: =MIN(H6:H12) | I13: NIM 变动最不利者
A14: 最有利情景 ΔNIM（最大值） | H14: =MAX(H6:H12) | I14: NIM 变动最有利者
A16: 【二】分母口径切换情景（NIM 对分母界定有多敏感）
A17: 分母口径 | B17: 分母余额 (亿元) | C17: 分子 NII (亿元/年) | D17: NIM | E17: 与监管口径差 (百分点) | F17: 排序 | G17: 占资产端比 | H17: — | I17: 说明
A18: 口径1 生息资产（★监管） | B18: ='⑤NIM计量表'!B5 | C18: ='⑤NIM计量表'!B16 | D18: =IF(B18=0,0,C18/B18) | E18: =D18-'⑤NIM计量表'!$B$17 | F18: =RANK(D18,$D$18:$D$21) | G18: =IF('⑤NIM计量表'!B7=0,0,B18/'⑤NIM计量表'!B7) | I18: 监管采用；剔除利率 0 的非生息资产
A19: 口径2 资产端合计 | B19: ='⑤NIM计量表'!B7 | C19: ='⑤NIM计量表'!B16 | D19: =IF(B19=0,0,C19/B19) | E19: =D19-'⑤NIM计量表'!$B$17 | F19: =RANK(D19,$D$18:$D$21) | G19: =IF('⑤NIM计量表'!B7=0,0,B19/'⑤NIM计量表'!B7) | I19: 含非生息，分母变大 NIM 变小
A20: 口径3 总资产（+权益） | B20: ='⑤NIM计量表'!B7+'⑤NIM计量表'!B8 | C20: ='⑤NIM计量表'!B16 | D20: =IF(B20=0,0,C20/B20) | E20: =D20-'⑤NIM计量表'!$B$17 | F20: =RANK(D20,$D$18:$D$21) | G20: =IF('⑤NIM计量表'!B7=0,0,B20/'⑤NIM计量表'!B7) | I20: 杠杆调整后分母，NIM 最低
A21: 口径4 风险加权资产近似 | B21: =SUMIF('①分母口径数据源'!$C$4:$C$27,"资产",'①分母口径数据源'!$F$4:$F$27) | C21: ='⑤NIM计量表'!B16 | D21: =IF(B21=0,0,C21/B21) | E21: =D21-'⑤NIM计量表'!$B$17 | F21: =RANK(D21,$D$18:$D$21) | G21: =IF('⑤NIM计量表'!B7=0,0,B21/'⑤NIM计量表'!B7) | I21: 近似口径
A23: 【三】NIM 风险敞口判定
A24: 加息 100bp 下 ΔNIM（核心敏感度） | B24: =H7 | I24: 绝对值越大，NIM 对利率越敏感
A25: 加息 250bp 下 ΔNIM | B25: =H6 | I25: 极端加息情景
A26: 降息 100bp 下 ΔNIM | B26: =H11 | I26: 降息情景
A27: 分母口径敏感度（口径1 − 口径3） | B27: =E18-E20 | I27: 仅口径差异导致的 NIM 变化
A28: NIM 敏感度判定 | B28: =IF(ABS(H7)>0.005,"高敏感（|Δ|>50bp）",IF(ABS(H7)>0.002,"中敏感（20~50bp）","低敏感（<20bp）")) | I28: 100bp 冲击下 NIM 变动
A29: 加息 250bp 是否跌破 1.50% 下限 | B29: =IF(G6<'⑤NIM计量表'!B67,"跌破","未跌破") | I29: 监管红线检验

Sheet ⑧计算逻辑说明
A1: ⑧ NIM 计量逻辑说明 · 与 NII 模版的分工 · prcp 实体映射
A3: 【一】NIM 与 NII 模版的分工
A4: NII 模版回答 | B4: 「一年赚了多少利息净收入」—— 关注分子口径与规模，单位亿元/年
A5: NIM 模版回答 | B5: 「每元生息资产赚多少」—— 关注分母口径与效率，单位 %
A6: 关系式 | B6: NIM = NII ÷ 平均生息资产；分子完全相同，差异全在分母界定
A7: 共用数据 | B7: 两者同源于 prcp_basic_20251231.xlsx，24 个末级账户、余额、加权平均利率完全一致
A8: 交叉校验 | B8: ⑤NIM计量表 的 NII 应等于 NII计量模版 的 NII（校验点，见【五】）
A9: 【二】数据来源（prcp_basic_20251231.xlsx /「基础数据」）
A10: 当前余额 | B10: ①分母口径数据源!F 列 ← EJ 列（列 140），原始单位元，已换算亿元
A11: 加权平均利率 | B11: ①分母口径数据源!G 列 ← EL 列（列 142），已 /100 存为小数
A12: 年度利息 | B12: ①分母口径数据源!H 列 = F × G，等价于参照物 EM 列 × 12
A13: 剩余期限分布 | B13: ②期限分布!C~BJ 列 ← BX~EI 列（列 76~139），64 桶
A14: 1 年内到期 | B14: ②期限分布 第 3+NB 列 = SUM(1M~12M 十二个桶)
A15: 风险权重 | B15: ①分母口径数据源!N 列 ← EN 列（列 144），RWA 近似口径用
A16: 总资产 / 总负债 / 权益 | B16: 参照物 R4 / R29 / R43 的 EJ 列：108 万亿 / 98 万亿 / 10 万亿
A17: 【三】★ 核心：NIM 分母界定
A18: 生息资产判定 | B18: 资产端 且 加权平均利率 > 0 → 生息资产(EA)，计入 NIM 分母
A19: 非生息判定 | B19: 资产端 且 利率 = 0 → 非生息(NEA)，不计入分母，但计入总资产
A20: 本行分母构成 | B20: 生息资产 105 万亿 + 非生息资产 3 万亿 = 总资产 108 万亿
A21: ★ NIM ≠ NIS | B21: NIM = NIS × (计息负债 ÷ 生息资产)；本行系数 93.33%
A22: 规模错配拖累 | B22: 非生息资产不为负债融资，故分母 > 分子对应规模，NIS > NIM
A23: 多口径对比 | B23: 5 种候选分母并列，量化口径差异（NIM 可相差多个百分点）
A24: 【四】核心计量公式
A25: 年度利息 | B25: I_i = 当前余额_i × 加权平均利率_i
A26: 利息收入 | B26: Σ 生息资产 I_i
A27: 利息支出 | B27: Σ 计息负债 I_i
A28: ★ 净息差 NIM | B28: NIM = (利息收入 − 利息支出) ÷ 生息资产余额
A29: 生息资产收益率 | B29: =利息收入 ÷ 生息资产余额
A30: 计息负债成本率 | B30: =利息支出 ÷ 计息负债余额
A31: ★ 净利差 NIS | B31: NIS = 生息资产收益率 − 计息负债成本率
A32: ★ 规模调整系数 | B32: k = 计息负债 ÷ 生息资产；NIM = NIS × k
A33: 杜邦三分解 | B33: NIM = 收益率 × 资产效率 − 成本率 × (负债 ÷ 资产端合计)
A34: 重定价 β | B34: =MIN(0.98, MAX(0.10, 1年内到期 ÷ Σ分布))
A35: ΔNII 敏感度 | B35: ΔNII = −Δr × (A_β − L_β)；ΔNIM = ΔNII ÷ 生息资产
A36: 【五】与 NII 计量模版的分工对照
A37: ①~② 数据源 | B37: NII 模版与 NIM 模版同源，均直接取自 prcp_basic_20251231.xlsx
A38: ③④⑤⑥ 对应 | B38: NII 模版「④利息收入明细」≈ NIM 模版「③生息资产界定」的生息资产部分
A39: NIM 模版独有 | B39: ⑤NIM计量表【四】NIS 分解、【五】多口径 NIM、【六】杜邦三分解
A40: ⑥NII驱动分解 独有 | B40: 量 / 价 / 结构三因子 + 6 类结构优化情景的 NIM 提升空间
A41: ⑦情景敏感性 差异 | B41: NII 模版看 ΔNII（亿元），NIM 模版看 ΔNIM（百分点）
...
