Workbook

Sheet 同业负债比项目明细
A1: 中信银行 同业负债比 计量模版（项目明细）
A2: 公式: 同业负债比 = 同业负债 / 总负债 | 分子: 货币市场同业拆入+债券回购+NCD+同业存款+票据转贴现 | 分母: 24 项负债之和 | 监管红线 ≤ 33.33%
A4: 项目序号 | B4: 项目名称 | C4: 是否末级节点 | D4: 当前余额（人民币元） | E4: 是否同业负债 | F4: 同业负债折算系数 | G4: 计入同业负债额 | H4: IBL 规则说明
A5: S010000000000 | B5: 总资产 | C5: 否 | E5: 否 | F5: - | G5: =IF(AND(E5="是",F5=1),D5*F5,0) | H5: 汇总节点不参与计算
A6: S010100000000 | B6: （一）人民币小计 | C6: 否 | E6: 否 | F6: - | G6: =IF(AND(E6="是",F6=1),D6*F6,0) | H6: 汇总节点
A7: S010101000000 | B7: 1.境内人民币各项贷款 | C7: 否 | D7: 8.3808476e+12 | E7: 否 | F7: - | G7: =IF(AND(E7="是",F7=1),D7*F7,0) | H7: 汇总节点
A8: S010101010000 | B8: 1.1.对公一般贷款 | C8: 是 | D8: 2.945272e+12 | E8: 否 | F8: - | G8: =IF(AND(E8="是",F8=1),D8*F8,0) | H8: 资产项 不参与
A9: S010101020000 | B9: 1.2.个人贷款 | C9: 是 | D9: 1.8281866e+12 | E9: 否 | F9: - | G9: =IF(AND(E9="是",F9=1),D9*F9,0) | H9: 资产项 不参与
A10: S010101030000 | B10: 1.3.信用卡贷款 | C10: 是 | D10: 4.445255e+11 | E10: 否 | F10: - | G10: =IF(AND(E10="是",F10=1),D10*F10,0) | H10: 资产项 不参与
A11: S010101040000 | B11: 1.4.票据贴现 | C11: 是 | D11: 2.0134008e+11 | E11: 否 | F11: - | G11: =IF(AND(E11="是",F11=1),D11*F11,0) | H11: 资产项 不参与
A12: S010101050000 | B12: 1.5.非银贷款 | C12: 是 | D12: 348478250000 | E12: 否 | F12: - | G12: =IF(AND(E12="是",F12=1),D12*F12,0) | H12: 资产项 不参与
A13: S010102000000 | B13: 2.人民币非信贷类业务 | C13: 否 | D13: 2.6130452e+12 | E13: 否 | F13: - | G13: =IF(AND(E13="是",F13=1),D13*F13,0) | H13: 汇总节点
A14: S010102010000 | B14: 2.1.债券投资 | C14: 否 | D14: 1.7944005e+12 | E14: 否 | F14: - | G14: =IF(AND(E14="是",F14=1),D14*F14,0) | H14: 汇总节点
A15: S010102010100 | B15: 2.1.1金市自营债券 | C15: 否 | D15: 1.1843826e+12 | E15: 否 | F15: - | G15: =IF(AND(E15="是",F15=1),D15*F15,0) | H15: 汇总节点
A16: S010102010101 | B16: 2.1.1.1AC | C16: 是 | D16: 5.4398007e+11 | E16: 否 | F16: - | G16: =IF(AND(E16="是",F16=1),D16*F16,0) | H16: 资产项
A17: S010102010102 | B17: 2.1.1.2FVOCI | C17: 是 | D17: 640402496404 | E17: 否 | F17: - | G17: =IF(AND(E17="是",F17=1),D17*F17,0) | H17: 资产项
A18: S010102010103 | B18: 2.1.1.3FVTPL | C18: 是 | D18: 50000000000 | E18: 否 | F18: - | G18: =IF(AND(E18="是",F18=1),D18*F18,0) | H18: 资产项
... A30: S010103020200 | B30: 3.2.2. 其中：其它 | C30: 是 | D30: 100000000000 | E30: 否 | F30: - | G30: =IF(AND(E30="是",F30=1),D30*F30,0) | H30: 资产项
A31: S010200000000 | B31: （二）外币小计（美元） | C31: 否 | E31: 否 | F31: - | G31: =IF(AND(E31="是",F31=1),D31*F31,0) | H31: 汇总节点
A32: S010201000000 | B32: 1.外币贷款 | C32: 是 | D32: 80000000000 | E32: 否 | F32: - | G32: =IF(AND(E32="是",F32=1),D32*F32,0) | H32: 资产项
A33: S010202000000 | B33: 2.外币非信贷资产 | C33: 否 | E33: 否 | F33: - | G33: =IF(AND(E33="是",F33=1),D33*F33,0) | H33: 汇总节点
A34: S010202010000 | B34: 2.1.外币债券 | C34: 是 | D34: 35000000000 | E34: 否 | F34: - | G34: =IF(AND(E34="是",F34=1),D34*F34,0) | H34: 资产项
A35: S010202020000 | B35: 2.2.同业资产 | C35: 是 | D35: 25000000000 | E35: 否 | F35: - | G35: =IF(AND(E35="是",F35=1),D35*F35,0) | H35: 资产项 同业资产 非同业负债
A36: S010203000000 | B36: 3.外币非生息资产 | C36: 是 | D36: 10000000000 | E36: 否 | F36: - | G36: =IF(AND(E36="是",F36=1),D36*F36,0) | H36: 资产项
A37: S020000000000 | B37: 总负债 | C37: 否 | E37: 否 | F37: - | G37: =IF(AND(E37="是",F37=1),D37*F37,0) | H37: 汇总节点
A38: S020100000000 | B38: （一）人民币小计 | C38: 否 | E38: 否 | F38: - | G38: =IF(AND(E38="是",F38=1),D38*F38,0) | H38: 汇总节点
A39: S020101000000 | B39: 1.境内人民币自营存款 | C39: 否 | E39: 否 | F39: - | G39: =IF(AND(E39="是",F39=1),D39*F39,0) | H39: 汇总节点
A40: S020101010000 | B40: 1.1.对公存款 | C40: 否 | D40: 4.2226821e+12 | E40: 否 | F40: - | G40: =IF(AND(E40="是",F40=1),D40*F40,0) | H40: 汇总节点
A41: S020101010100 | B41: 1.1.1对公活期存款 | C41: 是 | D41: 2.4862124e+12 | E41: 否 | F41: - | G41: =IF(AND(E41="是",F41=1),D41*F41,0) | H41: 客户存款 不计入同业负债
A42: S020101010200 | B42: 1.1.2对公定期存款 | C42: 是 | D42: 1.7364697e+12 | E42: 否 | F42: - | G42: =IF(AND(E42="是",F42=1),D42*F42,0) | H42: 客户存款 不计入同业负债
A43: S020101020000 | B43: 1.2.零售存款 | C43: 否 | D43: 2.1694315e+12 | E43: 否 | F43: - | G43: =IF(AND(E43="是",F43=1),D43*F43,0) | H43: 汇总节点
A44: S020101020100 | B44: 1.2.1零售活期存款 | C44: 是 | D44: 4.348672e+11 | E44: 否 | F44: - | G44: =IF(AND(E44="是",F44=1),D44*F44,0) | H44: 客户存款 不计入同业负债
A45: S020101020200 | B45: 1.2.2零售定期存款 | C45: 是 | D45: 1.7345643e+12 | E45: 否 | F45: - | G45: =IF(AND(E45="是",F45=1),D45*F45,0) | H45: 客户存款 不计入同业负债
A46: S020102000000 | B46: 2.人民币市场化负债 | C46: 否 | E46: 否 | F46: - | G46: =IF(AND(E46="是",F46=1),D46*F46,0) | H46: 汇总节点
A47: S020102010000 | B47: 2.2.1同业负债 | C47: 否 | E47: 否 | F47: - | G47: =IF(AND(E47="是",F47=1),D47*F47,0) | H47: 汇总节点 (同业负债 5 子项)
A48: S020102010100 | B48: 2.2.1.1货币市场同业拆入 | C48: 是 | D48: 3.2988349e+10 | E48: 是 | F48: 1 | G48: =IF(AND(E48="是",F48=1),D48*F48,0) | H48: ⭐同业负债: 货币市场同业拆入 100% 计入
A49: S020102010200 | B49: 2.2.1.2货币市场债券回购 | C49: 是 | D49: 95875096000 | E49: 是 | F49: 1 | G49: =IF(AND(E49="是",F49=1),D49*F49,0) | H49: ⭐同业负债: 货币市场债券回购 100% 计入
A50: S020102010300 | B50: 2.2.1.3同业存单（NCD） | C50: 是 | D50: 9.3223794e+11 | E50: 是 | F50: 1 | G50: =IF(AND(E50="是",F50=1),D50*F50,0) | H50: ⭐同业负债: 同业存单 NCD 100% 计入
A51: S020102010400 | B51: 2.2.1.4同业存款 | C51: 是 | D51: 9.1560505e+11 | E51: 是 | F51: 1 | G51: =IF(AND(E51="是",F51=1),D51*F51,0) | H51: ⭐同业负债: 同业存款 100% 计入
A52: S020102010500 | B52: 2.2.1.5票据转贴现回购 | C52: 是 | D52: 1000000000 | E52: 是 | F52: 1 | G52: =IF(AND(E52="是",F52=1),D52*F52,0) | H52: ⭐同业负债: 票据转贴现 100% 计入
...

Sheet 同业负债比计算
A1: 中信银行 同业负债比 计算表
A2: 数据基准：中信银行 2025 年末 | 单位：人民币元
A4: 项目 | B4: 金额（人民币元） | C4: 占合计
A5: 【一、同业负债（分子）】
A6: 1. 货币市场同业拆入 | B6: =同业负债比项目明细!D45
A7: 2. 货币市场债券回购 | B7: =同业负债比项目明细!D46
A8: 3. 同业存单 (NCD) | B8: =同业负债比项目明细!D47
A9: 4. 同业存款 | B9: =同业负债比项目明细!D48
A10: 5. 票据转贴现回购 | B10: =同业负债比项目明细!D49
A11: 同业负债合计 (A) | B11: =SUM(D6:D10) | C11: 100.00%
A13: 【二、总负债（分母）】
A14: 1. 对公活期存款 | B14: =同业负债比项目明细!D37
A15: 2. 对公定期存款 | B15: =同业负债比项目明细!D38
A16: 3. 零售活期存款 | B16: =同业负债比项目明细!D40
A17: 4. 零售定期存款 | B17: =同业负债比项目明细!D41
A18: 5. 同业负债 5 项合计 | B18: =同业负债比项目明细!D45+同业负债比项目明细!D46+同业负债比项目明细!D47+同业负债比项目明细!D48+同业负债比项目明细!D49
A19: 6. 央行借款 4 项 | B19: =同业负债比项目明细!D50+同业负债比项目明细!D51+同业负债比项目明细!D52+同业负债比项目明细!D53
A20: 7. 外币存款 | B20: =同业负债比项目明细!D55
A21: 8. 外币市场化负债 | B21: =同业负债比项目明细!D56
A22: 总负债合计 (B) | B22: =SUM(D13:D20) | C22: 100.00%
C23: ★ 同业负债比 ★
A24: 【三、同业负债比】
A25: 同业负债比 = A / B | B25: =D11/D22
A27: 【四、监管检查】
A28: 监管红线 | B28: 33.33% | C28: ≤ 33.33%
A29: 当前值 vs 红线 | B29: =IF(D27<=0.3333,"✓ 达标","✗ 超标")
A30: 距红线 (缓冲) | B30: =(0.3333-D27)*100 | C30: pp

Sheet 折算依据
A1: 同业负债比 折算依据与监管规定
A3: 序号 | B3: 项目 | C3: 内容/公式
A4: 1 | B4: 指标名称 | C4: 同业负债占比 (Interbank Liability Ratio)
A5: 2 | B5: 指标代码 | C5: IBL
A6: 3 | B6: 计算公式 | C6: 同业负债比 = 同业负债合计 / 总负债合计 × 100%
A7: 4 | B7: 分子定义 | C7: 同业负债 = 货币市场同业拆入 + 货币市场债券回购 + 同业存单 (NCD) + 同业存款 + 票据转贴现回购
A8: 5 | B8: 分母定义 | C8: 总负债 = 对公存款 + 零售存款 + 同业负债 + 央行借款 + 外币存款 + 外币市场化负债 (24 项)
A9: 6 | B9: 数据来源 | C9: 中信银行 2025 年末账户册 (ZX_COA 方案)
A10: 7 | B10: 监管规定 | C10: 银保监会《商业银行风险监管核心指标》同业负债占比 ≤ 33.33%
A11: 8 | B11: 折算系数 | C11: 同业负债 5 项: 100% 计入 | 央行借款 4 项: 0% (不计) | 客户存款: 0% (不计) | 外币: 0% (不计)
A12: 9 | B12: 中信银行实测 | C12: 2025 年末 同业负债合计 ≈ 1.98 万亿 / 总负债 ≈ 9.16 万亿 ≈ 21.6% (留有 12pp 缓冲空间)
A13: 10 | B13: 考核层级 | C13: 本行底线 ≤ 33.33% | 安全 ≤ 25% | 预警 25-30% | 危险 30-33.33% | 红线 > 33.33%
A14: 11 | B14: 业务含义 | C14: 同业负债占比反映银行对同业资金的依赖程度，过高则流动性风险集中
A15: 12 | B15: 调整建议 | C15: 保持同业负债占比 ≤ 25% 安全区间, 避免依赖同业资金
